2023-05-03 09:14:48,583 - distributed.nanny - INFO -         Start Nanny at: 'tcp://172.16.3.168:36811'
2023-05-03 09:14:57,086 - distributed.worker - INFO -       Start worker at:   tcp://172.16.3.168:39334
2023-05-03 09:14:57,086 - distributed.worker - INFO -          Listening to:   tcp://172.16.3.168:39334
2023-05-03 09:14:57,086 - distributed.worker - INFO -           Worker name:             SLURMCluster-0
2023-05-03 09:14:57,086 - distributed.worker - INFO -          dashboard at:         172.16.3.168:43906
2023-05-03 09:14:57,086 - distributed.worker - INFO - Waiting to connect to:   tcp://172.16.3.158:44759
2023-05-03 09:14:57,086 - distributed.worker - INFO - -------------------------------------------------
2023-05-03 09:14:57,086 - distributed.worker - INFO -               Threads:                         36
2023-05-03 09:14:57,086 - distributed.worker - INFO -                Memory:                 178.81 GiB
2023-05-03 09:14:57,086 - distributed.worker - INFO -       Local Directory: /tmp/dask-worker-space/worker-4iwc9r3c
2023-05-03 09:14:57,086 - distributed.worker - INFO - -------------------------------------------------
2023-05-03 09:14:57,094 - distributed.worker - INFO -         Registered to:   tcp://172.16.3.158:44759
2023-05-03 09:14:57,094 - distributed.worker - INFO - -------------------------------------------------
2023-05-03 09:14:57,095 - distributed.core - INFO - Starting established connection to tcp://172.16.3.158:44759
2023-05-03 09:18:45,521 - distributed.utils_perf - INFO - full garbage collection released 1.43 GiB from 30 reference cycles (threshold: 9.54 MiB)
2023-05-03 09:18:50,924 - distributed.utils_perf - INFO - full garbage collection released 833.99 MiB from 680 reference cycles (threshold: 9.54 MiB)
2023-05-03 09:19:46,082 - distributed.utils_perf - INFO - full garbage collection released 2.20 GiB from 440 reference cycles (threshold: 9.54 MiB)
2023-05-03 09:19:49,269 - distributed.utils_perf - INFO - full garbage collection released 620.25 MiB from 519 reference cycles (threshold: 9.54 MiB)
2023-05-03 09:21:56,026 - distributed.core - INFO - Event loop was unresponsive in Worker for 3.78s.  This is often caused by long-running GIL-holding functions or moving large chunks of data. This can cause timeouts and instability.
2023-05-03 09:21:59,303 - distributed.core - INFO - Event loop was unresponsive in Worker for 3.28s.  This is often caused by long-running GIL-holding functions or moving large chunks of data. This can cause timeouts and instability.
2023-05-03 09:22:09,143 - distributed.core - INFO - Event loop was unresponsive in Worker for 8.19s.  This is often caused by long-running GIL-holding functions or moving large chunks of data. This can cause timeouts and instability.
2023-05-03 09:22:15,141 - distributed.core - INFO - Event loop was unresponsive in Worker for 6.00s.  This is often caused by long-running GIL-holding functions or moving large chunks of data. This can cause timeouts and instability.
2023-05-03 09:22:30,936 - distributed.core - INFO - Event loop was unresponsive in Worker for 3.54s.  This is often caused by long-running GIL-holding functions or moving large chunks of data. This can cause timeouts and instability.
2023-05-03 09:22:38,122 - distributed.core - INFO - Event loop was unresponsive in Worker for 5.61s.  This is often caused by long-running GIL-holding functions or moving large chunks of data. This can cause timeouts and instability.
2023-05-03 09:22:39,257 - distributed.utils_perf - WARNING - full garbage collections took 13% CPU time recently (threshold: 10%)
2023-05-03 09:22:55,772 - distributed.utils_perf - WARNING - full garbage collections took 13% CPU time recently (threshold: 10%)
2023-05-03 09:23:09,451 - distributed.utils_perf - WARNING - full garbage collections took 13% CPU time recently (threshold: 10%)
2023-05-03 09:23:09,525 - distributed.core - INFO - Event loop was unresponsive in Worker for 3.94s.  This is often caused by long-running GIL-holding functions or moving large chunks of data. This can cause timeouts and instability.
2023-05-03 09:23:15,187 - distributed.utils_perf - WARNING - full garbage collections took 12% CPU time recently (threshold: 10%)
2023-05-03 09:23:23,387 - distributed.core - INFO - Event loop was unresponsive in Worker for 3.63s.  This is often caused by long-running GIL-holding functions or moving large chunks of data. This can cause timeouts and instability.
2023-05-03 09:23:28,827 - distributed.core - INFO - Event loop was unresponsive in Worker for 5.44s.  This is often caused by long-running GIL-holding functions or moving large chunks of data. This can cause timeouts and instability.
2023-05-03 09:23:29,910 - distributed.utils_perf - WARNING - full garbage collections took 13% CPU time recently (threshold: 10%)
2023-05-03 09:23:34,197 - distributed.core - INFO - Event loop was unresponsive in Worker for 4.23s.  This is often caused by long-running GIL-holding functions or moving large chunks of data. This can cause timeouts and instability.
2023-05-03 09:23:40,317 - distributed.core - INFO - Event loop was unresponsive in Worker for 6.12s.  This is often caused by long-running GIL-holding functions or moving large chunks of data. This can cause timeouts and instability.
2023-05-03 09:23:44,693 - distributed.core - INFO - Event loop was unresponsive in Worker for 4.38s.  This is often caused by long-running GIL-holding functions or moving large chunks of data. This can cause timeouts and instability.
2023-05-03 09:23:50,888 - distributed.utils_perf - WARNING - full garbage collections took 12% CPU time recently (threshold: 10%)
2023-05-03 09:23:57,799 - distributed.utils_perf - WARNING - full garbage collections took 12% CPU time recently (threshold: 10%)
2023-05-03 09:24:11,622 - distributed.core - INFO - Event loop was unresponsive in Worker for 3.22s.  This is often caused by long-running GIL-holding functions or moving large chunks of data. This can cause timeouts and instability.
2023-05-03 09:24:25,108 - distributed.core - INFO - Event loop was unresponsive in Worker for 3.19s.  This is often caused by long-running GIL-holding functions or moving large chunks of data. This can cause timeouts and instability.
2023-05-03 09:24:29,623 - distributed.utils_perf - WARNING - full garbage collections took 11% CPU time recently (threshold: 10%)
2023-05-03 09:24:48,505 - distributed.core - INFO - Event loop was unresponsive in Worker for 3.44s.  This is often caused by long-running GIL-holding functions or moving large chunks of data. This can cause timeouts and instability.
2023-05-03 09:25:17,238 - distributed.core - INFO - Event loop was unresponsive in Worker for 3.84s.  This is often caused by long-running GIL-holding functions or moving large chunks of data. This can cause timeouts and instability.
2023-05-03 09:25:30,636 - distributed.utils_perf - WARNING - full garbage collections took 10% CPU time recently (threshold: 10%)
2023-05-03 09:26:55,435 - distributed.core - INFO - Event loop was unresponsive in Worker for 3.96s.  This is often caused by long-running GIL-holding functions or moving large chunks of data. This can cause timeouts and instability.
2023-05-03 09:27:46,573 - distributed.core - INFO - Event loop was unresponsive in Worker for 5.32s.  This is often caused by long-running GIL-holding functions or moving large chunks of data. This can cause timeouts and instability.
2023-05-03 09:28:52,028 - distributed.utils_perf - INFO - full garbage collection released 16.07 MiB from 800 reference cycles (threshold: 9.54 MiB)
2023-05-03 09:29:51,368 - distributed.core - INFO - Event loop was unresponsive in Worker for 3.47s.  This is often caused by long-running GIL-holding functions or moving large chunks of data. This can cause timeouts and instability.
2023-05-03 09:30:43,243 - distributed.worker - ERROR - failed during get data with tcp://172.16.3.168:39334 -> tcp://172.16.3.62:35035
Traceback (most recent call last):
  File "/vortexfs1/home/anthony.meza/mambaforge/envs/atm_rivers/lib/python3.10/site-packages/tornado/iostream.py", line 861, in _read_to_buffer
    bytes_read = self.read_from_fd(buf)
  File "/vortexfs1/home/anthony.meza/mambaforge/envs/atm_rivers/lib/python3.10/site-packages/tornado/iostream.py", line 1116, in read_from_fd
    return self.socket.recv_into(buf, len(buf))
ConnectionResetError: [Errno 104] Connection reset by peer

The above exception was the direct cause of the following exception:

Traceback (most recent call last):
  File "/vortexfs1/home/anthony.meza/mambaforge/envs/atm_rivers/lib/python3.10/site-packages/distributed/worker.py", line 1783, in get_data
    response = await comm.read(deserializers=serializers)
  File "/vortexfs1/home/anthony.meza/mambaforge/envs/atm_rivers/lib/python3.10/site-packages/distributed/comm/tcp.py", line 241, in read
    convert_stream_closed_error(self, e)
  File "/vortexfs1/home/anthony.meza/mambaforge/envs/atm_rivers/lib/python3.10/site-packages/distributed/comm/tcp.py", line 142, in convert_stream_closed_error
    raise CommClosedError(f"in {obj}: {exc.__class__.__name__}: {exc}") from exc
distributed.comm.core.CommClosedError: in <TCP (closed)  local=tcp://172.16.3.168:39334 remote=tcp://172.16.3.62:44077>: ConnectionResetError: [Errno 104] Connection reset by peer
2023-05-03 09:30:43,249 - distributed.core - INFO - Lost connection to 'tcp://172.16.3.62:44077'
Traceback (most recent call last):
  File "/vortexfs1/home/anthony.meza/mambaforge/envs/atm_rivers/lib/python3.10/site-packages/tornado/iostream.py", line 861, in _read_to_buffer
    bytes_read = self.read_from_fd(buf)
  File "/vortexfs1/home/anthony.meza/mambaforge/envs/atm_rivers/lib/python3.10/site-packages/tornado/iostream.py", line 1116, in read_from_fd
    return self.socket.recv_into(buf, len(buf))
ConnectionResetError: [Errno 104] Connection reset by peer

The above exception was the direct cause of the following exception:

Traceback (most recent call last):
  File "/vortexfs1/home/anthony.meza/mambaforge/envs/atm_rivers/lib/python3.10/site-packages/distributed/core.py", line 831, in _handle_comm
    result = await result
  File "/vortexfs1/home/anthony.meza/mambaforge/envs/atm_rivers/lib/python3.10/site-packages/distributed/core.py", line 990, in wrapper
    return await func(self, *args, **kwargs)
  File "/vortexfs1/home/anthony.meza/mambaforge/envs/atm_rivers/lib/python3.10/site-packages/distributed/worker.py", line 1783, in get_data
    response = await comm.read(deserializers=serializers)
  File "/vortexfs1/home/anthony.meza/mambaforge/envs/atm_rivers/lib/python3.10/site-packages/distributed/comm/tcp.py", line 241, in read
    convert_stream_closed_error(self, e)
  File "/vortexfs1/home/anthony.meza/mambaforge/envs/atm_rivers/lib/python3.10/site-packages/distributed/comm/tcp.py", line 142, in convert_stream_closed_error
    raise CommClosedError(f"in {obj}: {exc.__class__.__name__}: {exc}") from exc
distributed.comm.core.CommClosedError: in <TCP (closed)  local=tcp://172.16.3.168:39334 remote=tcp://172.16.3.62:44077>: ConnectionResetError: [Errno 104] Connection reset by peer
2023-05-03 09:30:44,802 - distributed.core - INFO - Removing comms to tcp://172.16.3.62:35035
2023-05-03 09:31:13,607 - distributed.worker - ERROR - Worker stream died during communication: tcp://172.16.3.62:35035
Traceback (most recent call last):
  File "/vortexfs1/home/anthony.meza/mambaforge/envs/atm_rivers/lib/python3.10/site-packages/distributed/comm/tcp.py", line 235, in read
    n = await stream.read_into(chunk)
tornado.iostream.StreamClosedError: Stream is closed

The above exception was the direct cause of the following exception:

Traceback (most recent call last):
  File "/vortexfs1/home/anthony.meza/mambaforge/envs/atm_rivers/lib/python3.10/site-packages/distributed/worker.py", line 2056, in gather_dep
    response = await get_data_from_worker(
  File "/vortexfs1/home/anthony.meza/mambaforge/envs/atm_rivers/lib/python3.10/site-packages/distributed/worker.py", line 2891, in get_data_from_worker
    response = await send_recv(
  File "/vortexfs1/home/anthony.meza/mambaforge/envs/atm_rivers/lib/python3.10/site-packages/distributed/core.py", line 1027, in send_recv
    response = await comm.read(deserializers=deserializers)
  File "/vortexfs1/home/anthony.meza/mambaforge/envs/atm_rivers/lib/python3.10/site-packages/distributed/comm/tcp.py", line 241, in read
    convert_stream_closed_error(self, e)
  File "/vortexfs1/home/anthony.meza/mambaforge/envs/atm_rivers/lib/python3.10/site-packages/distributed/comm/tcp.py", line 144, in convert_stream_closed_error
    raise CommClosedError(f"in {obj}: {exc}") from exc
distributed.comm.core.CommClosedError: in <TCP (closed) Ephemeral Worker->Worker for gather local=tcp://172.16.3.168:52243 remote=tcp://172.16.3.62:35035>: Stream is closed
2023-05-03 09:31:13,624 - distributed.core - INFO - Event loop was unresponsive in Worker for 29.09s.  This is often caused by long-running GIL-holding functions or moving large chunks of data. This can cause timeouts and instability.
2023-05-03 09:33:19,760 - distributed.core - INFO - Removing comms to tcp://172.16.3.105:44979
2023-05-03 09:33:19,795 - distributed.worker - ERROR - Worker stream died during communication: tcp://172.16.3.105:44979
Traceback (most recent call last):
  File "/vortexfs1/home/anthony.meza/mambaforge/envs/atm_rivers/lib/python3.10/site-packages/distributed/comm/tcp.py", line 235, in read
    n = await stream.read_into(chunk)
tornado.iostream.StreamClosedError: Stream is closed

The above exception was the direct cause of the following exception:

Traceback (most recent call last):
  File "/vortexfs1/home/anthony.meza/mambaforge/envs/atm_rivers/lib/python3.10/site-packages/distributed/worker.py", line 2056, in gather_dep
    response = await get_data_from_worker(
  File "/vortexfs1/home/anthony.meza/mambaforge/envs/atm_rivers/lib/python3.10/site-packages/distributed/worker.py", line 2891, in get_data_from_worker
    response = await send_recv(
  File "/vortexfs1/home/anthony.meza/mambaforge/envs/atm_rivers/lib/python3.10/site-packages/distributed/core.py", line 1027, in send_recv
    response = await comm.read(deserializers=deserializers)
  File "/vortexfs1/home/anthony.meza/mambaforge/envs/atm_rivers/lib/python3.10/site-packages/distributed/comm/tcp.py", line 241, in read
    convert_stream_closed_error(self, e)
  File "/vortexfs1/home/anthony.meza/mambaforge/envs/atm_rivers/lib/python3.10/site-packages/distributed/comm/tcp.py", line 144, in convert_stream_closed_error
    raise CommClosedError(f"in {obj}: {exc}") from exc
distributed.comm.core.CommClosedError: in <TCP (closed) Ephemeral Worker->Worker for gather local=tcp://172.16.3.168:33044 remote=tcp://172.16.3.105:44979>: Stream is closed
2023-05-03 09:35:27,150 - distributed.utils_perf - INFO - full garbage collection released 27.05 MiB from 719 reference cycles (threshold: 9.54 MiB)
2023-05-03 09:35:27,163 - distributed.worker - ERROR - Failed to communicate with scheduler during heartbeat.
Traceback (most recent call last):
  File "/vortexfs1/home/anthony.meza/mambaforge/envs/atm_rivers/lib/python3.10/site-packages/tornado/iostream.py", line 861, in _read_to_buffer
    bytes_read = self.read_from_fd(buf)
  File "/vortexfs1/home/anthony.meza/mambaforge/envs/atm_rivers/lib/python3.10/site-packages/tornado/iostream.py", line 1116, in read_from_fd
    return self.socket.recv_into(buf, len(buf))
ConnectionResetError: [Errno 104] Connection reset by peer

The above exception was the direct cause of the following exception:

Traceback (most recent call last):
  File "/vortexfs1/home/anthony.meza/mambaforge/envs/atm_rivers/lib/python3.10/site-packages/distributed/worker.py", line 1234, in heartbeat
    response = await retry_operation(
  File "/vortexfs1/home/anthony.meza/mambaforge/envs/atm_rivers/lib/python3.10/site-packages/distributed/utils_comm.py", line 434, in retry_operation
    return await retry(
  File "/vortexfs1/home/anthony.meza/mambaforge/envs/atm_rivers/lib/python3.10/site-packages/distributed/utils_comm.py", line 413, in retry
    return await coro()
  File "/vortexfs1/home/anthony.meza/mambaforge/envs/atm_rivers/lib/python3.10/site-packages/distributed/core.py", line 1268, in send_recv_from_rpc
    return await send_recv(comm=comm, op=key, **kwargs)
  File "/vortexfs1/home/anthony.meza/mambaforge/envs/atm_rivers/lib/python3.10/site-packages/distributed/core.py", line 1027, in send_recv
    response = await comm.read(deserializers=deserializers)
  File "/vortexfs1/home/anthony.meza/mambaforge/envs/atm_rivers/lib/python3.10/site-packages/distributed/comm/tcp.py", line 241, in read
    convert_stream_closed_error(self, e)
  File "/vortexfs1/home/anthony.meza/mambaforge/envs/atm_rivers/lib/python3.10/site-packages/distributed/comm/tcp.py", line 142, in convert_stream_closed_error
    raise CommClosedError(f"in {obj}: {exc.__class__.__name__}: {exc}") from exc
distributed.comm.core.CommClosedError: in <TCP (closed) ConnectionPool.heartbeat_worker local=tcp://172.16.3.168:44705 remote=tcp://172.16.3.158:44759>: ConnectionResetError: [Errno 104] Connection reset by peer
2023-05-03 09:35:27,166 - distributed.core - INFO - Connection to tcp://172.16.3.158:44759 has been closed.
2023-05-03 09:35:27,166 - distributed.worker - INFO - Stopping worker at tcp://172.16.3.168:39334. Reason: worker-handle-scheduler-connection-broken
2023-05-03 09:35:27,168 - distributed.worker - ERROR - failed during get data with tcp://172.16.3.168:39334 -> tcp://172.16.3.88:33948
Traceback (most recent call last):
  File "/vortexfs1/home/anthony.meza/mambaforge/envs/atm_rivers/lib/python3.10/site-packages/distributed/comm/tcp.py", line 225, in read
    frames_nbytes = await stream.read_bytes(fmt_size)
tornado.iostream.StreamClosedError: Stream is closed

The above exception was the direct cause of the following exception:

Traceback (most recent call last):
  File "/vortexfs1/home/anthony.meza/mambaforge/envs/atm_rivers/lib/python3.10/site-packages/distributed/worker.py", line 1783, in get_data
    response = await comm.read(deserializers=serializers)
  File "/vortexfs1/home/anthony.meza/mambaforge/envs/atm_rivers/lib/python3.10/site-packages/distributed/comm/tcp.py", line 241, in read
    convert_stream_closed_error(self, e)
  File "/vortexfs1/home/anthony.meza/mambaforge/envs/atm_rivers/lib/python3.10/site-packages/distributed/comm/tcp.py", line 144, in convert_stream_closed_error
    raise CommClosedError(f"in {obj}: {exc}") from exc
distributed.comm.core.CommClosedError: in <TCP (closed)  local=tcp://172.16.3.168:39334 remote=tcp://172.16.3.88:50434>: Stream is closed
2023-05-03 09:35:28,766 - distributed.batched - INFO - Batched Comm Closed <TCP (closed) Worker->Scheduler local=tcp://172.16.3.168:44467 remote=tcp://172.16.3.158:44759>
Traceback (most recent call last):
  File "/vortexfs1/home/anthony.meza/mambaforge/envs/atm_rivers/lib/python3.10/site-packages/distributed/batched.py", line 115, in _background_send
    nbytes = yield coro
  File "/vortexfs1/home/anthony.meza/mambaforge/envs/atm_rivers/lib/python3.10/site-packages/tornado/gen.py", line 767, in run
    value = future.result()
  File "/vortexfs1/home/anthony.meza/mambaforge/envs/atm_rivers/lib/python3.10/site-packages/distributed/comm/tcp.py", line 269, in write
    raise CommClosedError()
distributed.comm.core.CommClosedError
2023-05-03 09:35:28,775 - distributed.nanny - INFO - Closing Nanny gracefully at 'tcp://172.16.3.168:36811'. Reason: worker-handle-scheduler-connection-broken
2023-05-03 09:35:28,819 - distributed.worker - ERROR - failed during get data with tcp://172.16.3.168:39334 -> tcp://172.16.3.93:41353
Traceback (most recent call last):
  File "/vortexfs1/home/anthony.meza/mambaforge/envs/atm_rivers/lib/python3.10/site-packages/distributed/comm/tcp.py", line 317, in write
    raise StreamClosedError()
tornado.iostream.StreamClosedError: Stream is closed

The above exception was the direct cause of the following exception:

Traceback (most recent call last):
  File "/vortexfs1/home/anthony.meza/mambaforge/envs/atm_rivers/lib/python3.10/site-packages/distributed/worker.py", line 1782, in get_data
    compressed = await comm.write(msg, serializers=serializers)
  File "/vortexfs1/home/anthony.meza/mambaforge/envs/atm_rivers/lib/python3.10/site-packages/distributed/comm/tcp.py", line 328, in write
    convert_stream_closed_error(self, e)
  File "/vortexfs1/home/anthony.meza/mambaforge/envs/atm_rivers/lib/python3.10/site-packages/distributed/comm/tcp.py", line 144, in convert_stream_closed_error
    raise CommClosedError(f"in {obj}: {exc}") from exc
distributed.comm.core.CommClosedError: in <TCP (closed)  local=tcp://172.16.3.168:39334 remote=tcp://172.16.3.93:54010>: Stream is closed
2023-05-03 09:35:31,605 - distributed.client - ERROR - 
ConnectionRefusedError: [Errno 111] Connection refused

The above exception was the direct cause of the following exception:

Traceback (most recent call last):
  File "/vortexfs1/home/anthony.meza/mambaforge/envs/atm_rivers/lib/python3.10/site-packages/distributed/comm/core.py", line 292, in connect
    comm = await wait_for(
  File "/vortexfs1/home/anthony.meza/mambaforge/envs/atm_rivers/lib/python3.10/site-packages/distributed/utils.py", line 1850, in wait_for
    return await asyncio.wait_for(fut, timeout)
  File "/vortexfs1/home/anthony.meza/mambaforge/envs/atm_rivers/lib/python3.10/asyncio/tasks.py", line 445, in wait_for
    return fut.result()
  File "/vortexfs1/home/anthony.meza/mambaforge/envs/atm_rivers/lib/python3.10/site-packages/distributed/comm/tcp.py", line 511, in connect
    convert_stream_closed_error(self, e)
  File "/vortexfs1/home/anthony.meza/mambaforge/envs/atm_rivers/lib/python3.10/site-packages/distributed/comm/tcp.py", line 142, in convert_stream_closed_error
    raise CommClosedError(f"in {obj}: {exc.__class__.__name__}: {exc}") from exc
distributed.comm.core.CommClosedError: in <distributed.comm.tcp.TCPConnector object at 0x2abd93c4c820>: ConnectionRefusedError: [Errno 111] Connection refused

During handling of the above exception, another exception occurred:

Traceback (most recent call last):
  File "/vortexfs1/home/anthony.meza/mambaforge/envs/atm_rivers/lib/python3.10/site-packages/distributed/utils.py", line 752, in wrapper
    return await func(*args, **kwargs)
  File "/vortexfs1/home/anthony.meza/mambaforge/envs/atm_rivers/lib/python3.10/site-packages/distributed/client.py", line 1321, in _reconnect
    await self._ensure_connected(timeout=timeout)
  File "/vortexfs1/home/anthony.meza/mambaforge/envs/atm_rivers/lib/python3.10/site-packages/distributed/client.py", line 1351, in _ensure_connected
    comm = await connect(
  File "/vortexfs1/home/anthony.meza/mambaforge/envs/atm_rivers/lib/python3.10/site-packages/distributed/comm/core.py", line 316, in connect
    await asyncio.sleep(backoff)
  File "/vortexfs1/home/anthony.meza/mambaforge/envs/atm_rivers/lib/python3.10/asyncio/tasks.py", line 605, in sleep
    return await future
asyncio.exceptions.CancelledError
2023-05-03 09:35:31,716 - distributed.nanny - INFO - Worker closed
2023-05-03 09:35:33,724 - distributed.nanny - ERROR - Worker process died unexpectedly
2023-05-03 09:35:47,331 - distributed.nanny - INFO - Closing Nanny at 'tcp://172.16.3.168:36811'. Reason: nanny-close-gracefully
2023-05-03 09:35:47,332 - distributed.dask_worker - INFO - End worker
