2023-05-10 21:06:45,259 - distributed.nanny - INFO -         Start Nanny at: 'tcp://172.16.3.128:45385'
2023-05-10 21:06:46,730 - distributed.worker - INFO -       Start worker at:   tcp://172.16.3.128:40566
2023-05-10 21:06:46,730 - distributed.worker - INFO -          Listening to:   tcp://172.16.3.128:40566
2023-05-10 21:06:46,730 - distributed.worker - INFO -           Worker name:             SLURMCluster-5
2023-05-10 21:06:46,731 - distributed.worker - INFO -          dashboard at:         172.16.3.128:45646
2023-05-10 21:06:46,731 - distributed.worker - INFO - Waiting to connect to:    tcp://172.16.3.56:44943
2023-05-10 21:06:46,731 - distributed.worker - INFO - -------------------------------------------------
2023-05-10 21:06:46,731 - distributed.worker - INFO -               Threads:                         36
2023-05-10 21:06:46,731 - distributed.worker - INFO -                Memory:                  46.57 GiB
2023-05-10 21:06:46,731 - distributed.worker - INFO -       Local Directory: /tmp/dask-worker-space/worker-il3jskjr
2023-05-10 21:06:46,731 - distributed.worker - INFO - -------------------------------------------------
2023-05-10 21:06:46,735 - distributed.worker - INFO -         Registered to:    tcp://172.16.3.56:44943
2023-05-10 21:06:46,735 - distributed.worker - INFO - -------------------------------------------------
2023-05-10 21:06:46,735 - distributed.core - INFO - Starting established connection to tcp://172.16.3.56:44943
/vortexfs1/home/anthony.meza/mambaforge/envs/atm_rivers/lib/python3.10/site-packages/dask/core.py:119: RuntimeWarning: invalid value encountered in divide
  return func(*(_execute_task(a, cache) for a in args))
2023-05-10 21:08:27,728 - distributed.worker.memory - WARNING - Worker is at 81% memory usage. Pausing worker.  Process memory: 37.73 GiB -- Worker memory limit: 46.57 GiB
2023-05-10 21:08:27,755 - distributed.core - INFO - Event loop was unresponsive in Worker for 11.29s.  This is often caused by long-running GIL-holding functions or moving large chunks of data. This can cause timeouts and instability.
2023-05-10 21:08:31,515 - distributed.core - INFO - Removing comms to tcp://172.16.3.55:40722
2023-05-10 21:08:34,076 - distributed.nanny.memory - WARNING - Worker tcp://172.16.3.128:40566 (pid=364026) exceeded 95% memory budget. Restarting...
2023-05-10 21:08:37,976 - distributed.nanny - INFO - Worker process 364026 was killed by signal 15
2023-05-10 21:08:38,341 - distributed.nanny - WARNING - Restarting worker
2023-05-10 21:08:40,952 - distributed.worker - INFO -       Start worker at:   tcp://172.16.3.128:45461
2023-05-10 21:08:40,952 - distributed.worker - INFO -          Listening to:   tcp://172.16.3.128:45461
2023-05-10 21:08:40,953 - distributed.worker - INFO -           Worker name:             SLURMCluster-5
2023-05-10 21:08:40,953 - distributed.worker - INFO -          dashboard at:         172.16.3.128:40635
2023-05-10 21:08:40,953 - distributed.worker - INFO - Waiting to connect to:    tcp://172.16.3.56:44943
2023-05-10 21:08:40,953 - distributed.worker - INFO - -------------------------------------------------
2023-05-10 21:08:40,953 - distributed.worker - INFO -               Threads:                         36
2023-05-10 21:08:40,953 - distributed.worker - INFO -                Memory:                  46.57 GiB
2023-05-10 21:08:40,953 - distributed.worker - INFO -       Local Directory: /tmp/dask-worker-space/worker-ev3zp59q
2023-05-10 21:08:40,953 - distributed.worker - INFO - -------------------------------------------------
2023-05-10 21:08:40,960 - distributed.worker - INFO -         Registered to:    tcp://172.16.3.56:44943
2023-05-10 21:08:40,960 - distributed.worker - INFO - -------------------------------------------------
2023-05-10 21:08:40,960 - distributed.core - INFO - Starting established connection to tcp://172.16.3.56:44943
/vortexfs1/home/anthony.meza/mambaforge/envs/atm_rivers/lib/python3.10/site-packages/dask/core.py:119: RuntimeWarning: invalid value encountered in divide
  return func(*(_execute_task(a, cache) for a in args))
2023-05-10 21:11:04,096 - distributed.utils_perf - INFO - full garbage collection released 665.31 MiB from 95 reference cycles (threshold: 9.54 MiB)
2023-05-10 21:13:31,942 - distributed.worker.memory - WARNING - Worker is at 84% memory usage. Pausing worker.  Process memory: 39.18 GiB -- Worker memory limit: 46.57 GiB
2023-05-10 21:13:31,942 - distributed.core - INFO - Removing comms to tcp://172.16.3.55:40502
2023-05-10 21:13:32,029 - distributed.core - INFO - Event loop was unresponsive in Worker for 10.74s.  This is often caused by long-running GIL-holding functions or moving large chunks of data. This can cause timeouts and instability.
2023-05-10 21:13:39,074 - distributed.nanny.memory - WARNING - Worker tcp://172.16.3.128:45461 (pid=364282) exceeded 95% memory budget. Restarting...
2023-05-10 21:13:43,061 - distributed.nanny - INFO - Worker process 364282 was killed by signal 15
2023-05-10 21:13:53,430 - distributed.nanny - WARNING - Restarting worker
2023-05-10 21:14:01,524 - distributed.worker - INFO -       Start worker at:   tcp://172.16.3.128:45706
2023-05-10 21:14:01,525 - distributed.worker - INFO -          Listening to:   tcp://172.16.3.128:45706
2023-05-10 21:14:01,525 - distributed.worker - INFO -           Worker name:             SLURMCluster-5
2023-05-10 21:14:01,525 - distributed.worker - INFO -          dashboard at:         172.16.3.128:33596
2023-05-10 21:14:01,525 - distributed.worker - INFO - Waiting to connect to:    tcp://172.16.3.56:44943
2023-05-10 21:14:01,525 - distributed.worker - INFO - -------------------------------------------------
2023-05-10 21:14:01,526 - distributed.worker - INFO -               Threads:                         36
2023-05-10 21:14:01,526 - distributed.worker - INFO -                Memory:                  46.57 GiB
2023-05-10 21:14:01,526 - distributed.worker - INFO -       Local Directory: /tmp/dask-worker-space/worker-mfxd_6ts
2023-05-10 21:14:01,526 - distributed.worker - INFO - -------------------------------------------------
2023-05-10 21:14:31,526 - distributed.worker - INFO - Waiting to connect to:    tcp://172.16.3.56:44943
2023-05-10 21:14:53,431 - distributed.nanny - ERROR - Timed out connecting Nanny '<Nanny: tcp://172.16.3.128:45461, threads: 36>' to scheduler 'tcp://172.16.3.56:44943'
2023-05-10 21:14:53,432 - distributed.nanny - INFO - Closing Nanny at 'tcp://172.16.3.128:45385'. Reason: nanny-instantiate-timeout
2023-05-10 21:14:56,736 - distributed.worker - INFO - Stopping worker at tcp://172.16.3.128:45706. Reason: worker-close
2023-05-10 21:14:56,736 - distributed.worker - INFO - Closed worker has not yet started: Status.init
2023-05-10 21:14:56,739 - distributed.nanny - ERROR - Failed to start worker
ConnectionRefusedError: [Errno 111] Connection refused

The above exception was the direct cause of the following exception:

Traceback (most recent call last):
  File "/vortexfs1/home/anthony.meza/mambaforge/envs/atm_rivers/lib/python3.10/site-packages/distributed/comm/core.py", line 292, in connect
    comm = await wait_for(
  File "/vortexfs1/home/anthony.meza/mambaforge/envs/atm_rivers/lib/python3.10/site-packages/distributed/utils.py", line 1878, in wait_for
    return await asyncio.wait_for(fut, timeout)
  File "/vortexfs1/home/anthony.meza/mambaforge/envs/atm_rivers/lib/python3.10/asyncio/tasks.py", line 445, in wait_for
    return fut.result()
  File "/vortexfs1/home/anthony.meza/mambaforge/envs/atm_rivers/lib/python3.10/site-packages/distributed/comm/tcp.py", line 511, in connect
    convert_stream_closed_error(self, e)
  File "/vortexfs1/home/anthony.meza/mambaforge/envs/atm_rivers/lib/python3.10/site-packages/distributed/comm/tcp.py", line 142, in convert_stream_closed_error
    raise CommClosedError(f"in {obj}: {exc.__class__.__name__}: {exc}") from exc
distributed.comm.core.CommClosedError: in <distributed.comm.tcp.TCPConnector object at 0x2aaacb2973d0>: ConnectionRefusedError: [Errno 111] Connection refused

During handling of the above exception, another exception occurred:

Traceback (most recent call last):
  File "/vortexfs1/home/anthony.meza/mambaforge/envs/atm_rivers/lib/python3.10/site-packages/distributed/worker.py", line 1475, in start_unsafe
    await self._register_with_scheduler()
  File "/vortexfs1/home/anthony.meza/mambaforge/envs/atm_rivers/lib/python3.10/site-packages/distributed/worker.py", line 1165, in _register_with_scheduler
    comm = await connect(self.scheduler.address, **self.connection_args)
  File "/vortexfs1/home/anthony.meza/mambaforge/envs/atm_rivers/lib/python3.10/site-packages/distributed/comm/core.py", line 316, in connect
    await asyncio.sleep(backoff)
  File "/vortexfs1/home/anthony.meza/mambaforge/envs/atm_rivers/lib/python3.10/asyncio/tasks.py", line 605, in sleep
    return await future
asyncio.exceptions.CancelledError

During handling of the above exception, another exception occurred:

Traceback (most recent call last):
  File "/vortexfs1/home/anthony.meza/mambaforge/envs/atm_rivers/lib/python3.10/asyncio/tasks.py", line 456, in wait_for
    return fut.result()
asyncio.exceptions.CancelledError

The above exception was the direct cause of the following exception:

Traceback (most recent call last):
  File "/vortexfs1/home/anthony.meza/mambaforge/envs/atm_rivers/lib/python3.10/site-packages/distributed/core.py", line 537, in start
    await wait_for(self.start_unsafe(), timeout=timeout)
  File "/vortexfs1/home/anthony.meza/mambaforge/envs/atm_rivers/lib/python3.10/site-packages/distributed/utils.py", line 1878, in wait_for
    return await asyncio.wait_for(fut, timeout)
  File "/vortexfs1/home/anthony.meza/mambaforge/envs/atm_rivers/lib/python3.10/asyncio/tasks.py", line 458, in wait_for
    raise exceptions.TimeoutError() from exc
asyncio.exceptions.TimeoutError

The above exception was the direct cause of the following exception:

Traceback (most recent call last):
  File "/vortexfs1/home/anthony.meza/mambaforge/envs/atm_rivers/lib/python3.10/site-packages/distributed/nanny.py", line 932, in run
    async with worker:
  File "/vortexfs1/home/anthony.meza/mambaforge/envs/atm_rivers/lib/python3.10/site-packages/distributed/core.py", line 551, in __aenter__
    await self
  File "/vortexfs1/home/anthony.meza/mambaforge/envs/atm_rivers/lib/python3.10/site-packages/distributed/core.py", line 540, in start
    raise asyncio.TimeoutError(
asyncio.exceptions.TimeoutError: Worker start timed out after 60s.
slurmstepd: error: *** JOB 3090009 ON pn078 CANCELLED AT 2023-05-10T21:26:39 ***
