2023-05-02 17:33:00,262 - distributed.nanny - INFO -         Start Nanny at: 'tcp://172.16.3.188:42158'
2023-05-02 17:33:00,635 - distributed.diskutils - INFO - Found stale lock file and directory '/tmp/dask-worker-space/worker-jkhk93fl', purging
2023-05-02 17:33:01,662 - distributed.worker - INFO -       Start worker at:   tcp://172.16.3.188:44732
2023-05-02 17:33:01,662 - distributed.worker - INFO -          Listening to:   tcp://172.16.3.188:44732
2023-05-02 17:33:01,663 - distributed.worker - INFO -           Worker name:             SLURMCluster-4
2023-05-02 17:33:01,663 - distributed.worker - INFO -          dashboard at:         172.16.3.188:39486
2023-05-02 17:33:01,663 - distributed.worker - INFO - Waiting to connect to:   tcp://172.16.3.106:40988
2023-05-02 17:33:01,663 - distributed.worker - INFO - -------------------------------------------------
2023-05-02 17:33:01,663 - distributed.worker - INFO -               Threads:                         36
2023-05-02 17:33:01,663 - distributed.worker - INFO -                Memory:                  93.13 GiB
2023-05-02 17:33:01,663 - distributed.worker - INFO -       Local Directory: /tmp/dask-worker-space/worker-26a14i8n
2023-05-02 17:33:01,663 - distributed.worker - INFO - -------------------------------------------------
2023-05-02 17:33:01,668 - distributed.worker - INFO -         Registered to:   tcp://172.16.3.106:40988
2023-05-02 17:33:01,668 - distributed.worker - INFO - -------------------------------------------------
2023-05-02 17:33:01,668 - distributed.core - INFO - Starting established connection to tcp://172.16.3.106:40988
2023-05-02 17:33:58,037 - distributed.core - INFO - Event loop was unresponsive in Worker for 3.53s.  This is often caused by long-running GIL-holding functions or moving large chunks of data. This can cause timeouts and instability.
2023-05-02 17:34:20,155 - distributed.utils_perf - INFO - full garbage collection released 314.18 MiB from 204 reference cycles (threshold: 9.54 MiB)
2023-05-02 17:34:56,467 - distributed.utils_perf - INFO - full garbage collection released 358.55 MiB from 199 reference cycles (threshold: 9.54 MiB)
2023-05-02 17:35:17,029 - distributed.core - INFO - Event loop was unresponsive in Worker for 3.40s.  This is often caused by long-running GIL-holding functions or moving large chunks of data. This can cause timeouts and instability.
2023-05-02 17:35:20,645 - distributed.core - INFO - Event loop was unresponsive in Worker for 3.62s.  This is often caused by long-running GIL-holding functions or moving large chunks of data. This can cause timeouts and instability.
2023-05-02 17:35:29,956 - distributed.core - INFO - Event loop was unresponsive in Worker for 9.31s.  This is often caused by long-running GIL-holding functions or moving large chunks of data. This can cause timeouts and instability.
2023-05-02 17:35:49,978 - distributed.core - INFO - Event loop was unresponsive in Worker for 20.02s.  This is often caused by long-running GIL-holding functions or moving large chunks of data. This can cause timeouts and instability.
2023-05-02 17:35:57,294 - distributed.worker - ERROR - failed during get data with tcp://172.16.3.188:44732 -> tcp://172.16.3.167:38216
Traceback (most recent call last):
  File "/vortexfs1/home/anthony.meza/mambaforge/envs/atm_rivers/lib/python3.10/site-packages/distributed/comm/tcp.py", line 225, in read
    frames_nbytes = await stream.read_bytes(fmt_size)
tornado.iostream.StreamClosedError: Stream is closed

The above exception was the direct cause of the following exception:

Traceback (most recent call last):
  File "/vortexfs1/home/anthony.meza/mambaforge/envs/atm_rivers/lib/python3.10/site-packages/distributed/worker.py", line 1783, in get_data
    response = await comm.read(deserializers=serializers)
  File "/vortexfs1/home/anthony.meza/mambaforge/envs/atm_rivers/lib/python3.10/site-packages/distributed/comm/tcp.py", line 241, in read
    convert_stream_closed_error(self, e)
  File "/vortexfs1/home/anthony.meza/mambaforge/envs/atm_rivers/lib/python3.10/site-packages/distributed/comm/tcp.py", line 144, in convert_stream_closed_error
    raise CommClosedError(f"in {obj}: {exc}") from exc
distributed.comm.core.CommClosedError: in <TCP (closed)  local=tcp://172.16.3.188:44732 remote=tcp://172.16.3.167:43290>: Stream is closed
2023-05-02 17:35:57,298 - distributed.core - INFO - Lost connection to 'tcp://172.16.3.167:43290'
Traceback (most recent call last):
  File "/vortexfs1/home/anthony.meza/mambaforge/envs/atm_rivers/lib/python3.10/site-packages/distributed/comm/tcp.py", line 225, in read
    frames_nbytes = await stream.read_bytes(fmt_size)
tornado.iostream.StreamClosedError: Stream is closed

The above exception was the direct cause of the following exception:

Traceback (most recent call last):
  File "/vortexfs1/home/anthony.meza/mambaforge/envs/atm_rivers/lib/python3.10/site-packages/distributed/core.py", line 831, in _handle_comm
    result = await result
  File "/vortexfs1/home/anthony.meza/mambaforge/envs/atm_rivers/lib/python3.10/site-packages/distributed/core.py", line 990, in wrapper
    return await func(self, *args, **kwargs)
  File "/vortexfs1/home/anthony.meza/mambaforge/envs/atm_rivers/lib/python3.10/site-packages/distributed/worker.py", line 1783, in get_data
    response = await comm.read(deserializers=serializers)
  File "/vortexfs1/home/anthony.meza/mambaforge/envs/atm_rivers/lib/python3.10/site-packages/distributed/comm/tcp.py", line 241, in read
    convert_stream_closed_error(self, e)
  File "/vortexfs1/home/anthony.meza/mambaforge/envs/atm_rivers/lib/python3.10/site-packages/distributed/comm/tcp.py", line 144, in convert_stream_closed_error
    raise CommClosedError(f"in {obj}: {exc}") from exc
distributed.comm.core.CommClosedError: in <TCP (closed)  local=tcp://172.16.3.188:44732 remote=tcp://172.16.3.167:43290>: Stream is closed
2023-05-02 17:35:57,317 - distributed.worker - ERROR - failed during get data with tcp://172.16.3.188:44732 -> tcp://172.16.3.105:39501
Traceback (most recent call last):
  File "/vortexfs1/home/anthony.meza/mambaforge/envs/atm_rivers/lib/python3.10/site-packages/distributed/comm/tcp.py", line 317, in write
    raise StreamClosedError()
tornado.iostream.StreamClosedError: Stream is closed

The above exception was the direct cause of the following exception:

Traceback (most recent call last):
  File "/vortexfs1/home/anthony.meza/mambaforge/envs/atm_rivers/lib/python3.10/site-packages/distributed/worker.py", line 1782, in get_data
    compressed = await comm.write(msg, serializers=serializers)
  File "/vortexfs1/home/anthony.meza/mambaforge/envs/atm_rivers/lib/python3.10/site-packages/distributed/comm/tcp.py", line 328, in write
    convert_stream_closed_error(self, e)
  File "/vortexfs1/home/anthony.meza/mambaforge/envs/atm_rivers/lib/python3.10/site-packages/distributed/comm/tcp.py", line 144, in convert_stream_closed_error
    raise CommClosedError(f"in {obj}: {exc}") from exc
distributed.comm.core.CommClosedError: in <TCP (closed)  local=tcp://172.16.3.188:44732 remote=tcp://172.16.3.105:50220>: Stream is closed
2023-05-02 17:35:57,317 - distributed.core - INFO - Lost connection to 'tcp://172.16.3.105:50220'
Traceback (most recent call last):
  File "/vortexfs1/home/anthony.meza/mambaforge/envs/atm_rivers/lib/python3.10/site-packages/distributed/comm/tcp.py", line 317, in write
    raise StreamClosedError()
tornado.iostream.StreamClosedError: Stream is closed

The above exception was the direct cause of the following exception:

Traceback (most recent call last):
  File "/vortexfs1/home/anthony.meza/mambaforge/envs/atm_rivers/lib/python3.10/site-packages/distributed/core.py", line 831, in _handle_comm
    result = await result
  File "/vortexfs1/home/anthony.meza/mambaforge/envs/atm_rivers/lib/python3.10/site-packages/distributed/core.py", line 990, in wrapper
    return await func(self, *args, **kwargs)
  File "/vortexfs1/home/anthony.meza/mambaforge/envs/atm_rivers/lib/python3.10/site-packages/distributed/worker.py", line 1782, in get_data
    compressed = await comm.write(msg, serializers=serializers)
  File "/vortexfs1/home/anthony.meza/mambaforge/envs/atm_rivers/lib/python3.10/site-packages/distributed/comm/tcp.py", line 328, in write
    convert_stream_closed_error(self, e)
  File "/vortexfs1/home/anthony.meza/mambaforge/envs/atm_rivers/lib/python3.10/site-packages/distributed/comm/tcp.py", line 144, in convert_stream_closed_error
    raise CommClosedError(f"in {obj}: {exc}") from exc
distributed.comm.core.CommClosedError: in <TCP (closed)  local=tcp://172.16.3.188:44732 remote=tcp://172.16.3.105:50220>: Stream is closed
2023-05-02 17:36:03,049 - distributed.core - INFO - Event loop was unresponsive in Worker for 13.07s.  This is often caused by long-running GIL-holding functions or moving large chunks of data. This can cause timeouts and instability.
2023-05-02 17:36:03,059 - distributed.worker - ERROR - failed during get data with tcp://172.16.3.188:44732 -> tcp://172.16.3.187:46233
Traceback (most recent call last):
  File "/vortexfs1/home/anthony.meza/mambaforge/envs/atm_rivers/lib/python3.10/site-packages/distributed/comm/tcp.py", line 317, in write
    raise StreamClosedError()
tornado.iostream.StreamClosedError: Stream is closed

The above exception was the direct cause of the following exception:

Traceback (most recent call last):
  File "/vortexfs1/home/anthony.meza/mambaforge/envs/atm_rivers/lib/python3.10/site-packages/distributed/worker.py", line 1782, in get_data
    compressed = await comm.write(msg, serializers=serializers)
  File "/vortexfs1/home/anthony.meza/mambaforge/envs/atm_rivers/lib/python3.10/site-packages/distributed/comm/tcp.py", line 328, in write
    convert_stream_closed_error(self, e)
  File "/vortexfs1/home/anthony.meza/mambaforge/envs/atm_rivers/lib/python3.10/site-packages/distributed/comm/tcp.py", line 144, in convert_stream_closed_error
    raise CommClosedError(f"in {obj}: {exc}") from exc
distributed.comm.core.CommClosedError: in <TCP (closed)  local=tcp://172.16.3.188:44732 remote=tcp://172.16.3.187:42470>: Stream is closed
2023-05-02 17:36:03,059 - distributed.core - INFO - Lost connection to 'tcp://172.16.3.187:42470'
Traceback (most recent call last):
  File "/vortexfs1/home/anthony.meza/mambaforge/envs/atm_rivers/lib/python3.10/site-packages/distributed/comm/tcp.py", line 317, in write
    raise StreamClosedError()
tornado.iostream.StreamClosedError: Stream is closed

The above exception was the direct cause of the following exception:

Traceback (most recent call last):
  File "/vortexfs1/home/anthony.meza/mambaforge/envs/atm_rivers/lib/python3.10/site-packages/distributed/core.py", line 831, in _handle_comm
    result = await result
  File "/vortexfs1/home/anthony.meza/mambaforge/envs/atm_rivers/lib/python3.10/site-packages/distributed/core.py", line 990, in wrapper
    return await func(self, *args, **kwargs)
  File "/vortexfs1/home/anthony.meza/mambaforge/envs/atm_rivers/lib/python3.10/site-packages/distributed/worker.py", line 1782, in get_data
    compressed = await comm.write(msg, serializers=serializers)
  File "/vortexfs1/home/anthony.meza/mambaforge/envs/atm_rivers/lib/python3.10/site-packages/distributed/comm/tcp.py", line 328, in write
    convert_stream_closed_error(self, e)
  File "/vortexfs1/home/anthony.meza/mambaforge/envs/atm_rivers/lib/python3.10/site-packages/distributed/comm/tcp.py", line 144, in convert_stream_closed_error
    raise CommClosedError(f"in {obj}: {exc}") from exc
distributed.comm.core.CommClosedError: in <TCP (closed)  local=tcp://172.16.3.188:44732 remote=tcp://172.16.3.187:42470>: Stream is closed
2023-05-02 17:36:03,712 - distributed.core - INFO - Connection to tcp://172.16.3.106:40988 has been closed.
2023-05-02 17:36:03,713 - distributed.worker - INFO - Stopping worker at tcp://172.16.3.188:44732. Reason: worker-handle-scheduler-connection-broken
2023-05-02 17:36:03,713 - distributed.batched - INFO - Batched Comm Closed <TCP (closed) Worker->Scheduler local=tcp://172.16.3.188:51635 remote=tcp://172.16.3.106:40988>
Traceback (most recent call last):
  File "/vortexfs1/home/anthony.meza/mambaforge/envs/atm_rivers/lib/python3.10/site-packages/distributed/comm/tcp.py", line 317, in write
    raise StreamClosedError()
tornado.iostream.StreamClosedError: Stream is closed

The above exception was the direct cause of the following exception:

Traceback (most recent call last):
  File "/vortexfs1/home/anthony.meza/mambaforge/envs/atm_rivers/lib/python3.10/site-packages/distributed/batched.py", line 115, in _background_send
    nbytes = yield coro
  File "/vortexfs1/home/anthony.meza/mambaforge/envs/atm_rivers/lib/python3.10/site-packages/tornado/gen.py", line 767, in run
    value = future.result()
  File "/vortexfs1/home/anthony.meza/mambaforge/envs/atm_rivers/lib/python3.10/site-packages/distributed/comm/tcp.py", line 328, in write
    convert_stream_closed_error(self, e)
  File "/vortexfs1/home/anthony.meza/mambaforge/envs/atm_rivers/lib/python3.10/site-packages/distributed/comm/tcp.py", line 144, in convert_stream_closed_error
    raise CommClosedError(f"in {obj}: {exc}") from exc
distributed.comm.core.CommClosedError: in <TCP (closed) Worker->Scheduler local=tcp://172.16.3.188:51635 remote=tcp://172.16.3.106:40988>: Stream is closed
2023-05-02 17:36:03,744 - distributed.nanny - INFO - Closing Nanny gracefully at 'tcp://172.16.3.188:42158'. Reason: worker-handle-scheduler-connection-broken
2023-05-02 17:36:14,159 - distributed.worker - ERROR - Failed to communicate with scheduler during heartbeat.
ConnectionRefusedError: [Errno 111] Connection refused

The above exception was the direct cause of the following exception:

Traceback (most recent call last):
  File "/vortexfs1/home/anthony.meza/mambaforge/envs/atm_rivers/lib/python3.10/site-packages/distributed/comm/core.py", line 292, in connect
    comm = await wait_for(
  File "/vortexfs1/home/anthony.meza/mambaforge/envs/atm_rivers/lib/python3.10/site-packages/distributed/utils.py", line 1850, in wait_for
    return await asyncio.wait_for(fut, timeout)
  File "/vortexfs1/home/anthony.meza/mambaforge/envs/atm_rivers/lib/python3.10/asyncio/tasks.py", line 445, in wait_for
    return fut.result()
  File "/vortexfs1/home/anthony.meza/mambaforge/envs/atm_rivers/lib/python3.10/site-packages/distributed/comm/tcp.py", line 511, in connect
    convert_stream_closed_error(self, e)
  File "/vortexfs1/home/anthony.meza/mambaforge/envs/atm_rivers/lib/python3.10/site-packages/distributed/comm/tcp.py", line 142, in convert_stream_closed_error
    raise CommClosedError(f"in {obj}: {exc.__class__.__name__}: {exc}") from exc
distributed.comm.core.CommClosedError: in <distributed.comm.tcp.TCPConnector object at 0x2aab72438820>: ConnectionRefusedError: [Errno 111] Connection refused

During handling of the above exception, another exception occurred:

Traceback (most recent call last):
  File "/vortexfs1/home/anthony.meza/mambaforge/envs/atm_rivers/lib/python3.10/site-packages/distributed/core.py", line 1430, in _connect
    comm = await connect(
  File "/vortexfs1/home/anthony.meza/mambaforge/envs/atm_rivers/lib/python3.10/site-packages/distributed/comm/core.py", line 316, in connect
    await asyncio.sleep(backoff)
  File "/vortexfs1/home/anthony.meza/mambaforge/envs/atm_rivers/lib/python3.10/asyncio/tasks.py", line 605, in sleep
    return await future
asyncio.exceptions.CancelledError

During handling of the above exception, another exception occurred:

Traceback (most recent call last):
  File "/vortexfs1/home/anthony.meza/mambaforge/envs/atm_rivers/lib/python3.10/site-packages/distributed/worker.py", line 1234, in heartbeat
    response = await retry_operation(
  File "/vortexfs1/home/anthony.meza/mambaforge/envs/atm_rivers/lib/python3.10/site-packages/distributed/utils_comm.py", line 434, in retry_operation
    return await retry(
  File "/vortexfs1/home/anthony.meza/mambaforge/envs/atm_rivers/lib/python3.10/site-packages/distributed/utils_comm.py", line 413, in retry
    return await coro()
  File "/vortexfs1/home/anthony.meza/mambaforge/envs/atm_rivers/lib/python3.10/site-packages/distributed/core.py", line 1265, in send_recv_from_rpc
    comm = await self.pool.connect(self.addr)
  File "/vortexfs1/home/anthony.meza/mambaforge/envs/atm_rivers/lib/python3.10/site-packages/distributed/core.py", line 1509, in connect
    return await connect_attempt
  File "/vortexfs1/home/anthony.meza/mambaforge/envs/atm_rivers/lib/python3.10/site-packages/distributed/core.py", line 1453, in _connect
    raise CommClosedError(reason)
distributed.comm.core.CommClosedError: ConnectionPool closing.
2023-05-02 17:36:14,210 - distributed.nanny - INFO - Worker closed
2023-05-02 17:36:16,212 - distributed.nanny - ERROR - Worker process died unexpectedly
2023-05-02 17:36:17,809 - distributed.nanny - INFO - Closing Nanny at 'tcp://172.16.3.188:42158'. Reason: nanny-close-gracefully
2023-05-02 17:36:17,810 - distributed.dask_worker - INFO - End worker
