2023-04-20 15:16:29,985 - distributed.nanny - INFO -         Start Nanny at: 'tcp://172.16.3.168:42784'
2023-04-20 15:16:30,689 - distributed.diskutils - INFO - Found stale lock file and directory '/tmp/dask-worker-space/worker-yyzw0dot', purging
2023-04-20 15:16:35,366 - distributed.worker - INFO -       Start worker at:   tcp://172.16.3.168:35640
2023-04-20 15:16:35,366 - distributed.worker - INFO -          Listening to:   tcp://172.16.3.168:35640
2023-04-20 15:16:35,366 - distributed.worker - INFO -           Worker name:             SLURMCluster-6
2023-04-20 15:16:35,366 - distributed.worker - INFO -          dashboard at:         172.16.3.168:35715
2023-04-20 15:16:35,366 - distributed.worker - INFO - Waiting to connect to:   tcp://172.16.3.161:33683
2023-04-20 15:16:35,366 - distributed.worker - INFO - -------------------------------------------------
2023-04-20 15:16:35,366 - distributed.worker - INFO -               Threads:                         36
2023-04-20 15:16:35,367 - distributed.worker - INFO -                Memory:                  93.13 GiB
2023-04-20 15:16:35,367 - distributed.worker - INFO -       Local Directory: /tmp/dask-worker-space/worker-tvppkfh8
2023-04-20 15:16:35,367 - distributed.worker - INFO - -------------------------------------------------
2023-04-20 15:16:35,372 - distributed.worker - INFO -         Registered to:   tcp://172.16.3.161:33683
2023-04-20 15:16:35,372 - distributed.worker - INFO - -------------------------------------------------
2023-04-20 15:16:35,373 - distributed.core - INFO - Starting established connection to tcp://172.16.3.161:33683
2023-04-20 15:40:01,734 - distributed.worker - ERROR - Exception during execution of task ('getitem-sub-mean_chunk-52306cb101f0aaae2c6b5c43f285c007', 8, 0, 0).
Traceback (most recent call last):
  File "/vortexfs1/home/anthony.meza/.conda/envs/notebook_env/lib/python3.10/site-packages/distributed/worker.py", line 2337, in _prepare_args_for_execution
    data[k] = self.data[k]
  File "/vortexfs1/home/anthony.meza/.conda/envs/notebook_env/lib/python3.10/site-packages/zict/buffer.py", line 108, in __getitem__
    raise KeyError(key)
KeyError: "('rechunk-merge-a848b390727fa5e163e2da1fece02263', 9, 0, 0, 0)"

During handling of the above exception, another exception occurred:

Traceback (most recent call last):
  File "/vortexfs1/home/anthony.meza/.conda/envs/notebook_env/lib/python3.10/site-packages/distributed/worker.py", line 2235, in execute
    args2, kwargs2 = self._prepare_args_for_execution(ts, args, kwargs)
  File "/vortexfs1/home/anthony.meza/.conda/envs/notebook_env/lib/python3.10/site-packages/distributed/worker.py", line 2341, in _prepare_args_for_execution
    data[k] = Actor(type(self.state.actors[k]), self.address, k, self)
KeyError: "('rechunk-merge-a848b390727fa5e163e2da1fece02263', 9, 0, 0, 0)"
2023-04-20 15:40:03,441 - distributed.worker - ERROR - Failed to communicate with scheduler during heartbeat.
Traceback (most recent call last):
  File "/vortexfs1/home/anthony.meza/.conda/envs/notebook_env/lib/python3.10/site-packages/tornado/iostream.py", line 867, in _read_to_buffer
    bytes_read = self.read_from_fd(buf)
  File "/vortexfs1/home/anthony.meza/.conda/envs/notebook_env/lib/python3.10/site-packages/tornado/iostream.py", line 1140, in read_from_fd
    return self.socket.recv_into(buf, len(buf))
ConnectionResetError: [Errno 104] Connection reset by peer

The above exception was the direct cause of the following exception:

Traceback (most recent call last):
  File "/vortexfs1/home/anthony.meza/.conda/envs/notebook_env/lib/python3.10/site-packages/distributed/worker.py", line 1215, in heartbeat
    response = await retry_operation(
  File "/vortexfs1/home/anthony.meza/.conda/envs/notebook_env/lib/python3.10/site-packages/distributed/utils_comm.py", line 386, in retry_operation
    return await retry(
  File "/vortexfs1/home/anthony.meza/.conda/envs/notebook_env/lib/python3.10/site-packages/distributed/utils_comm.py", line 371, in retry
    return await coro()
  File "/vortexfs1/home/anthony.meza/.conda/envs/notebook_env/lib/python3.10/site-packages/distributed/core.py", line 1163, in send_recv_from_rpc
    return await send_recv(comm=comm, op=key, **kwargs)
  File "/vortexfs1/home/anthony.meza/.conda/envs/notebook_env/lib/python3.10/site-packages/distributed/core.py", line 928, in send_recv
    response = await comm.read(deserializers=deserializers)
  File "/vortexfs1/home/anthony.meza/.conda/envs/notebook_env/lib/python3.10/site-packages/distributed/comm/tcp.py", line 241, in read
    convert_stream_closed_error(self, e)
  File "/vortexfs1/home/anthony.meza/.conda/envs/notebook_env/lib/python3.10/site-packages/distributed/comm/tcp.py", line 142, in convert_stream_closed_error
    raise CommClosedError(f"in {obj}: {exc.__class__.__name__}: {exc}") from exc
distributed.comm.core.CommClosedError: in <TCP (closed) ConnectionPool.heartbeat_worker local=tcp://172.16.3.168:35453 remote=tcp://172.16.3.161:33683>: ConnectionResetError: [Errno 104] Connection reset by peer
2023-04-20 15:40:03,446 - distributed.core - INFO - Connection to tcp://172.16.3.161:33683 has been closed.
2023-04-20 15:40:03,446 - distributed.worker - INFO - Stopping worker at tcp://172.16.3.168:35640. Reason: worker-handle-scheduler-connection-broken
2023-04-20 15:40:03,449 - distributed.nanny - INFO - Closing Nanny gracefully at 'tcp://172.16.3.168:42784'. Reason: worker-handle-scheduler-connection-broken
2023-04-20 15:40:03,455 - distributed.nanny - INFO - Worker closed
2023-04-20 15:40:05,459 - distributed.nanny - ERROR - Worker process died unexpectedly
2023-04-20 15:40:05,751 - distributed.nanny - INFO - Closing Nanny at 'tcp://172.16.3.168:42784'. Reason: nanny-close-gracefully
2023-04-20 15:40:05,752 - distributed.dask_worker - INFO - End worker
