2023-05-01 12:30:06,270 - distributed.nanny - INFO -         Start Nanny at: 'tcp://172.16.3.97:41868'
2023-05-01 12:30:15,103 - distributed.worker - INFO -       Start worker at:    tcp://172.16.3.97:45929
2023-05-01 12:30:15,103 - distributed.worker - INFO -          Listening to:    tcp://172.16.3.97:45929
2023-05-01 12:30:15,103 - distributed.worker - INFO -           Worker name:             SLURMCluster-3
2023-05-01 12:30:15,103 - distributed.worker - INFO -          dashboard at:          172.16.3.97:37867
2023-05-01 12:30:15,103 - distributed.worker - INFO - Waiting to connect to:    tcp://172.16.3.62:37872
2023-05-01 12:30:15,103 - distributed.worker - INFO - -------------------------------------------------
2023-05-01 12:30:15,103 - distributed.worker - INFO -               Threads:                         36
2023-05-01 12:30:15,103 - distributed.worker - INFO -                Memory:                 178.81 GiB
2023-05-01 12:30:15,103 - distributed.worker - INFO -       Local Directory: /tmp/dask-worker-space/worker-h06kxfff
2023-05-01 12:30:15,103 - distributed.worker - INFO - -------------------------------------------------
2023-05-01 12:30:15,113 - distributed.worker - INFO -         Registered to:    tcp://172.16.3.62:37872
2023-05-01 12:30:15,114 - distributed.worker - INFO - -------------------------------------------------
2023-05-01 12:30:15,114 - distributed.core - INFO - Starting established connection to tcp://172.16.3.62:37872
2023-05-01 12:32:45,126 - distributed.worker - ERROR - Exception during execution of task _preprocess-1661736d-6b68-4b52-bacb-5c757d43105b.
Traceback (most recent call last):
  File "/vortexfs1/home/anthony.meza/mambaforge/envs/atm_rivers/lib/python3.10/site-packages/zict/buffer.py", line 184, in __getitem__
    return self.fast[key]
  File "/vortexfs1/home/anthony.meza/mambaforge/envs/atm_rivers/lib/python3.10/site-packages/zict/common.py", line 127, in wrapper
    return func(*args, **kwargs)
  File "/vortexfs1/home/anthony.meza/mambaforge/envs/atm_rivers/lib/python3.10/site-packages/zict/lru.py", line 117, in __getitem__
    result = self.d[key]
KeyError: 'open_dataset-075ade1b-7f53-4db6-b6e1-2153ddc1ceae'

During handling of the above exception, another exception occurred:

Traceback (most recent call last):
  File "/vortexfs1/home/anthony.meza/mambaforge/envs/atm_rivers/lib/python3.10/site-packages/distributed/worker.py", line 2381, in _prepare_args_for_execution
    data[k] = self.data[k]
  File "/vortexfs1/home/anthony.meza/mambaforge/envs/atm_rivers/lib/python3.10/site-packages/distributed/spill.py", line 223, in __getitem__
    return super().__getitem__(key)
  File "/vortexfs1/home/anthony.meza/mambaforge/envs/atm_rivers/lib/python3.10/site-packages/zict/common.py", line 127, in wrapper
    return func(*args, **kwargs)
  File "/vortexfs1/home/anthony.meza/mambaforge/envs/atm_rivers/lib/python3.10/site-packages/zict/buffer.py", line 186, in __getitem__
    return self.slow_to_fast(key)
  File "/vortexfs1/home/anthony.meza/mambaforge/envs/atm_rivers/lib/python3.10/site-packages/zict/buffer.py", line 153, in slow_to_fast
    value = self.slow[key]
  File "/vortexfs1/home/anthony.meza/mambaforge/envs/atm_rivers/lib/python3.10/site-packages/zict/common.py", line 127, in wrapper
    return func(*args, **kwargs)
  File "/vortexfs1/home/anthony.meza/mambaforge/envs/atm_rivers/lib/python3.10/site-packages/zict/cache.py", line 67, in __getitem__
    gen = self._last_updated[key]
KeyError: 'open_dataset-075ade1b-7f53-4db6-b6e1-2153ddc1ceae'

During handling of the above exception, another exception occurred:

Traceback (most recent call last):
  File "/vortexfs1/home/anthony.meza/mambaforge/envs/atm_rivers/lib/python3.10/site-packages/distributed/worker.py", line 2249, in execute
    args2, kwargs2 = self._prepare_args_for_execution(ts, args, kwargs)
  File "/vortexfs1/home/anthony.meza/mambaforge/envs/atm_rivers/lib/python3.10/site-packages/distributed/worker.py", line 2385, in _prepare_args_for_execution
    data[k] = Actor(type(self.state.actors[k]), self.address, k, self)
KeyError: 'open_dataset-075ade1b-7f53-4db6-b6e1-2153ddc1ceae'
2023-05-01 12:32:45,129 - distributed.worker - ERROR - Exception during execution of task getattr-cddffb2f-914d-4016-b3a6-70b9bd55a427.
Traceback (most recent call last):
  File "/vortexfs1/home/anthony.meza/mambaforge/envs/atm_rivers/lib/python3.10/site-packages/zict/buffer.py", line 184, in __getitem__
    return self.fast[key]
  File "/vortexfs1/home/anthony.meza/mambaforge/envs/atm_rivers/lib/python3.10/site-packages/zict/common.py", line 127, in wrapper
    return func(*args, **kwargs)
  File "/vortexfs1/home/anthony.meza/mambaforge/envs/atm_rivers/lib/python3.10/site-packages/zict/lru.py", line 117, in __getitem__
    result = self.d[key]
KeyError: 'open_dataset-075ade1b-7f53-4db6-b6e1-2153ddc1ceae'

During handling of the above exception, another exception occurred:

Traceback (most recent call last):
  File "/vortexfs1/home/anthony.meza/mambaforge/envs/atm_rivers/lib/python3.10/site-packages/distributed/worker.py", line 2381, in _prepare_args_for_execution
    data[k] = self.data[k]
  File "/vortexfs1/home/anthony.meza/mambaforge/envs/atm_rivers/lib/python3.10/site-packages/distributed/spill.py", line 223, in __getitem__
    return super().__getitem__(key)
  File "/vortexfs1/home/anthony.meza/mambaforge/envs/atm_rivers/lib/python3.10/site-packages/zict/common.py", line 127, in wrapper
    return func(*args, **kwargs)
  File "/vortexfs1/home/anthony.meza/mambaforge/envs/atm_rivers/lib/python3.10/site-packages/zict/buffer.py", line 186, in __getitem__
    return self.slow_to_fast(key)
  File "/vortexfs1/home/anthony.meza/mambaforge/envs/atm_rivers/lib/python3.10/site-packages/zict/buffer.py", line 153, in slow_to_fast
    value = self.slow[key]
  File "/vortexfs1/home/anthony.meza/mambaforge/envs/atm_rivers/lib/python3.10/site-packages/zict/common.py", line 127, in wrapper
    return func(*args, **kwargs)
  File "/vortexfs1/home/anthony.meza/mambaforge/envs/atm_rivers/lib/python3.10/site-packages/zict/cache.py", line 67, in __getitem__
    gen = self._last_updated[key]
KeyError: 'open_dataset-075ade1b-7f53-4db6-b6e1-2153ddc1ceae'

During handling of the above exception, another exception occurred:

Traceback (most recent call last):
  File "/vortexfs1/home/anthony.meza/mambaforge/envs/atm_rivers/lib/python3.10/site-packages/distributed/worker.py", line 2249, in execute
    args2, kwargs2 = self._prepare_args_for_execution(ts, args, kwargs)
  File "/vortexfs1/home/anthony.meza/mambaforge/envs/atm_rivers/lib/python3.10/site-packages/distributed/worker.py", line 2385, in _prepare_args_for_execution
    data[k] = Actor(type(self.state.actors[k]), self.address, k, self)
KeyError: 'open_dataset-075ade1b-7f53-4db6-b6e1-2153ddc1ceae'
2023-05-01 12:32:45,130 - distributed.worker - ERROR - Exception during execution of task _preprocess-7cd39dbc-bea2-447b-9298-69e66b66d12d.
Traceback (most recent call last):
  File "/vortexfs1/home/anthony.meza/mambaforge/envs/atm_rivers/lib/python3.10/site-packages/zict/buffer.py", line 184, in __getitem__
    return self.fast[key]
  File "/vortexfs1/home/anthony.meza/mambaforge/envs/atm_rivers/lib/python3.10/site-packages/zict/common.py", line 127, in wrapper
    return func(*args, **kwargs)
  File "/vortexfs1/home/anthony.meza/mambaforge/envs/atm_rivers/lib/python3.10/site-packages/zict/lru.py", line 117, in __getitem__
    result = self.d[key]
KeyError: 'open_dataset-1212f522-7073-4588-b380-b4b18b2013cc'

During handling of the above exception, another exception occurred:

Traceback (most recent call last):
  File "/vortexfs1/home/anthony.meza/mambaforge/envs/atm_rivers/lib/python3.10/site-packages/distributed/worker.py", line 2381, in _prepare_args_for_execution
    data[k] = self.data[k]
  File "/vortexfs1/home/anthony.meza/mambaforge/envs/atm_rivers/lib/python3.10/site-packages/distributed/spill.py", line 223, in __getitem__
    return super().__getitem__(key)
  File "/vortexfs1/home/anthony.meza/mambaforge/envs/atm_rivers/lib/python3.10/site-packages/zict/common.py", line 127, in wrapper
    return func(*args, **kwargs)
  File "/vortexfs1/home/anthony.meza/mambaforge/envs/atm_rivers/lib/python3.10/site-packages/zict/buffer.py", line 186, in __getitem__
    return self.slow_to_fast(key)
  File "/vortexfs1/home/anthony.meza/mambaforge/envs/atm_rivers/lib/python3.10/site-packages/zict/buffer.py", line 153, in slow_to_fast
    value = self.slow[key]
  File "/vortexfs1/home/anthony.meza/mambaforge/envs/atm_rivers/lib/python3.10/site-packages/zict/common.py", line 127, in wrapper
    return func(*args, **kwargs)
  File "/vortexfs1/home/anthony.meza/mambaforge/envs/atm_rivers/lib/python3.10/site-packages/zict/cache.py", line 67, in __getitem__
    gen = self._last_updated[key]
KeyError: 'open_dataset-1212f522-7073-4588-b380-b4b18b2013cc'

During handling of the above exception, another exception occurred:

Traceback (most recent call last):
  File "/vortexfs1/home/anthony.meza/mambaforge/envs/atm_rivers/lib/python3.10/site-packages/distributed/worker.py", line 2249, in execute
    args2, kwargs2 = self._prepare_args_for_execution(ts, args, kwargs)
  File "/vortexfs1/home/anthony.meza/mambaforge/envs/atm_rivers/lib/python3.10/site-packages/distributed/worker.py", line 2385, in _prepare_args_for_execution
    data[k] = Actor(type(self.state.actors[k]), self.address, k, self)
KeyError: 'open_dataset-1212f522-7073-4588-b380-b4b18b2013cc'
2023-05-01 12:32:45,130 - distributed.worker - ERROR - Exception during execution of task getattr-ef8fa1da-c8ab-46d2-ac47-5043fdd7ec8b.
Traceback (most recent call last):
  File "/vortexfs1/home/anthony.meza/mambaforge/envs/atm_rivers/lib/python3.10/site-packages/zict/buffer.py", line 184, in __getitem__
    return self.fast[key]
  File "/vortexfs1/home/anthony.meza/mambaforge/envs/atm_rivers/lib/python3.10/site-packages/zict/common.py", line 127, in wrapper
    return func(*args, **kwargs)
  File "/vortexfs1/home/anthony.meza/mambaforge/envs/atm_rivers/lib/python3.10/site-packages/zict/lru.py", line 117, in __getitem__
    result = self.d[key]
KeyError: 'open_dataset-1212f522-7073-4588-b380-b4b18b2013cc'

During handling of the above exception, another exception occurred:

Traceback (most recent call last):
  File "/vortexfs1/home/anthony.meza/mambaforge/envs/atm_rivers/lib/python3.10/site-packages/distributed/worker.py", line 2381, in _prepare_args_for_execution
    data[k] = self.data[k]
  File "/vortexfs1/home/anthony.meza/mambaforge/envs/atm_rivers/lib/python3.10/site-packages/distributed/spill.py", line 223, in __getitem__
    return super().__getitem__(key)
  File "/vortexfs1/home/anthony.meza/mambaforge/envs/atm_rivers/lib/python3.10/site-packages/zict/common.py", line 127, in wrapper
    return func(*args, **kwargs)
  File "/vortexfs1/home/anthony.meza/mambaforge/envs/atm_rivers/lib/python3.10/site-packages/zict/buffer.py", line 186, in __getitem__
    return self.slow_to_fast(key)
  File "/vortexfs1/home/anthony.meza/mambaforge/envs/atm_rivers/lib/python3.10/site-packages/zict/buffer.py", line 153, in slow_to_fast
    value = self.slow[key]
  File "/vortexfs1/home/anthony.meza/mambaforge/envs/atm_rivers/lib/python3.10/site-packages/zict/common.py", line 127, in wrapper
    return func(*args, **kwargs)
  File "/vortexfs1/home/anthony.meza/mambaforge/envs/atm_rivers/lib/python3.10/site-packages/zict/cache.py", line 67, in __getitem__
    gen = self._last_updated[key]
KeyError: 'open_dataset-1212f522-7073-4588-b380-b4b18b2013cc'

During handling of the above exception, another exception occurred:

Traceback (most recent call last):
  File "/vortexfs1/home/anthony.meza/mambaforge/envs/atm_rivers/lib/python3.10/site-packages/distributed/worker.py", line 2249, in execute
    args2, kwargs2 = self._prepare_args_for_execution(ts, args, kwargs)
  File "/vortexfs1/home/anthony.meza/mambaforge/envs/atm_rivers/lib/python3.10/site-packages/distributed/worker.py", line 2385, in _prepare_args_for_execution
    data[k] = Actor(type(self.state.actors[k]), self.address, k, self)
KeyError: 'open_dataset-1212f522-7073-4588-b380-b4b18b2013cc'
2023-05-01 12:32:45,131 - distributed.worker - ERROR - Exception during execution of task _preprocess-104df6a9-cee8-4883-ae1a-59b6059f820b.
Traceback (most recent call last):
  File "/vortexfs1/home/anthony.meza/mambaforge/envs/atm_rivers/lib/python3.10/site-packages/zict/buffer.py", line 184, in __getitem__
    return self.fast[key]
  File "/vortexfs1/home/anthony.meza/mambaforge/envs/atm_rivers/lib/python3.10/site-packages/zict/common.py", line 127, in wrapper
    return func(*args, **kwargs)
  File "/vortexfs1/home/anthony.meza/mambaforge/envs/atm_rivers/lib/python3.10/site-packages/zict/lru.py", line 117, in __getitem__
    result = self.d[key]
KeyError: 'open_dataset-a32832fa-f402-417b-b563-1dd748ba02f3'

During handling of the above exception, another exception occurred:

Traceback (most recent call last):
  File "/vortexfs1/home/anthony.meza/mambaforge/envs/atm_rivers/lib/python3.10/site-packages/distributed/worker.py", line 2381, in _prepare_args_for_execution
    data[k] = self.data[k]
  File "/vortexfs1/home/anthony.meza/mambaforge/envs/atm_rivers/lib/python3.10/site-packages/distributed/spill.py", line 223, in __getitem__
    return super().__getitem__(key)
  File "/vortexfs1/home/anthony.meza/mambaforge/envs/atm_rivers/lib/python3.10/site-packages/zict/common.py", line 127, in wrapper
    return func(*args, **kwargs)
  File "/vortexfs1/home/anthony.meza/mambaforge/envs/atm_rivers/lib/python3.10/site-packages/zict/buffer.py", line 186, in __getitem__
    return self.slow_to_fast(key)
  File "/vortexfs1/home/anthony.meza/mambaforge/envs/atm_rivers/lib/python3.10/site-packages/zict/buffer.py", line 153, in slow_to_fast
    value = self.slow[key]
  File "/vortexfs1/home/anthony.meza/mambaforge/envs/atm_rivers/lib/python3.10/site-packages/zict/common.py", line 127, in wrapper
    return func(*args, **kwargs)
  File "/vortexfs1/home/anthony.meza/mambaforge/envs/atm_rivers/lib/python3.10/site-packages/zict/cache.py", line 67, in __getitem__
    gen = self._last_updated[key]
KeyError: 'open_dataset-a32832fa-f402-417b-b563-1dd748ba02f3'

During handling of the above exception, another exception occurred:

Traceback (most recent call last):
  File "/vortexfs1/home/anthony.meza/mambaforge/envs/atm_rivers/lib/python3.10/site-packages/distributed/worker.py", line 2249, in execute
    args2, kwargs2 = self._prepare_args_for_execution(ts, args, kwargs)
  File "/vortexfs1/home/anthony.meza/mambaforge/envs/atm_rivers/lib/python3.10/site-packages/distributed/worker.py", line 2385, in _prepare_args_for_execution
    data[k] = Actor(type(self.state.actors[k]), self.address, k, self)
KeyError: 'open_dataset-a32832fa-f402-417b-b563-1dd748ba02f3'
2023-05-01 12:32:45,132 - distributed.worker - ERROR - Exception during execution of task getattr-d2056a38-9d08-4472-aced-128e136d14e7.
Traceback (most recent call last):
  File "/vortexfs1/home/anthony.meza/mambaforge/envs/atm_rivers/lib/python3.10/site-packages/zict/buffer.py", line 184, in __getitem__
    return self.fast[key]
  File "/vortexfs1/home/anthony.meza/mambaforge/envs/atm_rivers/lib/python3.10/site-packages/zict/common.py", line 127, in wrapper
    return func(*args, **kwargs)
  File "/vortexfs1/home/anthony.meza/mambaforge/envs/atm_rivers/lib/python3.10/site-packages/zict/lru.py", line 117, in __getitem__
    result = self.d[key]
KeyError: 'open_dataset-a32832fa-f402-417b-b563-1dd748ba02f3'

During handling of the above exception, another exception occurred:

Traceback (most recent call last):
  File "/vortexfs1/home/anthony.meza/mambaforge/envs/atm_rivers/lib/python3.10/site-packages/distributed/worker.py", line 2381, in _prepare_args_for_execution
    data[k] = self.data[k]
  File "/vortexfs1/home/anthony.meza/mambaforge/envs/atm_rivers/lib/python3.10/site-packages/distributed/spill.py", line 223, in __getitem__
    return super().__getitem__(key)
  File "/vortexfs1/home/anthony.meza/mambaforge/envs/atm_rivers/lib/python3.10/site-packages/zict/common.py", line 127, in wrapper
    return func(*args, **kwargs)
  File "/vortexfs1/home/anthony.meza/mambaforge/envs/atm_rivers/lib/python3.10/site-packages/zict/buffer.py", line 186, in __getitem__
    return self.slow_to_fast(key)
  File "/vortexfs1/home/anthony.meza/mambaforge/envs/atm_rivers/lib/python3.10/site-packages/zict/buffer.py", line 153, in slow_to_fast
    value = self.slow[key]
  File "/vortexfs1/home/anthony.meza/mambaforge/envs/atm_rivers/lib/python3.10/site-packages/zict/common.py", line 127, in wrapper
    return func(*args, **kwargs)
  File "/vortexfs1/home/anthony.meza/mambaforge/envs/atm_rivers/lib/python3.10/site-packages/zict/cache.py", line 67, in __getitem__
    gen = self._last_updated[key]
KeyError: 'open_dataset-a32832fa-f402-417b-b563-1dd748ba02f3'

During handling of the above exception, another exception occurred:

Traceback (most recent call last):
  File "/vortexfs1/home/anthony.meza/mambaforge/envs/atm_rivers/lib/python3.10/site-packages/distributed/worker.py", line 2249, in execute
    args2, kwargs2 = self._prepare_args_for_execution(ts, args, kwargs)
  File "/vortexfs1/home/anthony.meza/mambaforge/envs/atm_rivers/lib/python3.10/site-packages/distributed/worker.py", line 2385, in _prepare_args_for_execution
    data[k] = Actor(type(self.state.actors[k]), self.address, k, self)
KeyError: 'open_dataset-a32832fa-f402-417b-b563-1dd748ba02f3'
2023-05-01 12:40:10,537 - distributed.core - INFO - Connection to tcp://172.16.3.62:37872 has been closed.
2023-05-01 12:40:10,543 - distributed.worker - INFO - Stopping worker at tcp://172.16.3.97:45929. Reason: worker-handle-scheduler-connection-broken
2023-05-01 12:40:10,543 - distributed.worker - ERROR - Failed to communicate with scheduler during heartbeat.
Traceback (most recent call last):
  File "/vortexfs1/home/anthony.meza/mambaforge/envs/atm_rivers/lib/python3.10/site-packages/tornado/iostream.py", line 861, in _read_to_buffer
    bytes_read = self.read_from_fd(buf)
  File "/vortexfs1/home/anthony.meza/mambaforge/envs/atm_rivers/lib/python3.10/site-packages/tornado/iostream.py", line 1116, in read_from_fd
    return self.socket.recv_into(buf, len(buf))
ConnectionResetError: [Errno 104] Connection reset by peer

The above exception was the direct cause of the following exception:

Traceback (most recent call last):
  File "/vortexfs1/home/anthony.meza/mambaforge/envs/atm_rivers/lib/python3.10/site-packages/distributed/worker.py", line 1234, in heartbeat
    response = await retry_operation(
  File "/vortexfs1/home/anthony.meza/mambaforge/envs/atm_rivers/lib/python3.10/site-packages/distributed/utils_comm.py", line 434, in retry_operation
    return await retry(
  File "/vortexfs1/home/anthony.meza/mambaforge/envs/atm_rivers/lib/python3.10/site-packages/distributed/utils_comm.py", line 413, in retry
    return await coro()
  File "/vortexfs1/home/anthony.meza/mambaforge/envs/atm_rivers/lib/python3.10/site-packages/distributed/core.py", line 1268, in send_recv_from_rpc
    return await send_recv(comm=comm, op=key, **kwargs)
  File "/vortexfs1/home/anthony.meza/mambaforge/envs/atm_rivers/lib/python3.10/site-packages/distributed/core.py", line 1027, in send_recv
    response = await comm.read(deserializers=deserializers)
  File "/vortexfs1/home/anthony.meza/mambaforge/envs/atm_rivers/lib/python3.10/site-packages/distributed/comm/tcp.py", line 241, in read
    convert_stream_closed_error(self, e)
  File "/vortexfs1/home/anthony.meza/mambaforge/envs/atm_rivers/lib/python3.10/site-packages/distributed/comm/tcp.py", line 142, in convert_stream_closed_error
    raise CommClosedError(f"in {obj}: {exc.__class__.__name__}: {exc}") from exc
distributed.comm.core.CommClosedError: in <TCP (closed) ConnectionPool.heartbeat_worker local=tcp://172.16.3.97:36111 remote=tcp://172.16.3.62:37872>: ConnectionResetError: [Errno 104] Connection reset by peer
2023-05-01 12:40:10,548 - distributed.nanny - INFO - Closing Nanny gracefully at 'tcp://172.16.3.97:41868'. Reason: worker-handle-scheduler-connection-broken
2023-05-01 12:40:10,553 - distributed.nanny - INFO - Worker closed
2023-05-01 12:40:13,150 - distributed.nanny - INFO - Closing Nanny at 'tcp://172.16.3.97:41868'. Reason: nanny-close-gracefully
2023-05-01 12:40:13,151 - distributed.dask_worker - INFO - End worker
