2023-04-18 12:30:53,228 - distributed.nanny - INFO -         Start Nanny at: 'tcp://172.16.3.94:38641'
2023-04-18 12:31:00,946 - distributed.worker - INFO -       Start worker at:    tcp://172.16.3.94:43142
2023-04-18 12:31:00,946 - distributed.worker - INFO -          Listening to:    tcp://172.16.3.94:43142
2023-04-18 12:31:00,946 - distributed.worker - INFO -           Worker name:             SLURMCluster-3
2023-04-18 12:31:00,946 - distributed.worker - INFO -          dashboard at:          172.16.3.94:42794
2023-04-18 12:31:00,946 - distributed.worker - INFO - Waiting to connect to:    tcp://172.16.3.91:36163
2023-04-18 12:31:00,947 - distributed.worker - INFO - -------------------------------------------------
2023-04-18 12:31:00,947 - distributed.worker - INFO -               Threads:                         36
2023-04-18 12:31:00,947 - distributed.worker - INFO -                Memory:                 178.81 GiB
2023-04-18 12:31:00,947 - distributed.worker - INFO -       Local Directory: /tmp/dask-worker-space/worker-troc5ozy
2023-04-18 12:31:00,947 - distributed.worker - INFO - -------------------------------------------------
2023-04-18 12:31:00,955 - distributed.worker - INFO -         Registered to:    tcp://172.16.3.91:36163
2023-04-18 12:31:00,955 - distributed.worker - INFO - -------------------------------------------------
2023-04-18 12:31:00,956 - distributed.core - INFO - Starting established connection to tcp://172.16.3.91:36163
2023-04-18 13:03:14,010 - distributed.core - INFO - Connection to tcp://172.16.3.91:36163 has been closed.
2023-04-18 13:03:14,011 - distributed.worker - INFO - Stopping worker at tcp://172.16.3.94:43142. Reason: worker-handle-scheduler-connection-broken
2023-04-18 13:03:14,012 - distributed.worker - ERROR - Failed to communicate with scheduler during heartbeat.
Traceback (most recent call last):
  File "/vortexfs1/home/anthony.meza/.conda/envs/notebook_env/lib/python3.10/site-packages/tornado/iostream.py", line 867, in _read_to_buffer
    bytes_read = self.read_from_fd(buf)
  File "/vortexfs1/home/anthony.meza/.conda/envs/notebook_env/lib/python3.10/site-packages/tornado/iostream.py", line 1140, in read_from_fd
    return self.socket.recv_into(buf, len(buf))
ConnectionResetError: [Errno 104] Connection reset by peer

The above exception was the direct cause of the following exception:

Traceback (most recent call last):
  File "/vortexfs1/home/anthony.meza/.conda/envs/notebook_env/lib/python3.10/site-packages/distributed/worker.py", line 1215, in heartbeat
    response = await retry_operation(
  File "/vortexfs1/home/anthony.meza/.conda/envs/notebook_env/lib/python3.10/site-packages/distributed/utils_comm.py", line 386, in retry_operation
    return await retry(
  File "/vortexfs1/home/anthony.meza/.conda/envs/notebook_env/lib/python3.10/site-packages/distributed/utils_comm.py", line 371, in retry
    return await coro()
  File "/vortexfs1/home/anthony.meza/.conda/envs/notebook_env/lib/python3.10/site-packages/distributed/core.py", line 1163, in send_recv_from_rpc
    return await send_recv(comm=comm, op=key, **kwargs)
  File "/vortexfs1/home/anthony.meza/.conda/envs/notebook_env/lib/python3.10/site-packages/distributed/core.py", line 928, in send_recv
    response = await comm.read(deserializers=deserializers)
  File "/vortexfs1/home/anthony.meza/.conda/envs/notebook_env/lib/python3.10/site-packages/distributed/comm/tcp.py", line 241, in read
    convert_stream_closed_error(self, e)
  File "/vortexfs1/home/anthony.meza/.conda/envs/notebook_env/lib/python3.10/site-packages/distributed/comm/tcp.py", line 142, in convert_stream_closed_error
    raise CommClosedError(f"in {obj}: {exc.__class__.__name__}: {exc}") from exc
distributed.comm.core.CommClosedError: in <TCP (closed) ConnectionPool.heartbeat_worker local=tcp://172.16.3.94:46553 remote=tcp://172.16.3.91:36163>: ConnectionResetError: [Errno 104] Connection reset by peer
2023-04-18 13:03:14,017 - distributed.nanny - INFO - Closing Nanny gracefully at 'tcp://172.16.3.94:38641'. Reason: worker-handle-scheduler-connection-broken
2023-04-18 13:03:16,166 - distributed.client - ERROR - 
ConnectionRefusedError: [Errno 111] Connection refused

The above exception was the direct cause of the following exception:

Traceback (most recent call last):
  File "/vortexfs1/home/anthony.meza/.conda/envs/notebook_env/lib/python3.10/site-packages/distributed/comm/core.py", line 291, in connect
    comm = await asyncio.wait_for(
  File "/vortexfs1/home/anthony.meza/.conda/envs/notebook_env/lib/python3.10/asyncio/tasks.py", line 445, in wait_for
    return fut.result()
  File "/vortexfs1/home/anthony.meza/.conda/envs/notebook_env/lib/python3.10/site-packages/distributed/comm/tcp.py", line 511, in connect
    convert_stream_closed_error(self, e)
  File "/vortexfs1/home/anthony.meza/.conda/envs/notebook_env/lib/python3.10/site-packages/distributed/comm/tcp.py", line 142, in convert_stream_closed_error
    raise CommClosedError(f"in {obj}: {exc.__class__.__name__}: {exc}") from exc
distributed.comm.core.CommClosedError: in <distributed.comm.tcp.TCPConnector object at 0x2aaacebf3a00>: ConnectionRefusedError: [Errno 111] Connection refused

During handling of the above exception, another exception occurred:

Traceback (most recent call last):
  File "/vortexfs1/home/anthony.meza/.conda/envs/notebook_env/lib/python3.10/site-packages/distributed/utils.py", line 742, in wrapper
    return await func(*args, **kwargs)
  File "/vortexfs1/home/anthony.meza/.conda/envs/notebook_env/lib/python3.10/site-packages/distributed/client.py", line 1298, in _reconnect
    await self._ensure_connected(timeout=timeout)
  File "/vortexfs1/home/anthony.meza/.conda/envs/notebook_env/lib/python3.10/site-packages/distributed/client.py", line 1328, in _ensure_connected
    comm = await connect(
  File "/vortexfs1/home/anthony.meza/.conda/envs/notebook_env/lib/python3.10/site-packages/distributed/comm/core.py", line 315, in connect
    await asyncio.sleep(backoff)
  File "/vortexfs1/home/anthony.meza/.conda/envs/notebook_env/lib/python3.10/asyncio/tasks.py", line 605, in sleep
    return await future
asyncio.exceptions.CancelledError

Traceback (most recent call last):
  File "/vortexfs1/home/anthony.meza/.conda/envs/notebook_env/lib/python3.10/site-packages/tornado/iostream.py", line 867, in _read_to_buffer
    bytes_read = self.read_from_fd(buf)
  File "/vortexfs1/home/anthony.meza/.conda/envs/notebook_env/lib/python3.10/site-packages/tornado/iostream.py", line 1140, in read_from_fd
    return self.socket.recv_into(buf, len(buf))
ConnectionResetError: [Errno 104] Connection reset by peer

The above exception was the direct cause of the following exception:

Traceback (most recent call last):
  File "/vortexfs1/home/anthony.meza/.conda/envs/notebook_env/lib/python3.10/site-packages/distributed/client.py", line 1500, in _handle_report
    msgs = await self.scheduler_comm.comm.read()
  File "/vortexfs1/home/anthony.meza/.conda/envs/notebook_env/lib/python3.10/site-packages/distributed/comm/tcp.py", line 241, in read
    convert_stream_closed_error(self, e)
  File "/vortexfs1/home/anthony.meza/.conda/envs/notebook_env/lib/python3.10/site-packages/distributed/comm/tcp.py", line 142, in convert_stream_closed_error
    raise CommClosedError(f"in {obj}: {exc.__class__.__name__}: {exc}") from exc
distributed.comm.core.CommClosedError: in <TCP (closed) Client->Scheduler local=tcp://172.16.3.94:46551 remote=tcp://172.16.3.91:36163>: ConnectionResetError: [Errno 104] Connection reset by peer

During handling of the above exception, another exception occurred:

Traceback (most recent call last):
  File "/vortexfs1/home/anthony.meza/.conda/envs/notebook_env/lib/python3.10/site-packages/distributed/utils.py", line 742, in wrapper
    return await func(*args, **kwargs)
  File "/vortexfs1/home/anthony.meza/.conda/envs/notebook_env/lib/python3.10/site-packages/distributed/client.py", line 1508, in _handle_report
    await self._reconnect()
  File "/vortexfs1/home/anthony.meza/.conda/envs/notebook_env/lib/python3.10/site-packages/distributed/utils.py", line 742, in wrapper
    return await func(*args, **kwargs)
  File "/vortexfs1/home/anthony.meza/.conda/envs/notebook_env/lib/python3.10/site-packages/distributed/client.py", line 1298, in _reconnect
    await self._ensure_connected(timeout=timeout)
  File "/vortexfs1/home/anthony.meza/.conda/envs/notebook_env/lib/python3.10/site-packages/distributed/client.py", line 1328, in _ensure_connected
    comm = await connect(
  File "/vortexfs1/home/anthony.meza/.conda/envs/notebook_env/lib/python3.10/site-packages/distributed/comm/core.py", line 315, in connect
    await asyncio.sleep(backoff)
  File "/vortexfs1/home/anthony.meza/.conda/envs/notebook_env/lib/python3.10/asyncio/tasks.py", line 605, in sleep
    return await future
asyncio.exceptions.CancelledError
2023-04-18 13:03:46,274 - distributed.nanny - INFO - Worker closed
2023-04-18 13:03:48,276 - distributed.nanny - ERROR - Worker process died unexpectedly
2023-04-18 13:07:14,364 - distributed.nanny - INFO - Closing Nanny at 'tcp://172.16.3.94:38641'. Reason: nanny-close-gracefully
2023-04-18 13:07:14,365 - distributed.dask_worker - INFO - End worker
