2023-04-18 10:10:18,166 - distributed.nanny - INFO -         Start Nanny at: 'tcp://172.16.3.65:39609'
2023-04-18 10:10:23,262 - distributed.worker - INFO -       Start worker at:    tcp://172.16.3.65:43058
2023-04-18 10:10:23,262 - distributed.worker - INFO -          Listening to:    tcp://172.16.3.65:43058
2023-04-18 10:10:23,262 - distributed.worker - INFO -           Worker name:             SLURMCluster-1
2023-04-18 10:10:23,262 - distributed.worker - INFO -          dashboard at:          172.16.3.65:43920
2023-04-18 10:10:23,262 - distributed.worker - INFO - Waiting to connect to:    tcp://172.16.3.91:46039
2023-04-18 10:10:23,262 - distributed.worker - INFO - -------------------------------------------------
2023-04-18 10:10:23,263 - distributed.worker - INFO -               Threads:                         36
2023-04-18 10:10:23,263 - distributed.worker - INFO -                Memory:                 178.81 GiB
2023-04-18 10:10:23,263 - distributed.worker - INFO -       Local Directory: /tmp/dask-worker-space/worker-mjpbbr9g
2023-04-18 10:10:23,263 - distributed.worker - INFO - -------------------------------------------------
2023-04-18 10:10:23,269 - distributed.worker - INFO -         Registered to:    tcp://172.16.3.91:46039
2023-04-18 10:10:23,269 - distributed.worker - INFO - -------------------------------------------------
2023-04-18 10:10:23,270 - distributed.core - INFO - Starting established connection to tcp://172.16.3.91:46039
2023-04-18 10:14:54,497 - distributed.core - INFO - Connection to tcp://172.16.3.91:46039 has been closed.
2023-04-18 10:14:54,498 - distributed.worker - INFO - Stopping worker at tcp://172.16.3.65:43058. Reason: worker-handle-scheduler-connection-broken
2023-04-18 10:14:54,503 - distributed.nanny - INFO - Closing Nanny gracefully at 'tcp://172.16.3.65:39609'. Reason: worker-handle-scheduler-connection-broken
2023-04-18 10:14:56,653 - distributed.client - ERROR - 
ConnectionRefusedError: [Errno 111] Connection refused

The above exception was the direct cause of the following exception:

Traceback (most recent call last):
  File "/vortexfs1/home/anthony.meza/.conda/envs/notebook_env/lib/python3.10/site-packages/distributed/comm/core.py", line 291, in connect
    comm = await asyncio.wait_for(
  File "/vortexfs1/home/anthony.meza/.conda/envs/notebook_env/lib/python3.10/asyncio/tasks.py", line 445, in wait_for
    return fut.result()
  File "/vortexfs1/home/anthony.meza/.conda/envs/notebook_env/lib/python3.10/site-packages/distributed/comm/tcp.py", line 511, in connect
    convert_stream_closed_error(self, e)
  File "/vortexfs1/home/anthony.meza/.conda/envs/notebook_env/lib/python3.10/site-packages/distributed/comm/tcp.py", line 142, in convert_stream_closed_error
    raise CommClosedError(f"in {obj}: {exc.__class__.__name__}: {exc}") from exc
distributed.comm.core.CommClosedError: in <distributed.comm.tcp.TCPConnector object at 0x2aaac78f6770>: ConnectionRefusedError: [Errno 111] Connection refused

During handling of the above exception, another exception occurred:

Traceback (most recent call last):
  File "/vortexfs1/home/anthony.meza/.conda/envs/notebook_env/lib/python3.10/site-packages/distributed/utils.py", line 742, in wrapper
    return await func(*args, **kwargs)
  File "/vortexfs1/home/anthony.meza/.conda/envs/notebook_env/lib/python3.10/site-packages/distributed/client.py", line 1298, in _reconnect
    await self._ensure_connected(timeout=timeout)
  File "/vortexfs1/home/anthony.meza/.conda/envs/notebook_env/lib/python3.10/site-packages/distributed/client.py", line 1328, in _ensure_connected
    comm = await connect(
  File "/vortexfs1/home/anthony.meza/.conda/envs/notebook_env/lib/python3.10/site-packages/distributed/comm/core.py", line 315, in connect
    await asyncio.sleep(backoff)
  File "/vortexfs1/home/anthony.meza/.conda/envs/notebook_env/lib/python3.10/asyncio/tasks.py", line 605, in sleep
    return await future
asyncio.exceptions.CancelledError

Traceback (most recent call last):
  File "/vortexfs1/home/anthony.meza/.conda/envs/notebook_env/lib/python3.10/site-packages/distributed/comm/tcp.py", line 225, in read
    frames_nbytes = await stream.read_bytes(fmt_size)
tornado.iostream.StreamClosedError: Stream is closed

The above exception was the direct cause of the following exception:

Traceback (most recent call last):
  File "/vortexfs1/home/anthony.meza/.conda/envs/notebook_env/lib/python3.10/site-packages/distributed/client.py", line 1500, in _handle_report
    msgs = await self.scheduler_comm.comm.read()
  File "/vortexfs1/home/anthony.meza/.conda/envs/notebook_env/lib/python3.10/site-packages/distributed/comm/tcp.py", line 241, in read
    convert_stream_closed_error(self, e)
  File "/vortexfs1/home/anthony.meza/.conda/envs/notebook_env/lib/python3.10/site-packages/distributed/comm/tcp.py", line 144, in convert_stream_closed_error
    raise CommClosedError(f"in {obj}: {exc}") from exc
distributed.comm.core.CommClosedError: in <TCP (closed) Client->Scheduler local=tcp://172.16.3.65:43268 remote=tcp://172.16.3.91:46039>: Stream is closed

During handling of the above exception, another exception occurred:

Traceback (most recent call last):
  File "/vortexfs1/home/anthony.meza/.conda/envs/notebook_env/lib/python3.10/site-packages/distributed/utils.py", line 742, in wrapper
    return await func(*args, **kwargs)
  File "/vortexfs1/home/anthony.meza/.conda/envs/notebook_env/lib/python3.10/site-packages/distributed/client.py", line 1508, in _handle_report
    await self._reconnect()
  File "/vortexfs1/home/anthony.meza/.conda/envs/notebook_env/lib/python3.10/site-packages/distributed/utils.py", line 742, in wrapper
    return await func(*args, **kwargs)
  File "/vortexfs1/home/anthony.meza/.conda/envs/notebook_env/lib/python3.10/site-packages/distributed/client.py", line 1298, in _reconnect
    await self._ensure_connected(timeout=timeout)
  File "/vortexfs1/home/anthony.meza/.conda/envs/notebook_env/lib/python3.10/site-packages/distributed/client.py", line 1328, in _ensure_connected
    comm = await connect(
  File "/vortexfs1/home/anthony.meza/.conda/envs/notebook_env/lib/python3.10/site-packages/distributed/comm/core.py", line 315, in connect
    await asyncio.sleep(backoff)
  File "/vortexfs1/home/anthony.meza/.conda/envs/notebook_env/lib/python3.10/asyncio/tasks.py", line 605, in sleep
    return await future
asyncio.exceptions.CancelledError
2023-04-18 10:15:26,660 - distributed.nanny - INFO - Worker closed
2023-04-18 10:15:28,662 - distributed.nanny - ERROR - Worker process died unexpectedly
2023-04-18 10:15:29,040 - distributed.nanny - INFO - Closing Nanny at 'tcp://172.16.3.65:39609'. Reason: nanny-close-gracefully
2023-04-18 10:15:29,041 - distributed.dask_worker - INFO - End worker
