2023-04-17 20:57:11,541 - distributed.nanny - INFO -         Start Nanny at: 'tcp://172.16.3.95:37960'
2023-04-17 20:57:12,754 - distributed.diskutils - INFO - Found stale lock file and directory '/tmp/dask-worker-space/worker-2n0qlr62', purging
2023-04-17 20:57:29,658 - distributed.worker - INFO -       Start worker at:    tcp://172.16.3.95:43579
2023-04-17 20:57:29,658 - distributed.worker - INFO -          Listening to:    tcp://172.16.3.95:43579
2023-04-17 20:57:29,658 - distributed.worker - INFO -           Worker name:             SLURMCluster-3
2023-04-17 20:57:29,658 - distributed.worker - INFO -          dashboard at:          172.16.3.95:39098
2023-04-17 20:57:29,658 - distributed.worker - INFO - Waiting to connect to:    tcp://172.16.3.64:44111
2023-04-17 20:57:29,658 - distributed.worker - INFO - -------------------------------------------------
2023-04-17 20:57:29,658 - distributed.worker - INFO -               Threads:                         36
2023-04-17 20:57:29,659 - distributed.worker - INFO -                Memory:                 178.81 GiB
2023-04-17 20:57:29,659 - distributed.worker - INFO -       Local Directory: /tmp/dask-worker-space/worker-payzgnal
2023-04-17 20:57:29,659 - distributed.worker - INFO - -------------------------------------------------
2023-04-17 20:57:29,676 - distributed.worker - INFO -         Registered to:    tcp://172.16.3.64:44111
2023-04-17 20:57:29,676 - distributed.worker - INFO - -------------------------------------------------
2023-04-17 20:57:29,676 - distributed.core - INFO - Starting established connection to tcp://172.16.3.64:44111
2023-04-17 20:58:44,819 - distributed.core - INFO - Event loop was unresponsive in Worker for 7.28s.  This is often caused by long-running GIL-holding functions or moving large chunks of data. This can cause timeouts and instability.
2023-04-17 21:00:54,156 - distributed.core - INFO - Event loop was unresponsive in Worker for 3.88s.  This is often caused by long-running GIL-holding functions or moving large chunks of data. This can cause timeouts and instability.
2023-04-17 21:01:00,543 - distributed.core - INFO - Event loop was unresponsive in Worker for 4.63s.  This is often caused by long-running GIL-holding functions or moving large chunks of data. This can cause timeouts and instability.
2023-04-17 21:01:04,117 - distributed.core - INFO - Event loop was unresponsive in Worker for 3.57s.  This is often caused by long-running GIL-holding functions or moving large chunks of data. This can cause timeouts and instability.
2023-04-17 21:01:35,206 - distributed.core - INFO - Event loop was unresponsive in Worker for 31.09s.  This is often caused by long-running GIL-holding functions or moving large chunks of data. This can cause timeouts and instability.
2023-04-17 21:01:50,590 - distributed.worker - ERROR - Failed to communicate with scheduler during heartbeat.
Traceback (most recent call last):
  File "/vortexfs1/home/anthony.meza/.conda/envs/notebook_env/lib/python3.10/site-packages/distributed/comm/tcp.py", line 317, in write
    raise StreamClosedError()
tornado.iostream.StreamClosedError: Stream is closed

The above exception was the direct cause of the following exception:

Traceback (most recent call last):
  File "/vortexfs1/home/anthony.meza/.conda/envs/notebook_env/lib/python3.10/site-packages/distributed/worker.py", line 1215, in heartbeat
    response = await retry_operation(
  File "/vortexfs1/home/anthony.meza/.conda/envs/notebook_env/lib/python3.10/site-packages/distributed/utils_comm.py", line 386, in retry_operation
    return await retry(
  File "/vortexfs1/home/anthony.meza/.conda/envs/notebook_env/lib/python3.10/site-packages/distributed/utils_comm.py", line 371, in retry
    return await coro()
  File "/vortexfs1/home/anthony.meza/.conda/envs/notebook_env/lib/python3.10/site-packages/distributed/core.py", line 1163, in send_recv_from_rpc
    return await send_recv(comm=comm, op=key, **kwargs)
  File "/vortexfs1/home/anthony.meza/.conda/envs/notebook_env/lib/python3.10/site-packages/distributed/core.py", line 926, in send_recv
    await comm.write(msg, serializers=serializers, on_error="raise")
  File "/vortexfs1/home/anthony.meza/.conda/envs/notebook_env/lib/python3.10/site-packages/distributed/comm/tcp.py", line 328, in write
    convert_stream_closed_error(self, e)
  File "/vortexfs1/home/anthony.meza/.conda/envs/notebook_env/lib/python3.10/site-packages/distributed/comm/tcp.py", line 144, in convert_stream_closed_error
    raise CommClosedError(f"in {obj}: {exc}") from exc
distributed.comm.core.CommClosedError: in <TCP (closed) ConnectionPool.heartbeat_worker local=tcp://172.16.3.95:50536 remote=tcp://172.16.3.64:44111>: Stream is closed
2023-04-17 21:01:50,620 - distributed.core - INFO - Event loop was unresponsive in Worker for 15.41s.  This is often caused by long-running GIL-holding functions or moving large chunks of data. This can cause timeouts and instability.
2023-04-17 21:01:55,403 - distributed.core - INFO - Event loop was unresponsive in Worker for 4.78s.  This is often caused by long-running GIL-holding functions or moving large chunks of data. This can cause timeouts and instability.
2023-04-17 21:01:58,415 - distributed.core - INFO - Event loop was unresponsive in Worker for 3.01s.  This is often caused by long-running GIL-holding functions or moving large chunks of data. This can cause timeouts and instability.
2023-04-17 21:02:05,972 - distributed.core - INFO - Event loop was unresponsive in Worker for 3.27s.  This is often caused by long-running GIL-holding functions or moving large chunks of data. This can cause timeouts and instability.
2023-04-17 21:02:22,733 - distributed.core - INFO - Event loop was unresponsive in Worker for 16.76s.  This is often caused by long-running GIL-holding functions or moving large chunks of data. This can cause timeouts and instability.
2023-04-17 21:02:28,447 - distributed.core - INFO - Event loop was unresponsive in Worker for 3.72s.  This is often caused by long-running GIL-holding functions or moving large chunks of data. This can cause timeouts and instability.
2023-04-17 21:02:49,472 - distributed.core - INFO - Event loop was unresponsive in Worker for 21.03s.  This is often caused by long-running GIL-holding functions or moving large chunks of data. This can cause timeouts and instability.
2023-04-17 21:02:52,955 - distributed.core - INFO - Event loop was unresponsive in Worker for 3.48s.  This is often caused by long-running GIL-holding functions or moving large chunks of data. This can cause timeouts and instability.
2023-04-17 21:02:59,430 - distributed.core - INFO - Event loop was unresponsive in Worker for 4.31s.  This is often caused by long-running GIL-holding functions or moving large chunks of data. This can cause timeouts and instability.
2023-04-17 21:03:04,003 - distributed.core - INFO - Event loop was unresponsive in Worker for 4.33s.  This is often caused by long-running GIL-holding functions or moving large chunks of data. This can cause timeouts and instability.
2023-04-17 21:03:11,302 - distributed.core - INFO - Event loop was unresponsive in Worker for 4.17s.  This is often caused by long-running GIL-holding functions or moving large chunks of data. This can cause timeouts and instability.
2023-04-17 21:03:15,553 - distributed.core - INFO - Event loop was unresponsive in Worker for 3.88s.  This is often caused by long-running GIL-holding functions or moving large chunks of data. This can cause timeouts and instability.
2023-04-17 21:03:22,485 - distributed.core - INFO - Event loop was unresponsive in Worker for 5.17s.  This is often caused by long-running GIL-holding functions or moving large chunks of data. This can cause timeouts and instability.
2023-04-17 21:03:35,317 - distributed.core - INFO - Event loop was unresponsive in Worker for 3.44s.  This is often caused by long-running GIL-holding functions or moving large chunks of data. This can cause timeouts and instability.
2023-04-17 21:03:40,877 - distributed.core - INFO - Event loop was unresponsive in Worker for 3.66s.  This is often caused by long-running GIL-holding functions or moving large chunks of data. This can cause timeouts and instability.
2023-04-17 21:03:49,326 - distributed.core - INFO - Event loop was unresponsive in Worker for 6.29s.  This is often caused by long-running GIL-holding functions or moving large chunks of data. This can cause timeouts and instability.
2023-04-17 21:04:08,743 - distributed.core - INFO - Event loop was unresponsive in Worker for 3.03s.  This is often caused by long-running GIL-holding functions or moving large chunks of data. This can cause timeouts and instability.
2023-04-17 21:04:16,442 - distributed.core - INFO - Event loop was unresponsive in Worker for 4.30s.  This is often caused by long-running GIL-holding functions or moving large chunks of data. This can cause timeouts and instability.
2023-04-17 21:04:21,059 - distributed.core - INFO - Event loop was unresponsive in Worker for 4.26s.  This is often caused by long-running GIL-holding functions or moving large chunks of data. This can cause timeouts and instability.
2023-04-17 21:04:28,249 - distributed.core - INFO - Event loop was unresponsive in Worker for 3.73s.  This is often caused by long-running GIL-holding functions or moving large chunks of data. This can cause timeouts and instability.
2023-04-17 21:04:36,379 - distributed.core - INFO - Event loop was unresponsive in Worker for 3.83s.  This is often caused by long-running GIL-holding functions or moving large chunks of data. This can cause timeouts and instability.
2023-04-17 21:04:47,220 - distributed.core - INFO - Event loop was unresponsive in Worker for 6.44s.  This is often caused by long-running GIL-holding functions or moving large chunks of data. This can cause timeouts and instability.
2023-04-17 21:04:56,997 - distributed.core - INFO - Event loop was unresponsive in Worker for 9.78s.  This is often caused by long-running GIL-holding functions or moving large chunks of data. This can cause timeouts and instability.
2023-04-17 21:05:03,847 - distributed.core - INFO - Event loop was unresponsive in Worker for 6.85s.  This is often caused by long-running GIL-holding functions or moving large chunks of data. This can cause timeouts and instability.
2023-04-17 21:05:13,366 - distributed.core - INFO - Event loop was unresponsive in Worker for 9.52s.  This is often caused by long-running GIL-holding functions or moving large chunks of data. This can cause timeouts and instability.
2023-04-17 21:05:22,297 - distributed.core - INFO - Event loop was unresponsive in Worker for 3.84s.  This is often caused by long-running GIL-holding functions or moving large chunks of data. This can cause timeouts and instability.
2023-04-17 21:05:26,464 - distributed.core - INFO - Event loop was unresponsive in Worker for 3.87s.  This is often caused by long-running GIL-holding functions or moving large chunks of data. This can cause timeouts and instability.
2023-04-17 21:05:32,379 - distributed.core - INFO - Event loop was unresponsive in Worker for 4.12s.  This is often caused by long-running GIL-holding functions or moving large chunks of data. This can cause timeouts and instability.
2023-04-17 21:05:38,254 - distributed.core - INFO - Event loop was unresponsive in Worker for 4.14s.  This is often caused by long-running GIL-holding functions or moving large chunks of data. This can cause timeouts and instability.
2023-04-17 21:30:45,210 - distributed.core - INFO - Connection to tcp://172.16.3.64:44111 has been closed.
2023-04-17 21:30:45,210 - distributed.worker - INFO - Stopping worker at tcp://172.16.3.95:43579. Reason: worker-handle-scheduler-connection-broken
2023-04-17 21:30:45,211 - distributed.batched - INFO - Batched Comm Closed <TCP (closed) Worker->Scheduler local=tcp://172.16.3.95:50426 remote=tcp://172.16.3.64:44111>
Traceback (most recent call last):
  File "/vortexfs1/home/anthony.meza/.conda/envs/notebook_env/lib/python3.10/site-packages/distributed/comm/tcp.py", line 317, in write
    raise StreamClosedError()
tornado.iostream.StreamClosedError: Stream is closed

The above exception was the direct cause of the following exception:

Traceback (most recent call last):
  File "/vortexfs1/home/anthony.meza/.conda/envs/notebook_env/lib/python3.10/site-packages/distributed/batched.py", line 115, in _background_send
    nbytes = yield coro
  File "/vortexfs1/home/anthony.meza/.conda/envs/notebook_env/lib/python3.10/site-packages/tornado/gen.py", line 762, in run
    value = future.result()
  File "/vortexfs1/home/anthony.meza/.conda/envs/notebook_env/lib/python3.10/site-packages/distributed/comm/tcp.py", line 328, in write
    convert_stream_closed_error(self, e)
  File "/vortexfs1/home/anthony.meza/.conda/envs/notebook_env/lib/python3.10/site-packages/distributed/comm/tcp.py", line 144, in convert_stream_closed_error
    raise CommClosedError(f"in {obj}: {exc}") from exc
distributed.comm.core.CommClosedError: in <TCP (closed) Worker->Scheduler local=tcp://172.16.3.95:50426 remote=tcp://172.16.3.64:44111>: Stream is closed
2023-04-17 21:30:45,604 - distributed.nanny - INFO - Closing Nanny gracefully at 'tcp://172.16.3.95:37960'. Reason: worker-handle-scheduler-connection-broken
2023-04-17 21:30:47,730 - distributed.client - ERROR - 
ConnectionRefusedError: [Errno 111] Connection refused

The above exception was the direct cause of the following exception:

Traceback (most recent call last):
  File "/vortexfs1/home/anthony.meza/.conda/envs/notebook_env/lib/python3.10/site-packages/distributed/comm/core.py", line 291, in connect
    comm = await asyncio.wait_for(
  File "/vortexfs1/home/anthony.meza/.conda/envs/notebook_env/lib/python3.10/asyncio/tasks.py", line 445, in wait_for
    return fut.result()
  File "/vortexfs1/home/anthony.meza/.conda/envs/notebook_env/lib/python3.10/site-packages/distributed/comm/tcp.py", line 511, in connect
    convert_stream_closed_error(self, e)
  File "/vortexfs1/home/anthony.meza/.conda/envs/notebook_env/lib/python3.10/site-packages/distributed/comm/tcp.py", line 142, in convert_stream_closed_error
    raise CommClosedError(f"in {obj}: {exc.__class__.__name__}: {exc}") from exc
distributed.comm.core.CommClosedError: in <distributed.comm.tcp.TCPConnector object at 0x2aab60f78fa0>: ConnectionRefusedError: [Errno 111] Connection refused

During handling of the above exception, another exception occurred:

Traceback (most recent call last):
  File "/vortexfs1/home/anthony.meza/.conda/envs/notebook_env/lib/python3.10/site-packages/distributed/utils.py", line 742, in wrapper
    return await func(*args, **kwargs)
  File "/vortexfs1/home/anthony.meza/.conda/envs/notebook_env/lib/python3.10/site-packages/distributed/client.py", line 1298, in _reconnect
    await self._ensure_connected(timeout=timeout)
  File "/vortexfs1/home/anthony.meza/.conda/envs/notebook_env/lib/python3.10/site-packages/distributed/client.py", line 1328, in _ensure_connected
    comm = await connect(
  File "/vortexfs1/home/anthony.meza/.conda/envs/notebook_env/lib/python3.10/site-packages/distributed/comm/core.py", line 315, in connect
    await asyncio.sleep(backoff)
  File "/vortexfs1/home/anthony.meza/.conda/envs/notebook_env/lib/python3.10/asyncio/tasks.py", line 605, in sleep
    return await future
asyncio.exceptions.CancelledError

Traceback (most recent call last):
  File "/vortexfs1/home/anthony.meza/.conda/envs/notebook_env/lib/python3.10/site-packages/distributed/comm/tcp.py", line 225, in read
    frames_nbytes = await stream.read_bytes(fmt_size)
tornado.iostream.StreamClosedError: Stream is closed

The above exception was the direct cause of the following exception:

Traceback (most recent call last):
  File "/vortexfs1/home/anthony.meza/.conda/envs/notebook_env/lib/python3.10/site-packages/distributed/client.py", line 1500, in _handle_report
    msgs = await self.scheduler_comm.comm.read()
  File "/vortexfs1/home/anthony.meza/.conda/envs/notebook_env/lib/python3.10/site-packages/distributed/comm/tcp.py", line 241, in read
    convert_stream_closed_error(self, e)
  File "/vortexfs1/home/anthony.meza/.conda/envs/notebook_env/lib/python3.10/site-packages/distributed/comm/tcp.py", line 144, in convert_stream_closed_error
    raise CommClosedError(f"in {obj}: {exc}") from exc
distributed.comm.core.CommClosedError: in <TCP (closed) Client->Scheduler local=tcp://172.16.3.95:50452 remote=tcp://172.16.3.64:44111>: Stream is closed

During handling of the above exception, another exception occurred:

Traceback (most recent call last):
  File "/vortexfs1/home/anthony.meza/.conda/envs/notebook_env/lib/python3.10/site-packages/distributed/utils.py", line 742, in wrapper
    return await func(*args, **kwargs)
  File "/vortexfs1/home/anthony.meza/.conda/envs/notebook_env/lib/python3.10/site-packages/distributed/client.py", line 1508, in _handle_report
    await self._reconnect()
  File "/vortexfs1/home/anthony.meza/.conda/envs/notebook_env/lib/python3.10/site-packages/distributed/utils.py", line 742, in wrapper
    return await func(*args, **kwargs)
  File "/vortexfs1/home/anthony.meza/.conda/envs/notebook_env/lib/python3.10/site-packages/distributed/client.py", line 1298, in _reconnect
    await self._ensure_connected(timeout=timeout)
  File "/vortexfs1/home/anthony.meza/.conda/envs/notebook_env/lib/python3.10/site-packages/distributed/client.py", line 1328, in _ensure_connected
    comm = await connect(
  File "/vortexfs1/home/anthony.meza/.conda/envs/notebook_env/lib/python3.10/site-packages/distributed/comm/core.py", line 315, in connect
    await asyncio.sleep(backoff)
  File "/vortexfs1/home/anthony.meza/.conda/envs/notebook_env/lib/python3.10/asyncio/tasks.py", line 605, in sleep
    return await future
asyncio.exceptions.CancelledError
2023-04-17 21:30:48,482 - distributed.nanny - INFO - Worker closed
2023-04-17 21:30:58,762 - distributed.nanny - INFO - Closing Nanny at 'tcp://172.16.3.95:37960'. Reason: nanny-close-gracefully
2023-04-17 21:30:58,763 - distributed.dask_worker - INFO - End worker
