2023-04-18 15:54:33,705 - distributed.nanny - INFO -         Start Nanny at: 'tcp://172.16.3.138:41731'
2023-04-18 15:54:34,132 - distributed.diskutils - INFO - Found stale lock file and directory '/tmp/dask-worker-space/worker-fvwrvusm', purging
2023-04-18 15:54:36,288 - distributed.worker - INFO -       Start worker at:   tcp://172.16.3.138:45645
2023-04-18 15:54:36,289 - distributed.worker - INFO -          Listening to:   tcp://172.16.3.138:45645
2023-04-18 15:54:36,289 - distributed.worker - INFO -           Worker name:             SLURMCluster-5
2023-04-18 15:54:36,289 - distributed.worker - INFO -          dashboard at:         172.16.3.138:36320
2023-04-18 15:54:36,289 - distributed.worker - INFO - Waiting to connect to:    tcp://172.16.3.91:34882
2023-04-18 15:54:36,289 - distributed.worker - INFO - -------------------------------------------------
2023-04-18 15:54:36,289 - distributed.worker - INFO -               Threads:                         32
2023-04-18 15:54:36,289 - distributed.worker - INFO -                Memory:                  46.57 GiB
2023-04-18 15:54:36,289 - distributed.worker - INFO -       Local Directory: /tmp/dask-worker-space/worker-ahv2a3ty
2023-04-18 15:54:36,289 - distributed.worker - INFO - -------------------------------------------------
2023-04-18 15:54:36,295 - distributed.worker - INFO -         Registered to:    tcp://172.16.3.91:34882
2023-04-18 15:54:36,295 - distributed.worker - INFO - -------------------------------------------------
2023-04-18 15:54:36,296 - distributed.core - INFO - Starting established connection to tcp://172.16.3.91:34882
/vortexfs1/home/anthony.meza/.conda/envs/notebook_env/lib/python3.10/site-packages/xarray/core/common.py:965: FutureWarning: 'base' in .resample() and in Grouper() is deprecated.
The new arguments that you should use are 'offset' or 'origin'.

>>> df.resample(freq="3s", base=2)

becomes:

>>> df.resample(freq="3s", offset="2s")

  grouper = pd.Grouper(
2023-04-18 16:03:26,827 - distributed.core - INFO - Event loop was unresponsive in Worker for 3.75s.  This is often caused by long-running GIL-holding functions or moving large chunks of data. This can cause timeouts and instability.
2023-04-18 16:06:12,045 - distributed.core - INFO - Event loop was unresponsive in Worker for 6.05s.  This is often caused by long-running GIL-holding functions or moving large chunks of data. This can cause timeouts and instability.
2023-04-18 16:06:23,380 - distributed.core - INFO - Event loop was unresponsive in Worker for 11.33s.  This is often caused by long-running GIL-holding functions or moving large chunks of data. This can cause timeouts and instability.
2023-04-18 16:06:40,125 - distributed.core - INFO - Event loop was unresponsive in Worker for 11.16s.  This is often caused by long-running GIL-holding functions or moving large chunks of data. This can cause timeouts and instability.
2023-04-18 16:06:44,511 - distributed.worker_memory - WARNING - Worker tcp://172.16.3.138:45645 (pid=112971) exceeded 95% memory budget. Restarting...
2023-04-18 16:06:44,705 - distributed.nanny - INFO - Worker process 112971 was killed by signal 15
2023-04-18 16:06:46,029 - distributed.nanny - WARNING - Restarting worker
2023-04-18 16:07:13,848 - distributed.worker - INFO -       Start worker at:   tcp://172.16.3.138:34792
2023-04-18 16:07:13,849 - distributed.worker - INFO -          Listening to:   tcp://172.16.3.138:34792
2023-04-18 16:07:13,849 - distributed.worker - INFO -           Worker name:             SLURMCluster-5
2023-04-18 16:07:13,849 - distributed.worker - INFO -          dashboard at:         172.16.3.138:36682
2023-04-18 16:07:13,849 - distributed.worker - INFO - Waiting to connect to:    tcp://172.16.3.91:34882
2023-04-18 16:07:13,849 - distributed.worker - INFO - -------------------------------------------------
2023-04-18 16:07:13,849 - distributed.worker - INFO -               Threads:                         32
2023-04-18 16:07:13,849 - distributed.worker - INFO -                Memory:                  46.57 GiB
2023-04-18 16:07:13,851 - distributed.worker - INFO -       Local Directory: /tmp/dask-worker-space/worker-dqe51x43
2023-04-18 16:07:13,851 - distributed.worker - INFO - -------------------------------------------------
2023-04-18 16:07:43,851 - distributed.worker - INFO - Waiting to connect to:    tcp://172.16.3.91:34882
2023-04-18 16:07:46,032 - distributed.nanny - ERROR - Timed out connecting Nanny '<Nanny: tcp://172.16.3.138:45645, threads: 32>' to scheduler 'tcp://172.16.3.91:34882'
2023-04-18 16:07:46,032 - distributed.nanny - INFO - Closing Nanny at 'tcp://172.16.3.138:41731'. Reason: nanny-instantiate-timeout
2023-04-18 16:07:46,033 - distributed.nanny - INFO - Nanny asking worker to close. Reason: nanny-instantiate-timeout
2023-04-18 16:07:46,034 - distributed.worker - INFO - Stopping worker at tcp://172.16.3.138:34792. Reason: nanny-instantiate-timeout
2023-04-18 16:07:46,034 - distributed.worker - INFO - Closed worker has not yet started: Status.init
2023-04-18 16:07:59,610 - distributed.nanny - ERROR - Failed to start worker
ConnectionRefusedError: [Errno 111] Connection refused

The above exception was the direct cause of the following exception:

Traceback (most recent call last):
  File "/vortexfs1/home/anthony.meza/.conda/envs/notebook_env/lib/python3.10/site-packages/distributed/comm/core.py", line 291, in connect
    comm = await asyncio.wait_for(
  File "/vortexfs1/home/anthony.meza/.conda/envs/notebook_env/lib/python3.10/asyncio/tasks.py", line 445, in wait_for
    return fut.result()
  File "/vortexfs1/home/anthony.meza/.conda/envs/notebook_env/lib/python3.10/site-packages/distributed/comm/tcp.py", line 511, in connect
    convert_stream_closed_error(self, e)
  File "/vortexfs1/home/anthony.meza/.conda/envs/notebook_env/lib/python3.10/site-packages/distributed/comm/tcp.py", line 142, in convert_stream_closed_error
    raise CommClosedError(f"in {obj}: {exc.__class__.__name__}: {exc}") from exc
distributed.comm.core.CommClosedError: in <distributed.comm.tcp.TCPConnector object at 0x2aaac7358370>: ConnectionRefusedError: [Errno 111] Connection refused

During handling of the above exception, another exception occurred:

Traceback (most recent call last):
  File "/vortexfs1/home/anthony.meza/.conda/envs/notebook_env/lib/python3.10/site-packages/distributed/worker.py", line 1454, in start_unsafe
    await self._register_with_scheduler()
  File "/vortexfs1/home/anthony.meza/.conda/envs/notebook_env/lib/python3.10/site-packages/distributed/worker.py", line 1133, in _register_with_scheduler
    comm = await connect(self.scheduler.address, **self.connection_args)
  File "/vortexfs1/home/anthony.meza/.conda/envs/notebook_env/lib/python3.10/site-packages/distributed/comm/core.py", line 315, in connect
    await asyncio.sleep(backoff)
  File "/vortexfs1/home/anthony.meza/.conda/envs/notebook_env/lib/python3.10/asyncio/tasks.py", line 605, in sleep
    return await future
asyncio.exceptions.CancelledError

During handling of the above exception, another exception occurred:

Traceback (most recent call last):
  File "/vortexfs1/home/anthony.meza/.conda/envs/notebook_env/lib/python3.10/asyncio/tasks.py", line 456, in wait_for
    return fut.result()
asyncio.exceptions.CancelledError

The above exception was the direct cause of the following exception:

Traceback (most recent call last):
  File "/vortexfs1/home/anthony.meza/.conda/envs/notebook_env/lib/python3.10/site-packages/distributed/core.py", line 482, in start
    await asyncio.wait_for(self.start_unsafe(), timeout=timeout)
  File "/vortexfs1/home/anthony.meza/.conda/envs/notebook_env/lib/python3.10/asyncio/tasks.py", line 458, in wait_for
    raise exceptions.TimeoutError() from exc
asyncio.exceptions.TimeoutError

The above exception was the direct cause of the following exception:

Traceback (most recent call last):
  File "/vortexfs1/home/anthony.meza/.conda/envs/notebook_env/lib/python3.10/site-packages/distributed/nanny.py", line 921, in run
    async with worker:
  File "/vortexfs1/home/anthony.meza/.conda/envs/notebook_env/lib/python3.10/site-packages/distributed/core.py", line 495, in __aenter__
    await self
  File "/vortexfs1/home/anthony.meza/.conda/envs/notebook_env/lib/python3.10/site-packages/distributed/core.py", line 485, in start
    raise asyncio.TimeoutError(
asyncio.exceptions.TimeoutError: Worker start timed out after 60s.
2023-04-18 16:08:00,003 - distributed.nanny - ERROR - Failed to restart worker after its process exited
Traceback (most recent call last):
  File "/vortexfs1/home/anthony.meza/.conda/envs/notebook_env/lib/python3.10/site-packages/distributed/nanny.py", line 848, in _wait_until_connected
    msg = self.init_result_q.get_nowait()
  File "/vortexfs1/home/anthony.meza/.conda/envs/notebook_env/lib/python3.10/multiprocessing/queues.py", line 135, in get_nowait
    return self.get(False)
  File "/vortexfs1/home/anthony.meza/.conda/envs/notebook_env/lib/python3.10/multiprocessing/queues.py", line 116, in get
    raise Empty
_queue.Empty

During handling of the above exception, another exception occurred:

Traceback (most recent call last):
  File "/vortexfs1/home/anthony.meza/.conda/envs/notebook_env/lib/python3.10/site-packages/distributed/nanny.py", line 714, in start
    msg = await self._wait_until_connected(uid)
  File "/vortexfs1/home/anthony.meza/.conda/envs/notebook_env/lib/python3.10/site-packages/distributed/nanny.py", line 850, in _wait_until_connected
    await asyncio.sleep(self._init_msg_interval)
  File "/vortexfs1/home/anthony.meza/.conda/envs/notebook_env/lib/python3.10/asyncio/tasks.py", line 605, in sleep
    return await future
asyncio.exceptions.CancelledError

During handling of the above exception, another exception occurred:

Traceback (most recent call last):
  File "/vortexfs1/home/anthony.meza/.conda/envs/notebook_env/lib/python3.10/asyncio/tasks.py", line 456, in wait_for
    return fut.result()
asyncio.exceptions.CancelledError

The above exception was the direct cause of the following exception:

Traceback (most recent call last):
  File "/vortexfs1/home/anthony.meza/.conda/envs/notebook_env/lib/python3.10/site-packages/distributed/nanny.py", line 545, in _on_worker_exit
    await self.instantiate()
  File "/vortexfs1/home/anthony.meza/.conda/envs/notebook_env/lib/python3.10/site-packages/distributed/nanny.py", line 426, in instantiate
    result = await asyncio.wait_for(
  File "/vortexfs1/home/anthony.meza/.conda/envs/notebook_env/lib/python3.10/asyncio/tasks.py", line 458, in wait_for
    raise exceptions.TimeoutError() from exc
asyncio.exceptions.TimeoutError
2023-04-18 16:08:00,018 - distributed.dask_worker - INFO - End worker
