2023-05-02 17:32:59,777 - distributed.nanny - INFO -         Start Nanny at: 'tcp://172.16.3.55:42968'
2023-05-02 17:33:00,150 - distributed.diskutils - INFO - Found stale lock file and directory '/tmp/dask-worker-space/worker-rpmqrgv0', purging
2023-05-02 17:33:01,015 - distributed.worker - INFO -       Start worker at:    tcp://172.16.3.55:42654
2023-05-02 17:33:01,015 - distributed.worker - INFO -          Listening to:    tcp://172.16.3.55:42654
2023-05-02 17:33:01,015 - distributed.worker - INFO -           Worker name:             SLURMCluster-6
2023-05-02 17:33:01,015 - distributed.worker - INFO -          dashboard at:          172.16.3.55:39178
2023-05-02 17:33:01,015 - distributed.worker - INFO - Waiting to connect to:   tcp://172.16.3.106:40988
2023-05-02 17:33:01,015 - distributed.worker - INFO - -------------------------------------------------
2023-05-02 17:33:01,015 - distributed.worker - INFO -               Threads:                         36
2023-05-02 17:33:01,015 - distributed.worker - INFO -                Memory:                  93.13 GiB
2023-05-02 17:33:01,016 - distributed.worker - INFO -       Local Directory: /tmp/dask-worker-space/worker-gyowthh6
2023-05-02 17:33:01,016 - distributed.worker - INFO - -------------------------------------------------
2023-05-02 17:33:01,021 - distributed.worker - INFO -         Registered to:   tcp://172.16.3.106:40988
2023-05-02 17:33:01,021 - distributed.worker - INFO - -------------------------------------------------
2023-05-02 17:33:01,022 - distributed.core - INFO - Starting established connection to tcp://172.16.3.106:40988
2023-05-02 17:35:01,131 - distributed.utils_perf - INFO - full garbage collection released 163.26 MiB from 119 reference cycles (threshold: 9.54 MiB)
2023-05-02 17:35:02,533 - distributed.core - INFO - Event loop was unresponsive in Worker for 4.37s.  This is often caused by long-running GIL-holding functions or moving large chunks of data. This can cause timeouts and instability.
2023-05-02 17:35:06,700 - distributed.core - INFO - Event loop was unresponsive in Worker for 4.17s.  This is often caused by long-running GIL-holding functions or moving large chunks of data. This can cause timeouts and instability.
2023-05-02 17:35:10,533 - distributed.core - INFO - Event loop was unresponsive in Worker for 3.83s.  This is often caused by long-running GIL-holding functions or moving large chunks of data. This can cause timeouts and instability.
2023-05-02 17:35:19,703 - distributed.core - INFO - Event loop was unresponsive in Worker for 3.36s.  This is often caused by long-running GIL-holding functions or moving large chunks of data. This can cause timeouts and instability.
2023-05-02 17:35:26,038 - distributed.core - INFO - Event loop was unresponsive in Worker for 3.71s.  This is often caused by long-running GIL-holding functions or moving large chunks of data. This can cause timeouts and instability.
2023-05-02 17:35:39,359 - distributed.core - INFO - Event loop was unresponsive in Worker for 3.42s.  This is often caused by long-running GIL-holding functions or moving large chunks of data. This can cause timeouts and instability.
2023-05-02 17:35:43,512 - distributed.core - INFO - Event loop was unresponsive in Worker for 4.15s.  This is often caused by long-running GIL-holding functions or moving large chunks of data. This can cause timeouts and instability.
2023-05-02 17:35:47,015 - distributed.core - INFO - Event loop was unresponsive in Worker for 3.50s.  This is often caused by long-running GIL-holding functions or moving large chunks of data. This can cause timeouts and instability.
2023-05-02 17:35:47,016 - distributed.worker - ERROR - Failed to communicate with scheduler during heartbeat.
Traceback (most recent call last):
  File "/vortexfs1/home/anthony.meza/mambaforge/envs/atm_rivers/lib/python3.10/site-packages/distributed/comm/tcp.py", line 225, in read
    frames_nbytes = await stream.read_bytes(fmt_size)
tornado.iostream.StreamClosedError: Stream is closed

The above exception was the direct cause of the following exception:

Traceback (most recent call last):
  File "/vortexfs1/home/anthony.meza/mambaforge/envs/atm_rivers/lib/python3.10/site-packages/distributed/worker.py", line 1234, in heartbeat
    response = await retry_operation(
  File "/vortexfs1/home/anthony.meza/mambaforge/envs/atm_rivers/lib/python3.10/site-packages/distributed/utils_comm.py", line 434, in retry_operation
    return await retry(
  File "/vortexfs1/home/anthony.meza/mambaforge/envs/atm_rivers/lib/python3.10/site-packages/distributed/utils_comm.py", line 413, in retry
    return await coro()
  File "/vortexfs1/home/anthony.meza/mambaforge/envs/atm_rivers/lib/python3.10/site-packages/distributed/core.py", line 1268, in send_recv_from_rpc
    return await send_recv(comm=comm, op=key, **kwargs)
  File "/vortexfs1/home/anthony.meza/mambaforge/envs/atm_rivers/lib/python3.10/site-packages/distributed/core.py", line 1027, in send_recv
    response = await comm.read(deserializers=deserializers)
  File "/vortexfs1/home/anthony.meza/mambaforge/envs/atm_rivers/lib/python3.10/site-packages/distributed/comm/tcp.py", line 241, in read
    convert_stream_closed_error(self, e)
  File "/vortexfs1/home/anthony.meza/mambaforge/envs/atm_rivers/lib/python3.10/site-packages/distributed/comm/tcp.py", line 144, in convert_stream_closed_error
    raise CommClosedError(f"in {obj}: {exc}") from exc
distributed.comm.core.CommClosedError: in <TCP (closed) ConnectionPool.heartbeat_worker local=tcp://172.16.3.55:60418 remote=tcp://172.16.3.106:40988>: Stream is closed
2023-05-02 17:35:48,304 - distributed.worker - ERROR - failed during get data with tcp://172.16.3.55:42654 -> tcp://172.16.3.105:39501
Traceback (most recent call last):
  File "/vortexfs1/home/anthony.meza/mambaforge/envs/atm_rivers/lib/python3.10/site-packages/tornado/iostream.py", line 962, in _handle_write
    num_bytes = self.write_to_fd(self._write_buffer.peek(size))
  File "/vortexfs1/home/anthony.meza/mambaforge/envs/atm_rivers/lib/python3.10/site-packages/tornado/iostream.py", line 1124, in write_to_fd
    return self.socket.send(data)  # type: ignore
BrokenPipeError: [Errno 32] Broken pipe

The above exception was the direct cause of the following exception:

Traceback (most recent call last):
  File "/vortexfs1/home/anthony.meza/mambaforge/envs/atm_rivers/lib/python3.10/site-packages/distributed/worker.py", line 1783, in get_data
    response = await comm.read(deserializers=serializers)
  File "/vortexfs1/home/anthony.meza/mambaforge/envs/atm_rivers/lib/python3.10/site-packages/distributed/comm/tcp.py", line 241, in read
    convert_stream_closed_error(self, e)
  File "/vortexfs1/home/anthony.meza/mambaforge/envs/atm_rivers/lib/python3.10/site-packages/distributed/comm/tcp.py", line 142, in convert_stream_closed_error
    raise CommClosedError(f"in {obj}: {exc.__class__.__name__}: {exc}") from exc
distributed.comm.core.CommClosedError: in <TCP (closed)  local=tcp://172.16.3.55:42654 remote=tcp://172.16.3.105:45956>: BrokenPipeError: [Errno 32] Broken pipe
2023-05-02 17:35:48,304 - distributed.core - INFO - Lost connection to 'tcp://172.16.3.105:45956'
Traceback (most recent call last):
  File "/vortexfs1/home/anthony.meza/mambaforge/envs/atm_rivers/lib/python3.10/site-packages/tornado/iostream.py", line 962, in _handle_write
    num_bytes = self.write_to_fd(self._write_buffer.peek(size))
  File "/vortexfs1/home/anthony.meza/mambaforge/envs/atm_rivers/lib/python3.10/site-packages/tornado/iostream.py", line 1124, in write_to_fd
    return self.socket.send(data)  # type: ignore
BrokenPipeError: [Errno 32] Broken pipe

The above exception was the direct cause of the following exception:

Traceback (most recent call last):
  File "/vortexfs1/home/anthony.meza/mambaforge/envs/atm_rivers/lib/python3.10/site-packages/distributed/core.py", line 831, in _handle_comm
    result = await result
  File "/vortexfs1/home/anthony.meza/mambaforge/envs/atm_rivers/lib/python3.10/site-packages/distributed/core.py", line 990, in wrapper
    return await func(self, *args, **kwargs)
  File "/vortexfs1/home/anthony.meza/mambaforge/envs/atm_rivers/lib/python3.10/site-packages/distributed/worker.py", line 1783, in get_data
    response = await comm.read(deserializers=serializers)
  File "/vortexfs1/home/anthony.meza/mambaforge/envs/atm_rivers/lib/python3.10/site-packages/distributed/comm/tcp.py", line 241, in read
    convert_stream_closed_error(self, e)
  File "/vortexfs1/home/anthony.meza/mambaforge/envs/atm_rivers/lib/python3.10/site-packages/distributed/comm/tcp.py", line 142, in convert_stream_closed_error
    raise CommClosedError(f"in {obj}: {exc.__class__.__name__}: {exc}") from exc
distributed.comm.core.CommClosedError: in <TCP (closed)  local=tcp://172.16.3.55:42654 remote=tcp://172.16.3.105:45956>: BrokenPipeError: [Errno 32] Broken pipe
2023-05-02 17:35:48,573 - distributed.core - INFO - Connection to tcp://172.16.3.106:40988 has been closed.
2023-05-02 17:35:48,574 - distributed.worker - INFO - Stopping worker at tcp://172.16.3.55:42654. Reason: worker-handle-scheduler-connection-broken
2023-05-02 17:35:50,883 - distributed.worker - ERROR - failed during get data with tcp://172.16.3.55:42654 -> tcp://172.16.3.167:38216
Traceback (most recent call last):
  File "/vortexfs1/home/anthony.meza/mambaforge/envs/atm_rivers/lib/python3.10/site-packages/tornado/iostream.py", line 962, in _handle_write
    num_bytes = self.write_to_fd(self._write_buffer.peek(size))
  File "/vortexfs1/home/anthony.meza/mambaforge/envs/atm_rivers/lib/python3.10/site-packages/tornado/iostream.py", line 1124, in write_to_fd
    return self.socket.send(data)  # type: ignore
ConnectionResetError: [Errno 104] Connection reset by peer

The above exception was the direct cause of the following exception:

Traceback (most recent call last):
  File "/vortexfs1/home/anthony.meza/mambaforge/envs/atm_rivers/lib/python3.10/site-packages/distributed/worker.py", line 1783, in get_data
    response = await comm.read(deserializers=serializers)
  File "/vortexfs1/home/anthony.meza/mambaforge/envs/atm_rivers/lib/python3.10/site-packages/distributed/comm/tcp.py", line 241, in read
    convert_stream_closed_error(self, e)
  File "/vortexfs1/home/anthony.meza/mambaforge/envs/atm_rivers/lib/python3.10/site-packages/distributed/comm/tcp.py", line 142, in convert_stream_closed_error
    raise CommClosedError(f"in {obj}: {exc.__class__.__name__}: {exc}") from exc
distributed.comm.core.CommClosedError: in <TCP (closed)  local=tcp://172.16.3.55:42654 remote=tcp://172.16.3.167:34745>: ConnectionResetError: [Errno 104] Connection reset by peer
2023-05-02 17:35:50,896 - distributed.batched - INFO - Batched Comm Closed <TCP (closed) Worker->Scheduler local=tcp://172.16.3.55:60416 remote=tcp://172.16.3.106:40988>
Traceback (most recent call last):
  File "/vortexfs1/home/anthony.meza/mambaforge/envs/atm_rivers/lib/python3.10/site-packages/distributed/batched.py", line 115, in _background_send
    nbytes = yield coro
  File "/vortexfs1/home/anthony.meza/mambaforge/envs/atm_rivers/lib/python3.10/site-packages/tornado/gen.py", line 767, in run
    value = future.result()
  File "/vortexfs1/home/anthony.meza/mambaforge/envs/atm_rivers/lib/python3.10/site-packages/distributed/comm/tcp.py", line 269, in write
    raise CommClosedError()
distributed.comm.core.CommClosedError
2023-05-02 17:35:50,911 - distributed.nanny - INFO - Closing Nanny gracefully at 'tcp://172.16.3.55:42968'. Reason: worker-handle-scheduler-connection-broken
2023-05-02 17:35:56,347 - distributed.nanny - INFO - Worker closed
2023-05-02 17:35:58,349 - distributed.nanny - ERROR - Worker process died unexpectedly
2023-05-02 17:35:59,188 - distributed.nanny - INFO - Closing Nanny at 'tcp://172.16.3.55:42968'. Reason: nanny-close-gracefully
2023-05-02 17:35:59,189 - distributed.dask_worker - INFO - End worker
