2023-05-02 23:38:10,263 - distributed.nanny - INFO -         Start Nanny at: 'tcp://172.16.3.85:45657'
2023-05-02 23:38:16,027 - distributed.worker - INFO -       Start worker at:    tcp://172.16.3.85:32837
2023-05-02 23:38:16,027 - distributed.worker - INFO -          Listening to:    tcp://172.16.3.85:32837
2023-05-02 23:38:16,027 - distributed.worker - INFO -           Worker name:             SLURMCluster-7
2023-05-02 23:38:16,027 - distributed.worker - INFO -          dashboard at:          172.16.3.85:36438
2023-05-02 23:38:16,027 - distributed.worker - INFO - Waiting to connect to:    tcp://172.16.3.60:43304
2023-05-02 23:38:16,027 - distributed.worker - INFO - -------------------------------------------------
2023-05-02 23:38:16,027 - distributed.worker - INFO -               Threads:                         36
2023-05-02 23:38:16,028 - distributed.worker - INFO -                Memory:                  93.13 GiB
2023-05-02 23:38:16,028 - distributed.worker - INFO -       Local Directory: /tmp/dask-worker-space/worker-t8e_cc7z
2023-05-02 23:38:16,028 - distributed.worker - INFO - -------------------------------------------------
2023-05-02 23:38:16,033 - distributed.worker - INFO -         Registered to:    tcp://172.16.3.60:43304
2023-05-02 23:38:16,033 - distributed.worker - INFO - -------------------------------------------------
2023-05-02 23:38:16,034 - distributed.core - INFO - Starting established connection to tcp://172.16.3.60:43304
2023-05-02 23:40:37,042 - distributed.core - INFO - Connection to tcp://172.16.3.60:43304 has been closed.
2023-05-02 23:40:37,043 - distributed.worker - INFO - Stopping worker at tcp://172.16.3.85:32837. Reason: worker-handle-scheduler-connection-broken
2023-05-02 23:40:37,045 - distributed.worker - ERROR - Failed to communicate with scheduler during heartbeat.
Traceback (most recent call last):
  File "/vortexfs1/home/anthony.meza/mambaforge/envs/atm_rivers/lib/python3.10/site-packages/tornado/iostream.py", line 861, in _read_to_buffer
    bytes_read = self.read_from_fd(buf)
  File "/vortexfs1/home/anthony.meza/mambaforge/envs/atm_rivers/lib/python3.10/site-packages/tornado/iostream.py", line 1116, in read_from_fd
    return self.socket.recv_into(buf, len(buf))
ConnectionResetError: [Errno 104] Connection reset by peer

The above exception was the direct cause of the following exception:

Traceback (most recent call last):
  File "/vortexfs1/home/anthony.meza/mambaforge/envs/atm_rivers/lib/python3.10/site-packages/distributed/worker.py", line 1234, in heartbeat
    response = await retry_operation(
  File "/vortexfs1/home/anthony.meza/mambaforge/envs/atm_rivers/lib/python3.10/site-packages/distributed/utils_comm.py", line 434, in retry_operation
    return await retry(
  File "/vortexfs1/home/anthony.meza/mambaforge/envs/atm_rivers/lib/python3.10/site-packages/distributed/utils_comm.py", line 413, in retry
    return await coro()
  File "/vortexfs1/home/anthony.meza/mambaforge/envs/atm_rivers/lib/python3.10/site-packages/distributed/core.py", line 1268, in send_recv_from_rpc
    return await send_recv(comm=comm, op=key, **kwargs)
  File "/vortexfs1/home/anthony.meza/mambaforge/envs/atm_rivers/lib/python3.10/site-packages/distributed/core.py", line 1027, in send_recv
    response = await comm.read(deserializers=deserializers)
  File "/vortexfs1/home/anthony.meza/mambaforge/envs/atm_rivers/lib/python3.10/site-packages/distributed/comm/tcp.py", line 241, in read
    convert_stream_closed_error(self, e)
  File "/vortexfs1/home/anthony.meza/mambaforge/envs/atm_rivers/lib/python3.10/site-packages/distributed/comm/tcp.py", line 142, in convert_stream_closed_error
    raise CommClosedError(f"in {obj}: {exc.__class__.__name__}: {exc}") from exc
distributed.comm.core.CommClosedError: in <TCP (closed) ConnectionPool.heartbeat_worker local=tcp://172.16.3.85:53734 remote=tcp://172.16.3.60:43304>: ConnectionResetError: [Errno 104] Connection reset by peer
2023-05-02 23:40:37,093 - distributed.nanny - INFO - Closing Nanny gracefully at 'tcp://172.16.3.85:45657'. Reason: worker-handle-scheduler-connection-broken
2023-05-02 23:40:39,201 - distributed.client - ERROR - 
ConnectionRefusedError: [Errno 111] Connection refused

The above exception was the direct cause of the following exception:

Traceback (most recent call last):
  File "/vortexfs1/home/anthony.meza/mambaforge/envs/atm_rivers/lib/python3.10/site-packages/distributed/comm/core.py", line 292, in connect
    comm = await wait_for(
  File "/vortexfs1/home/anthony.meza/mambaforge/envs/atm_rivers/lib/python3.10/site-packages/distributed/utils.py", line 1850, in wait_for
    return await asyncio.wait_for(fut, timeout)
  File "/vortexfs1/home/anthony.meza/mambaforge/envs/atm_rivers/lib/python3.10/asyncio/tasks.py", line 445, in wait_for
    return fut.result()
  File "/vortexfs1/home/anthony.meza/mambaforge/envs/atm_rivers/lib/python3.10/site-packages/distributed/comm/tcp.py", line 511, in connect
    convert_stream_closed_error(self, e)
  File "/vortexfs1/home/anthony.meza/mambaforge/envs/atm_rivers/lib/python3.10/site-packages/distributed/comm/tcp.py", line 142, in convert_stream_closed_error
    raise CommClosedError(f"in {obj}: {exc.__class__.__name__}: {exc}") from exc
distributed.comm.core.CommClosedError: in <distributed.comm.tcp.TCPConnector object at 0x2aaad7c3aef0>: ConnectionRefusedError: [Errno 111] Connection refused

During handling of the above exception, another exception occurred:

Traceback (most recent call last):
  File "/vortexfs1/home/anthony.meza/mambaforge/envs/atm_rivers/lib/python3.10/site-packages/distributed/utils.py", line 752, in wrapper
    return await func(*args, **kwargs)
  File "/vortexfs1/home/anthony.meza/mambaforge/envs/atm_rivers/lib/python3.10/site-packages/distributed/client.py", line 1321, in _reconnect
    await self._ensure_connected(timeout=timeout)
  File "/vortexfs1/home/anthony.meza/mambaforge/envs/atm_rivers/lib/python3.10/site-packages/distributed/client.py", line 1351, in _ensure_connected
    comm = await connect(
  File "/vortexfs1/home/anthony.meza/mambaforge/envs/atm_rivers/lib/python3.10/site-packages/distributed/comm/core.py", line 316, in connect
    await asyncio.sleep(backoff)
  File "/vortexfs1/home/anthony.meza/mambaforge/envs/atm_rivers/lib/python3.10/asyncio/tasks.py", line 605, in sleep
    return await future
asyncio.exceptions.CancelledError
2023-05-02 23:40:41,308 - distributed.client - ERROR - 
ConnectionRefusedError: [Errno 111] Connection refused

The above exception was the direct cause of the following exception:

Traceback (most recent call last):
  File "/vortexfs1/home/anthony.meza/mambaforge/envs/atm_rivers/lib/python3.10/site-packages/distributed/comm/core.py", line 292, in connect
    comm = await wait_for(
  File "/vortexfs1/home/anthony.meza/mambaforge/envs/atm_rivers/lib/python3.10/site-packages/distributed/utils.py", line 1850, in wait_for
    return await asyncio.wait_for(fut, timeout)
  File "/vortexfs1/home/anthony.meza/mambaforge/envs/atm_rivers/lib/python3.10/asyncio/tasks.py", line 445, in wait_for
    return fut.result()
  File "/vortexfs1/home/anthony.meza/mambaforge/envs/atm_rivers/lib/python3.10/site-packages/distributed/comm/tcp.py", line 511, in connect
    convert_stream_closed_error(self, e)
  File "/vortexfs1/home/anthony.meza/mambaforge/envs/atm_rivers/lib/python3.10/site-packages/distributed/comm/tcp.py", line 142, in convert_stream_closed_error
    raise CommClosedError(f"in {obj}: {exc.__class__.__name__}: {exc}") from exc
distributed.comm.core.CommClosedError: in <distributed.comm.tcp.TCPConnector object at 0x2aaab752f2b0>: ConnectionRefusedError: [Errno 111] Connection refused

During handling of the above exception, another exception occurred:

Traceback (most recent call last):
  File "/vortexfs1/home/anthony.meza/mambaforge/envs/atm_rivers/lib/python3.10/site-packages/distributed/utils.py", line 752, in wrapper
    return await func(*args, **kwargs)
  File "/vortexfs1/home/anthony.meza/mambaforge/envs/atm_rivers/lib/python3.10/site-packages/distributed/client.py", line 1321, in _reconnect
    await self._ensure_connected(timeout=timeout)
  File "/vortexfs1/home/anthony.meza/mambaforge/envs/atm_rivers/lib/python3.10/site-packages/distributed/client.py", line 1351, in _ensure_connected
    comm = await connect(
  File "/vortexfs1/home/anthony.meza/mambaforge/envs/atm_rivers/lib/python3.10/site-packages/distributed/comm/core.py", line 316, in connect
    await asyncio.sleep(backoff)
  File "/vortexfs1/home/anthony.meza/mambaforge/envs/atm_rivers/lib/python3.10/asyncio/tasks.py", line 605, in sleep
    return await future
asyncio.exceptions.CancelledError
2023-05-02 23:40:43,413 - distributed.client - ERROR - 
ConnectionRefusedError: [Errno 111] Connection refused

The above exception was the direct cause of the following exception:

Traceback (most recent call last):
  File "/vortexfs1/home/anthony.meza/mambaforge/envs/atm_rivers/lib/python3.10/site-packages/distributed/comm/core.py", line 292, in connect
    comm = await wait_for(
  File "/vortexfs1/home/anthony.meza/mambaforge/envs/atm_rivers/lib/python3.10/site-packages/distributed/utils.py", line 1850, in wait_for
    return await asyncio.wait_for(fut, timeout)
  File "/vortexfs1/home/anthony.meza/mambaforge/envs/atm_rivers/lib/python3.10/asyncio/tasks.py", line 445, in wait_for
    return fut.result()
  File "/vortexfs1/home/anthony.meza/mambaforge/envs/atm_rivers/lib/python3.10/site-packages/distributed/comm/tcp.py", line 511, in connect
    convert_stream_closed_error(self, e)
  File "/vortexfs1/home/anthony.meza/mambaforge/envs/atm_rivers/lib/python3.10/site-packages/distributed/comm/tcp.py", line 142, in convert_stream_closed_error
    raise CommClosedError(f"in {obj}: {exc.__class__.__name__}: {exc}") from exc
distributed.comm.core.CommClosedError: in <distributed.comm.tcp.TCPConnector object at 0x2aaad79a7160>: ConnectionRefusedError: [Errno 111] Connection refused

During handling of the above exception, another exception occurred:

Traceback (most recent call last):
  File "/vortexfs1/home/anthony.meza/mambaforge/envs/atm_rivers/lib/python3.10/site-packages/distributed/utils.py", line 752, in wrapper
    return await func(*args, **kwargs)
  File "/vortexfs1/home/anthony.meza/mambaforge/envs/atm_rivers/lib/python3.10/site-packages/distributed/client.py", line 1321, in _reconnect
    await self._ensure_connected(timeout=timeout)
  File "/vortexfs1/home/anthony.meza/mambaforge/envs/atm_rivers/lib/python3.10/site-packages/distributed/client.py", line 1351, in _ensure_connected
    comm = await connect(
  File "/vortexfs1/home/anthony.meza/mambaforge/envs/atm_rivers/lib/python3.10/site-packages/distributed/comm/core.py", line 316, in connect
    await asyncio.sleep(backoff)
  File "/vortexfs1/home/anthony.meza/mambaforge/envs/atm_rivers/lib/python3.10/asyncio/tasks.py", line 605, in sleep
    return await future
asyncio.exceptions.CancelledError
2023-05-02 23:40:45,519 - distributed.client - ERROR - 
ConnectionRefusedError: [Errno 111] Connection refused

The above exception was the direct cause of the following exception:

Traceback (most recent call last):
  File "/vortexfs1/home/anthony.meza/mambaforge/envs/atm_rivers/lib/python3.10/site-packages/distributed/comm/core.py", line 292, in connect
    comm = await wait_for(
  File "/vortexfs1/home/anthony.meza/mambaforge/envs/atm_rivers/lib/python3.10/site-packages/distributed/utils.py", line 1850, in wait_for
    return await asyncio.wait_for(fut, timeout)
  File "/vortexfs1/home/anthony.meza/mambaforge/envs/atm_rivers/lib/python3.10/asyncio/tasks.py", line 445, in wait_for
    return fut.result()
  File "/vortexfs1/home/anthony.meza/mambaforge/envs/atm_rivers/lib/python3.10/site-packages/distributed/comm/tcp.py", line 511, in connect
    convert_stream_closed_error(self, e)
  File "/vortexfs1/home/anthony.meza/mambaforge/envs/atm_rivers/lib/python3.10/site-packages/distributed/comm/tcp.py", line 142, in convert_stream_closed_error
    raise CommClosedError(f"in {obj}: {exc.__class__.__name__}: {exc}") from exc
distributed.comm.core.CommClosedError: in <distributed.comm.tcp.TCPConnector object at 0x2aaad7c3b370>: ConnectionRefusedError: [Errno 111] Connection refused

During handling of the above exception, another exception occurred:

Traceback (most recent call last):
  File "/vortexfs1/home/anthony.meza/mambaforge/envs/atm_rivers/lib/python3.10/site-packages/distributed/utils.py", line 752, in wrapper
    return await func(*args, **kwargs)
  File "/vortexfs1/home/anthony.meza/mambaforge/envs/atm_rivers/lib/python3.10/site-packages/distributed/client.py", line 1321, in _reconnect
    await self._ensure_connected(timeout=timeout)
  File "/vortexfs1/home/anthony.meza/mambaforge/envs/atm_rivers/lib/python3.10/site-packages/distributed/client.py", line 1351, in _ensure_connected
    comm = await connect(
  File "/vortexfs1/home/anthony.meza/mambaforge/envs/atm_rivers/lib/python3.10/site-packages/distributed/comm/core.py", line 316, in connect
    await asyncio.sleep(backoff)
  File "/vortexfs1/home/anthony.meza/mambaforge/envs/atm_rivers/lib/python3.10/asyncio/tasks.py", line 605, in sleep
    return await future
asyncio.exceptions.CancelledError
2023-05-02 23:41:15,522 - distributed.nanny - INFO - Worker closed
2023-05-02 23:41:17,524 - distributed.nanny - ERROR - Worker process died unexpectedly
2023-05-02 23:44:43,145 - distributed.nanny - INFO - Closing Nanny at 'tcp://172.16.3.85:45657'. Reason: nanny-close-gracefully
2023-05-02 23:44:43,146 - distributed.dask_worker - INFO - End worker
