2023-05-03 09:14:41,488 - distributed.nanny - INFO -         Start Nanny at: 'tcp://172.16.3.88:46392'
2023-05-03 09:14:42,476 - distributed.worker - INFO -       Start worker at:    tcp://172.16.3.88:33948
2023-05-03 09:14:42,476 - distributed.worker - INFO -          Listening to:    tcp://172.16.3.88:33948
2023-05-03 09:14:42,477 - distributed.worker - INFO -           Worker name:             SLURMCluster-2
2023-05-03 09:14:42,477 - distributed.worker - INFO -          dashboard at:          172.16.3.88:44060
2023-05-03 09:14:42,477 - distributed.worker - INFO - Waiting to connect to:   tcp://172.16.3.158:44759
2023-05-03 09:14:42,477 - distributed.worker - INFO - -------------------------------------------------
2023-05-03 09:14:42,477 - distributed.worker - INFO -               Threads:                         36
2023-05-03 09:14:42,477 - distributed.worker - INFO -                Memory:                 178.81 GiB
2023-05-03 09:14:42,477 - distributed.worker - INFO -       Local Directory: /tmp/dask-worker-space/worker-sqj66tcf
2023-05-03 09:14:42,477 - distributed.worker - INFO - -------------------------------------------------
2023-05-03 09:14:42,482 - distributed.worker - INFO -         Registered to:   tcp://172.16.3.158:44759
2023-05-03 09:14:42,482 - distributed.worker - INFO - -------------------------------------------------
2023-05-03 09:14:42,482 - distributed.core - INFO - Starting established connection to tcp://172.16.3.158:44759
2023-05-03 09:17:36,021 - distributed.utils_perf - INFO - full garbage collection released 207.64 MiB from 0 reference cycles (threshold: 9.54 MiB)
2023-05-03 09:17:40,446 - distributed.utils_perf - INFO - full garbage collection released 1.73 GiB from 160 reference cycles (threshold: 9.54 MiB)
2023-05-03 09:17:49,801 - distributed.utils_perf - INFO - full garbage collection released 186.59 MiB from 580 reference cycles (threshold: 9.54 MiB)
2023-05-03 09:17:58,025 - distributed.utils_perf - INFO - full garbage collection released 79.83 MiB from 859 reference cycles (threshold: 9.54 MiB)
2023-05-03 09:18:09,647 - distributed.utils_perf - INFO - full garbage collection released 1.22 GiB from 639 reference cycles (threshold: 9.54 MiB)
2023-05-03 09:18:40,107 - distributed.utils_perf - INFO - full garbage collection released 120.07 MiB from 600 reference cycles (threshold: 9.54 MiB)
2023-05-03 09:19:47,045 - distributed.core - INFO - Event loop was unresponsive in Worker for 3.58s.  This is often caused by long-running GIL-holding functions or moving large chunks of data. This can cause timeouts and instability.
2023-05-03 09:20:18,624 - distributed.core - INFO - Event loop was unresponsive in Worker for 3.27s.  This is often caused by long-running GIL-holding functions or moving large chunks of data. This can cause timeouts and instability.
2023-05-03 09:20:35,686 - distributed.core - INFO - Event loop was unresponsive in Worker for 3.40s.  This is often caused by long-running GIL-holding functions or moving large chunks of data. This can cause timeouts and instability.
2023-05-03 09:20:52,086 - distributed.core - INFO - Event loop was unresponsive in Worker for 3.55s.  This is often caused by long-running GIL-holding functions or moving large chunks of data. This can cause timeouts and instability.
2023-05-03 09:21:09,944 - distributed.core - INFO - Event loop was unresponsive in Worker for 4.53s.  This is often caused by long-running GIL-holding functions or moving large chunks of data. This can cause timeouts and instability.
2023-05-03 09:21:33,322 - distributed.core - INFO - Event loop was unresponsive in Worker for 4.94s.  This is often caused by long-running GIL-holding functions or moving large chunks of data. This can cause timeouts and instability.
2023-05-03 09:21:47,934 - distributed.core - INFO - Event loop was unresponsive in Worker for 4.00s.  This is often caused by long-running GIL-holding functions or moving large chunks of data. This can cause timeouts and instability.
2023-05-03 09:21:47,940 - distributed.utils_perf - INFO - full garbage collection released 11.25 MiB from 679 reference cycles (threshold: 9.54 MiB)
2023-05-03 09:22:00,028 - distributed.core - INFO - Event loop was unresponsive in Worker for 4.58s.  This is often caused by long-running GIL-holding functions or moving large chunks of data. This can cause timeouts and instability.
2023-05-03 09:22:14,453 - distributed.utils_perf - WARNING - full garbage collections took 23% CPU time recently (threshold: 10%)
2023-05-03 09:22:14,502 - distributed.core - INFO - Event loop was unresponsive in Worker for 5.10s.  This is often caused by long-running GIL-holding functions or moving large chunks of data. This can cause timeouts and instability.
2023-05-03 09:22:33,004 - distributed.utils_perf - WARNING - full garbage collections took 24% CPU time recently (threshold: 10%)
2023-05-03 09:22:33,116 - distributed.core - INFO - Event loop was unresponsive in Worker for 6.51s.  This is often caused by long-running GIL-holding functions or moving large chunks of data. This can cause timeouts and instability.
2023-05-03 09:23:10,493 - distributed.core - INFO - Event loop was unresponsive in Worker for 36.86s.  This is often caused by long-running GIL-holding functions or moving large chunks of data. This can cause timeouts and instability.
2023-05-03 09:23:17,146 - distributed.worker - ERROR - Worker stream died during communication: tcp://172.16.3.167:38996
Traceback (most recent call last):
  File "/vortexfs1/home/anthony.meza/mambaforge/envs/atm_rivers/lib/python3.10/site-packages/tornado/iostream.py", line 861, in _read_to_buffer
    bytes_read = self.read_from_fd(buf)
  File "/vortexfs1/home/anthony.meza/mambaforge/envs/atm_rivers/lib/python3.10/site-packages/tornado/iostream.py", line 1116, in read_from_fd
    return self.socket.recv_into(buf, len(buf))
ConnectionResetError: [Errno 104] Connection reset by peer

The above exception was the direct cause of the following exception:

Traceback (most recent call last):
  File "/vortexfs1/home/anthony.meza/mambaforge/envs/atm_rivers/lib/python3.10/site-packages/distributed/worker.py", line 2056, in gather_dep
    response = await get_data_from_worker(
  File "/vortexfs1/home/anthony.meza/mambaforge/envs/atm_rivers/lib/python3.10/site-packages/distributed/worker.py", line 2891, in get_data_from_worker
    response = await send_recv(
  File "/vortexfs1/home/anthony.meza/mambaforge/envs/atm_rivers/lib/python3.10/site-packages/distributed/core.py", line 1027, in send_recv
    response = await comm.read(deserializers=deserializers)
  File "/vortexfs1/home/anthony.meza/mambaforge/envs/atm_rivers/lib/python3.10/site-packages/distributed/comm/tcp.py", line 241, in read
    convert_stream_closed_error(self, e)
  File "/vortexfs1/home/anthony.meza/mambaforge/envs/atm_rivers/lib/python3.10/site-packages/distributed/comm/tcp.py", line 142, in convert_stream_closed_error
    raise CommClosedError(f"in {obj}: {exc.__class__.__name__}: {exc}") from exc
distributed.comm.core.CommClosedError: in <TCP (closed) Ephemeral Worker->Worker for gather local=tcp://172.16.3.88:52607 remote=tcp://172.16.3.167:38996>: ConnectionResetError: [Errno 104] Connection reset by peer
2023-05-03 09:23:17,730 - distributed.worker - ERROR - Worker stream died during communication: tcp://172.16.3.169:39906
Traceback (most recent call last):
  File "/vortexfs1/home/anthony.meza/mambaforge/envs/atm_rivers/lib/python3.10/site-packages/tornado/iostream.py", line 861, in _read_to_buffer
    bytes_read = self.read_from_fd(buf)
  File "/vortexfs1/home/anthony.meza/mambaforge/envs/atm_rivers/lib/python3.10/site-packages/tornado/iostream.py", line 1116, in read_from_fd
    return self.socket.recv_into(buf, len(buf))
ConnectionResetError: [Errno 104] Connection reset by peer

The above exception was the direct cause of the following exception:

Traceback (most recent call last):
  File "/vortexfs1/home/anthony.meza/mambaforge/envs/atm_rivers/lib/python3.10/site-packages/distributed/worker.py", line 2056, in gather_dep
    response = await get_data_from_worker(
  File "/vortexfs1/home/anthony.meza/mambaforge/envs/atm_rivers/lib/python3.10/site-packages/distributed/worker.py", line 2891, in get_data_from_worker
    response = await send_recv(
  File "/vortexfs1/home/anthony.meza/mambaforge/envs/atm_rivers/lib/python3.10/site-packages/distributed/core.py", line 1027, in send_recv
    response = await comm.read(deserializers=deserializers)
  File "/vortexfs1/home/anthony.meza/mambaforge/envs/atm_rivers/lib/python3.10/site-packages/distributed/comm/tcp.py", line 241, in read
    convert_stream_closed_error(self, e)
  File "/vortexfs1/home/anthony.meza/mambaforge/envs/atm_rivers/lib/python3.10/site-packages/distributed/comm/tcp.py", line 142, in convert_stream_closed_error
    raise CommClosedError(f"in {obj}: {exc.__class__.__name__}: {exc}") from exc
distributed.comm.core.CommClosedError: in <TCP (closed) Ephemeral Worker->Worker for gather local=tcp://172.16.3.88:35163 remote=tcp://172.16.3.169:39906>: ConnectionResetError: [Errno 104] Connection reset by peer
2023-05-03 09:23:17,731 - distributed.worker - ERROR - Worker stream died during communication: tcp://172.16.3.62:35035
Traceback (most recent call last):
  File "/vortexfs1/home/anthony.meza/mambaforge/envs/atm_rivers/lib/python3.10/site-packages/tornado/iostream.py", line 861, in _read_to_buffer
    bytes_read = self.read_from_fd(buf)
  File "/vortexfs1/home/anthony.meza/mambaforge/envs/atm_rivers/lib/python3.10/site-packages/tornado/iostream.py", line 1116, in read_from_fd
    return self.socket.recv_into(buf, len(buf))
ConnectionResetError: [Errno 104] Connection reset by peer

The above exception was the direct cause of the following exception:

Traceback (most recent call last):
  File "/vortexfs1/home/anthony.meza/mambaforge/envs/atm_rivers/lib/python3.10/site-packages/distributed/worker.py", line 2056, in gather_dep
    response = await get_data_from_worker(
  File "/vortexfs1/home/anthony.meza/mambaforge/envs/atm_rivers/lib/python3.10/site-packages/distributed/worker.py", line 2891, in get_data_from_worker
    response = await send_recv(
  File "/vortexfs1/home/anthony.meza/mambaforge/envs/atm_rivers/lib/python3.10/site-packages/distributed/core.py", line 1027, in send_recv
    response = await comm.read(deserializers=deserializers)
  File "/vortexfs1/home/anthony.meza/mambaforge/envs/atm_rivers/lib/python3.10/site-packages/distributed/comm/tcp.py", line 241, in read
    convert_stream_closed_error(self, e)
  File "/vortexfs1/home/anthony.meza/mambaforge/envs/atm_rivers/lib/python3.10/site-packages/distributed/comm/tcp.py", line 142, in convert_stream_closed_error
    raise CommClosedError(f"in {obj}: {exc.__class__.__name__}: {exc}") from exc
distributed.comm.core.CommClosedError: in <TCP (closed) Ephemeral Worker->Worker for gather local=tcp://172.16.3.88:51650 remote=tcp://172.16.3.62:35035>: ConnectionResetError: [Errno 104] Connection reset by peer
2023-05-03 09:23:17,731 - distributed.core - INFO - Event loop was unresponsive in Worker for 7.24s.  This is often caused by long-running GIL-holding functions or moving large chunks of data. This can cause timeouts and instability.
2023-05-03 09:23:48,708 - distributed.worker - ERROR - Worker stream died during communication: tcp://172.16.3.93:41353
Traceback (most recent call last):
  File "/vortexfs1/home/anthony.meza/mambaforge/envs/atm_rivers/lib/python3.10/site-packages/tornado/iostream.py", line 861, in _read_to_buffer
    bytes_read = self.read_from_fd(buf)
  File "/vortexfs1/home/anthony.meza/mambaforge/envs/atm_rivers/lib/python3.10/site-packages/tornado/iostream.py", line 1116, in read_from_fd
    return self.socket.recv_into(buf, len(buf))
ConnectionResetError: [Errno 104] Connection reset by peer

The above exception was the direct cause of the following exception:

Traceback (most recent call last):
  File "/vortexfs1/home/anthony.meza/mambaforge/envs/atm_rivers/lib/python3.10/site-packages/distributed/worker.py", line 2056, in gather_dep
    response = await get_data_from_worker(
  File "/vortexfs1/home/anthony.meza/mambaforge/envs/atm_rivers/lib/python3.10/site-packages/distributed/worker.py", line 2891, in get_data_from_worker
    response = await send_recv(
  File "/vortexfs1/home/anthony.meza/mambaforge/envs/atm_rivers/lib/python3.10/site-packages/distributed/core.py", line 1027, in send_recv
    response = await comm.read(deserializers=deserializers)
  File "/vortexfs1/home/anthony.meza/mambaforge/envs/atm_rivers/lib/python3.10/site-packages/distributed/comm/tcp.py", line 241, in read
    convert_stream_closed_error(self, e)
  File "/vortexfs1/home/anthony.meza/mambaforge/envs/atm_rivers/lib/python3.10/site-packages/distributed/comm/tcp.py", line 142, in convert_stream_closed_error
    raise CommClosedError(f"in {obj}: {exc.__class__.__name__}: {exc}") from exc
distributed.comm.core.CommClosedError: in <TCP (closed) Ephemeral Worker->Worker for gather local=tcp://172.16.3.88:55573 remote=tcp://172.16.3.93:41353>: ConnectionResetError: [Errno 104] Connection reset by peer
2023-05-03 09:23:48,843 - distributed.core - INFO - Event loop was unresponsive in Worker for 31.11s.  This is often caused by long-running GIL-holding functions or moving large chunks of data. This can cause timeouts and instability.
2023-05-03 09:23:52,159 - distributed.core - INFO - Event loop was unresponsive in Worker for 3.32s.  This is often caused by long-running GIL-holding functions or moving large chunks of data. This can cause timeouts and instability.
2023-05-03 09:23:57,029 - distributed.core - INFO - Event loop was unresponsive in Worker for 4.02s.  This is often caused by long-running GIL-holding functions or moving large chunks of data. This can cause timeouts and instability.
2023-05-03 09:24:20,260 - distributed.utils_perf - WARNING - full garbage collections took 19% CPU time recently (threshold: 10%)
2023-05-03 09:24:20,369 - distributed.core - INFO - Event loop was unresponsive in Worker for 9.97s.  This is often caused by long-running GIL-holding functions or moving large chunks of data. This can cause timeouts and instability.
2023-05-03 09:24:42,044 - distributed.utils_perf - WARNING - full garbage collections took 20% CPU time recently (threshold: 10%)
2023-05-03 09:24:42,799 - distributed.core - INFO - Event loop was unresponsive in Worker for 8.41s.  This is often caused by long-running GIL-holding functions or moving large chunks of data. This can cause timeouts and instability.
2023-05-03 09:25:05,144 - distributed.utils_perf - WARNING - full garbage collections took 21% CPU time recently (threshold: 10%)
2023-05-03 09:25:05,857 - distributed.core - INFO - Event loop was unresponsive in Worker for 9.03s.  This is often caused by long-running GIL-holding functions or moving large chunks of data. This can cause timeouts and instability.
2023-05-03 09:25:27,598 - distributed.utils_perf - WARNING - full garbage collections took 23% CPU time recently (threshold: 10%)
2023-05-03 09:25:28,287 - distributed.core - INFO - Event loop was unresponsive in Worker for 9.14s.  This is often caused by long-running GIL-holding functions or moving large chunks of data. This can cause timeouts and instability.
2023-05-03 09:25:54,691 - distributed.utils_perf - WARNING - full garbage collections took 24% CPU time recently (threshold: 10%)
2023-05-03 09:25:54,920 - distributed.core - INFO - Event loop was unresponsive in Worker for 10.59s.  This is often caused by long-running GIL-holding functions or moving large chunks of data. This can cause timeouts and instability.
2023-05-03 09:26:20,102 - distributed.utils_perf - WARNING - full garbage collections took 25% CPU time recently (threshold: 10%)
2023-05-03 09:26:20,644 - distributed.core - INFO - Event loop was unresponsive in Worker for 11.09s.  This is often caused by long-running GIL-holding functions or moving large chunks of data. This can cause timeouts and instability.
2023-05-03 09:26:42,223 - distributed.utils_perf - WARNING - full garbage collections took 26% CPU time recently (threshold: 10%)
2023-05-03 09:26:42,364 - distributed.core - INFO - Event loop was unresponsive in Worker for 10.18s.  This is often caused by long-running GIL-holding functions or moving large chunks of data. This can cause timeouts and instability.
2023-05-03 09:27:05,259 - distributed.utils_perf - WARNING - full garbage collections took 28% CPU time recently (threshold: 10%)
2023-05-03 09:27:05,355 - distributed.core - INFO - Event loop was unresponsive in Worker for 11.93s.  This is often caused by long-running GIL-holding functions or moving large chunks of data. This can cause timeouts and instability.
2023-05-03 09:27:29,528 - distributed.utils_perf - WARNING - full garbage collections took 29% CPU time recently (threshold: 10%)
2023-05-03 09:27:29,720 - distributed.core - INFO - Event loop was unresponsive in Worker for 10.72s.  This is often caused by long-running GIL-holding functions or moving large chunks of data. This can cause timeouts and instability.
2023-05-03 09:28:00,697 - distributed.utils_perf - WARNING - full garbage collections took 30% CPU time recently (threshold: 10%)
2023-05-03 09:28:01,105 - distributed.core - INFO - Event loop was unresponsive in Worker for 13.85s.  This is often caused by long-running GIL-holding functions or moving large chunks of data. This can cause timeouts and instability.
2023-05-03 09:28:24,785 - distributed.utils_perf - WARNING - full garbage collections took 31% CPU time recently (threshold: 10%)
2023-05-03 09:28:24,918 - distributed.core - INFO - Event loop was unresponsive in Worker for 11.89s.  This is often caused by long-running GIL-holding functions or moving large chunks of data. This can cause timeouts and instability.
2023-05-03 09:28:59,004 - distributed.utils_perf - WARNING - full garbage collections took 32% CPU time recently (threshold: 10%)
2023-05-03 09:28:59,371 - distributed.core - INFO - Event loop was unresponsive in Worker for 13.82s.  This is often caused by long-running GIL-holding functions or moving large chunks of data. This can cause timeouts and instability.
2023-05-03 09:29:32,743 - distributed.utils_perf - WARNING - full garbage collections took 33% CPU time recently (threshold: 10%)
2023-05-03 09:29:32,919 - distributed.core - INFO - Event loop was unresponsive in Worker for 14.04s.  This is often caused by long-running GIL-holding functions or moving large chunks of data. This can cause timeouts and instability.
2023-05-03 09:30:08,062 - distributed.utils_perf - WARNING - full garbage collections took 34% CPU time recently (threshold: 10%)
2023-05-03 09:30:08,547 - distributed.core - INFO - Event loop was unresponsive in Worker for 15.45s.  This is often caused by long-running GIL-holding functions or moving large chunks of data. This can cause timeouts and instability.
2023-05-03 09:30:42,635 - distributed.core - INFO - Event loop was unresponsive in Worker for 20.39s.  This is often caused by long-running GIL-holding functions or moving large chunks of data. This can cause timeouts and instability.
2023-05-03 09:31:07,774 - distributed.worker - ERROR - failed during get data with tcp://172.16.3.88:33948 -> tcp://172.16.3.62:35035
Traceback (most recent call last):
  File "/vortexfs1/home/anthony.meza/mambaforge/envs/atm_rivers/lib/python3.10/site-packages/tornado/iostream.py", line 962, in _handle_write
    num_bytes = self.write_to_fd(self._write_buffer.peek(size))
  File "/vortexfs1/home/anthony.meza/mambaforge/envs/atm_rivers/lib/python3.10/site-packages/tornado/iostream.py", line 1124, in write_to_fd
    return self.socket.send(data)  # type: ignore
BrokenPipeError: [Errno 32] Broken pipe

The above exception was the direct cause of the following exception:

Traceback (most recent call last):
  File "/vortexfs1/home/anthony.meza/mambaforge/envs/atm_rivers/lib/python3.10/site-packages/distributed/worker.py", line 1783, in get_data
    response = await comm.read(deserializers=serializers)
  File "/vortexfs1/home/anthony.meza/mambaforge/envs/atm_rivers/lib/python3.10/site-packages/distributed/comm/tcp.py", line 241, in read
    convert_stream_closed_error(self, e)
  File "/vortexfs1/home/anthony.meza/mambaforge/envs/atm_rivers/lib/python3.10/site-packages/distributed/comm/tcp.py", line 142, in convert_stream_closed_error
    raise CommClosedError(f"in {obj}: {exc.__class__.__name__}: {exc}") from exc
distributed.comm.core.CommClosedError: in <TCP (closed)  local=tcp://172.16.3.88:33948 remote=tcp://172.16.3.62:36353>: BrokenPipeError: [Errno 32] Broken pipe
2023-05-03 09:31:07,776 - distributed.core - INFO - Lost connection to 'tcp://172.16.3.62:36353'
Traceback (most recent call last):
  File "/vortexfs1/home/anthony.meza/mambaforge/envs/atm_rivers/lib/python3.10/site-packages/tornado/iostream.py", line 962, in _handle_write
    num_bytes = self.write_to_fd(self._write_buffer.peek(size))
  File "/vortexfs1/home/anthony.meza/mambaforge/envs/atm_rivers/lib/python3.10/site-packages/tornado/iostream.py", line 1124, in write_to_fd
    return self.socket.send(data)  # type: ignore
BrokenPipeError: [Errno 32] Broken pipe

The above exception was the direct cause of the following exception:

Traceback (most recent call last):
  File "/vortexfs1/home/anthony.meza/mambaforge/envs/atm_rivers/lib/python3.10/site-packages/distributed/core.py", line 831, in _handle_comm
    result = await result
  File "/vortexfs1/home/anthony.meza/mambaforge/envs/atm_rivers/lib/python3.10/site-packages/distributed/core.py", line 990, in wrapper
    return await func(self, *args, **kwargs)
  File "/vortexfs1/home/anthony.meza/mambaforge/envs/atm_rivers/lib/python3.10/site-packages/distributed/worker.py", line 1783, in get_data
    response = await comm.read(deserializers=serializers)
  File "/vortexfs1/home/anthony.meza/mambaforge/envs/atm_rivers/lib/python3.10/site-packages/distributed/comm/tcp.py", line 241, in read
    convert_stream_closed_error(self, e)
  File "/vortexfs1/home/anthony.meza/mambaforge/envs/atm_rivers/lib/python3.10/site-packages/distributed/comm/tcp.py", line 142, in convert_stream_closed_error
    raise CommClosedError(f"in {obj}: {exc.__class__.__name__}: {exc}") from exc
distributed.comm.core.CommClosedError: in <TCP (closed)  local=tcp://172.16.3.88:33948 remote=tcp://172.16.3.62:36353>: BrokenPipeError: [Errno 32] Broken pipe
2023-05-03 09:31:07,782 - distributed.core - INFO - Event loop was unresponsive in Worker for 25.15s.  This is often caused by long-running GIL-holding functions or moving large chunks of data. This can cause timeouts and instability.
2023-05-03 09:31:08,054 - distributed.worker - ERROR - Worker stream died during communication: tcp://172.16.3.62:35035
Traceback (most recent call last):
  File "/vortexfs1/home/anthony.meza/mambaforge/envs/atm_rivers/lib/python3.10/site-packages/distributed/comm/tcp.py", line 235, in read
    n = await stream.read_into(chunk)
tornado.iostream.StreamClosedError: Stream is closed

The above exception was the direct cause of the following exception:

Traceback (most recent call last):
  File "/vortexfs1/home/anthony.meza/mambaforge/envs/atm_rivers/lib/python3.10/site-packages/distributed/worker.py", line 2056, in gather_dep
    response = await get_data_from_worker(
  File "/vortexfs1/home/anthony.meza/mambaforge/envs/atm_rivers/lib/python3.10/site-packages/distributed/worker.py", line 2891, in get_data_from_worker
    response = await send_recv(
  File "/vortexfs1/home/anthony.meza/mambaforge/envs/atm_rivers/lib/python3.10/site-packages/distributed/core.py", line 1027, in send_recv
    response = await comm.read(deserializers=deserializers)
  File "/vortexfs1/home/anthony.meza/mambaforge/envs/atm_rivers/lib/python3.10/site-packages/distributed/comm/tcp.py", line 241, in read
    convert_stream_closed_error(self, e)
  File "/vortexfs1/home/anthony.meza/mambaforge/envs/atm_rivers/lib/python3.10/site-packages/distributed/comm/tcp.py", line 144, in convert_stream_closed_error
    raise CommClosedError(f"in {obj}: {exc}") from exc
distributed.comm.core.CommClosedError: in <TCP (closed) Ephemeral Worker->Worker for gather local=tcp://172.16.3.88:51746 remote=tcp://172.16.3.62:35035>: Stream is closed
2023-05-03 09:31:10,866 - distributed.utils_perf - WARNING - full garbage collections took 31% CPU time recently (threshold: 10%)
2023-05-03 09:31:13,245 - distributed.core - INFO - Removing comms to tcp://172.16.3.62:35035
2023-05-03 09:31:14,582 - distributed.worker - ERROR - Worker stream died during communication: tcp://172.16.3.62:35035
ConnectionRefusedError: [Errno 111] Connection refused

The above exception was the direct cause of the following exception:

Traceback (most recent call last):
  File "/vortexfs1/home/anthony.meza/mambaforge/envs/atm_rivers/lib/python3.10/site-packages/distributed/comm/core.py", line 292, in connect
    comm = await wait_for(
  File "/vortexfs1/home/anthony.meza/mambaforge/envs/atm_rivers/lib/python3.10/site-packages/distributed/utils.py", line 1850, in wait_for
    return await asyncio.wait_for(fut, timeout)
  File "/vortexfs1/home/anthony.meza/mambaforge/envs/atm_rivers/lib/python3.10/asyncio/tasks.py", line 445, in wait_for
    return fut.result()
  File "/vortexfs1/home/anthony.meza/mambaforge/envs/atm_rivers/lib/python3.10/site-packages/distributed/comm/tcp.py", line 511, in connect
    convert_stream_closed_error(self, e)
  File "/vortexfs1/home/anthony.meza/mambaforge/envs/atm_rivers/lib/python3.10/site-packages/distributed/comm/tcp.py", line 142, in convert_stream_closed_error
    raise CommClosedError(f"in {obj}: {exc.__class__.__name__}: {exc}") from exc
distributed.comm.core.CommClosedError: in <distributed.comm.tcp.TCPConnector object at 0x2aab60bb7be0>: ConnectionRefusedError: [Errno 111] Connection refused

During handling of the above exception, another exception occurred:

Traceback (most recent call last):
  File "/vortexfs1/home/anthony.meza/mambaforge/envs/atm_rivers/lib/python3.10/site-packages/distributed/core.py", line 1430, in _connect
    comm = await connect(
  File "/vortexfs1/home/anthony.meza/mambaforge/envs/atm_rivers/lib/python3.10/site-packages/distributed/comm/core.py", line 316, in connect
    await asyncio.sleep(backoff)
  File "/vortexfs1/home/anthony.meza/mambaforge/envs/atm_rivers/lib/python3.10/asyncio/tasks.py", line 605, in sleep
    return await future
asyncio.exceptions.CancelledError

During handling of the above exception, another exception occurred:

Traceback (most recent call last):
  File "/vortexfs1/home/anthony.meza/mambaforge/envs/atm_rivers/lib/python3.10/site-packages/distributed/worker.py", line 2056, in gather_dep
    response = await get_data_from_worker(
  File "/vortexfs1/home/anthony.meza/mambaforge/envs/atm_rivers/lib/python3.10/site-packages/distributed/worker.py", line 2888, in get_data_from_worker
    comm = await rpc.connect(worker)
  File "/vortexfs1/home/anthony.meza/mambaforge/envs/atm_rivers/lib/python3.10/site-packages/distributed/core.py", line 1509, in connect
    return await connect_attempt
  File "/vortexfs1/home/anthony.meza/mambaforge/envs/atm_rivers/lib/python3.10/site-packages/distributed/core.py", line 1453, in _connect
    raise CommClosedError(reason)
distributed.comm.core.CommClosedError: Address removed.
2023-05-03 09:31:17,774 - distributed.utils_perf - WARNING - full garbage collections took 31% CPU time recently (threshold: 10%)
2023-05-03 09:31:38,072 - distributed.utils_perf - WARNING - full garbage collections took 31% CPU time recently (threshold: 10%)
2023-05-03 09:31:40,221 - distributed.utils_perf - WARNING - full garbage collections took 31% CPU time recently (threshold: 10%)
2023-05-03 09:31:47,431 - distributed.utils_perf - WARNING - full garbage collections took 31% CPU time recently (threshold: 10%)
2023-05-03 09:31:54,654 - distributed.utils_perf - WARNING - full garbage collections took 31% CPU time recently (threshold: 10%)
2023-05-03 09:31:54,743 - distributed.worker - ERROR - failed during get data with tcp://172.16.3.88:33948 -> tcp://172.16.3.105:44979
Traceback (most recent call last):
  File "/vortexfs1/home/anthony.meza/mambaforge/envs/atm_rivers/lib/python3.10/site-packages/tornado/iostream.py", line 861, in _read_to_buffer
    bytes_read = self.read_from_fd(buf)
  File "/vortexfs1/home/anthony.meza/mambaforge/envs/atm_rivers/lib/python3.10/site-packages/tornado/iostream.py", line 1116, in read_from_fd
    return self.socket.recv_into(buf, len(buf))
TimeoutError: [Errno 110] Connection timed out

The above exception was the direct cause of the following exception:

Traceback (most recent call last):
  File "/vortexfs1/home/anthony.meza/mambaforge/envs/atm_rivers/lib/python3.10/site-packages/distributed/worker.py", line 1783, in get_data
    response = await comm.read(deserializers=serializers)
  File "/vortexfs1/home/anthony.meza/mambaforge/envs/atm_rivers/lib/python3.10/site-packages/distributed/comm/tcp.py", line 241, in read
    convert_stream_closed_error(self, e)
  File "/vortexfs1/home/anthony.meza/mambaforge/envs/atm_rivers/lib/python3.10/site-packages/distributed/comm/tcp.py", line 142, in convert_stream_closed_error
    raise CommClosedError(f"in {obj}: {exc.__class__.__name__}: {exc}") from exc
distributed.comm.core.CommClosedError: in <TCP (closed)  local=tcp://172.16.3.88:33948 remote=tcp://172.16.3.105:41903>: TimeoutError: [Errno 110] Connection timed out
2023-05-03 09:31:54,743 - distributed.core - INFO - Lost connection to 'tcp://172.16.3.105:41903'
Traceback (most recent call last):
  File "/vortexfs1/home/anthony.meza/mambaforge/envs/atm_rivers/lib/python3.10/site-packages/tornado/iostream.py", line 861, in _read_to_buffer
    bytes_read = self.read_from_fd(buf)
  File "/vortexfs1/home/anthony.meza/mambaforge/envs/atm_rivers/lib/python3.10/site-packages/tornado/iostream.py", line 1116, in read_from_fd
    return self.socket.recv_into(buf, len(buf))
TimeoutError: [Errno 110] Connection timed out

The above exception was the direct cause of the following exception:

Traceback (most recent call last):
  File "/vortexfs1/home/anthony.meza/mambaforge/envs/atm_rivers/lib/python3.10/site-packages/distributed/core.py", line 831, in _handle_comm
    result = await result
  File "/vortexfs1/home/anthony.meza/mambaforge/envs/atm_rivers/lib/python3.10/site-packages/distributed/core.py", line 990, in wrapper
    return await func(self, *args, **kwargs)
  File "/vortexfs1/home/anthony.meza/mambaforge/envs/atm_rivers/lib/python3.10/site-packages/distributed/worker.py", line 1783, in get_data
    response = await comm.read(deserializers=serializers)
  File "/vortexfs1/home/anthony.meza/mambaforge/envs/atm_rivers/lib/python3.10/site-packages/distributed/comm/tcp.py", line 241, in read
    convert_stream_closed_error(self, e)
  File "/vortexfs1/home/anthony.meza/mambaforge/envs/atm_rivers/lib/python3.10/site-packages/distributed/comm/tcp.py", line 142, in convert_stream_closed_error
    raise CommClosedError(f"in {obj}: {exc.__class__.__name__}: {exc}") from exc
distributed.comm.core.CommClosedError: in <TCP (closed)  local=tcp://172.16.3.88:33948 remote=tcp://172.16.3.105:41903>: TimeoutError: [Errno 110] Connection timed out
2023-05-03 09:32:18,862 - distributed.utils_perf - WARNING - full garbage collections took 31% CPU time recently (threshold: 10%)
2023-05-03 09:32:33,295 - distributed.utils_perf - WARNING - full garbage collections took 31% CPU time recently (threshold: 10%)
2023-05-03 09:32:36,444 - distributed.utils_perf - WARNING - full garbage collections took 31% CPU time recently (threshold: 10%)
2023-05-03 09:33:19,825 - distributed.core - INFO - Removing comms to tcp://172.16.3.105:44979
2023-05-03 09:33:19,874 - distributed.worker - ERROR - Worker stream died during communication: tcp://172.16.3.105:44979
Traceback (most recent call last):
  File "/vortexfs1/home/anthony.meza/mambaforge/envs/atm_rivers/lib/python3.10/site-packages/distributed/comm/tcp.py", line 235, in read
    n = await stream.read_into(chunk)
tornado.iostream.StreamClosedError: Stream is closed

The above exception was the direct cause of the following exception:

Traceback (most recent call last):
  File "/vortexfs1/home/anthony.meza/mambaforge/envs/atm_rivers/lib/python3.10/site-packages/distributed/worker.py", line 2056, in gather_dep
    response = await get_data_from_worker(
  File "/vortexfs1/home/anthony.meza/mambaforge/envs/atm_rivers/lib/python3.10/site-packages/distributed/worker.py", line 2891, in get_data_from_worker
    response = await send_recv(
  File "/vortexfs1/home/anthony.meza/mambaforge/envs/atm_rivers/lib/python3.10/site-packages/distributed/core.py", line 1027, in send_recv
    response = await comm.read(deserializers=deserializers)
  File "/vortexfs1/home/anthony.meza/mambaforge/envs/atm_rivers/lib/python3.10/site-packages/distributed/comm/tcp.py", line 241, in read
    convert_stream_closed_error(self, e)
  File "/vortexfs1/home/anthony.meza/mambaforge/envs/atm_rivers/lib/python3.10/site-packages/distributed/comm/tcp.py", line 144, in convert_stream_closed_error
    raise CommClosedError(f"in {obj}: {exc}") from exc
distributed.comm.core.CommClosedError: in <TCP (closed) Ephemeral Worker->Worker for gather local=tcp://172.16.3.88:55089 remote=tcp://172.16.3.105:44979>: Stream is closed
2023-05-03 09:33:25,121 - distributed.utils_perf - WARNING - full garbage collections took 31% CPU time recently (threshold: 10%)
2023-05-03 09:33:29,275 - distributed.utils_perf - WARNING - full garbage collections took 31% CPU time recently (threshold: 10%)
2023-05-03 09:33:38,760 - distributed.utils_perf - WARNING - full garbage collections took 31% CPU time recently (threshold: 10%)
2023-05-03 09:34:22,497 - distributed.utils_perf - WARNING - full garbage collections took 30% CPU time recently (threshold: 10%)
2023-05-03 09:35:25,917 - distributed.worker - ERROR - Failed to communicate with scheduler during heartbeat.
Traceback (most recent call last):
  File "/vortexfs1/home/anthony.meza/mambaforge/envs/atm_rivers/lib/python3.10/site-packages/tornado/iostream.py", line 861, in _read_to_buffer
    bytes_read = self.read_from_fd(buf)
  File "/vortexfs1/home/anthony.meza/mambaforge/envs/atm_rivers/lib/python3.10/site-packages/tornado/iostream.py", line 1116, in read_from_fd
    return self.socket.recv_into(buf, len(buf))
ConnectionResetError: [Errno 104] Connection reset by peer

The above exception was the direct cause of the following exception:

Traceback (most recent call last):
  File "/vortexfs1/home/anthony.meza/mambaforge/envs/atm_rivers/lib/python3.10/site-packages/distributed/worker.py", line 1234, in heartbeat
    response = await retry_operation(
  File "/vortexfs1/home/anthony.meza/mambaforge/envs/atm_rivers/lib/python3.10/site-packages/distributed/utils_comm.py", line 434, in retry_operation
    return await retry(
  File "/vortexfs1/home/anthony.meza/mambaforge/envs/atm_rivers/lib/python3.10/site-packages/distributed/utils_comm.py", line 413, in retry
    return await coro()
  File "/vortexfs1/home/anthony.meza/mambaforge/envs/atm_rivers/lib/python3.10/site-packages/distributed/core.py", line 1268, in send_recv_from_rpc
    return await send_recv(comm=comm, op=key, **kwargs)
  File "/vortexfs1/home/anthony.meza/mambaforge/envs/atm_rivers/lib/python3.10/site-packages/distributed/core.py", line 1027, in send_recv
    response = await comm.read(deserializers=deserializers)
  File "/vortexfs1/home/anthony.meza/mambaforge/envs/atm_rivers/lib/python3.10/site-packages/distributed/comm/tcp.py", line 241, in read
    convert_stream_closed_error(self, e)
  File "/vortexfs1/home/anthony.meza/mambaforge/envs/atm_rivers/lib/python3.10/site-packages/distributed/comm/tcp.py", line 142, in convert_stream_closed_error
    raise CommClosedError(f"in {obj}: {exc.__class__.__name__}: {exc}") from exc
distributed.comm.core.CommClosedError: in <TCP (closed) ConnectionPool.heartbeat_worker local=tcp://172.16.3.88:47144 remote=tcp://172.16.3.158:44759>: ConnectionResetError: [Errno 104] Connection reset by peer
2023-05-03 09:35:25,918 - distributed.core - INFO - Connection to tcp://172.16.3.158:44759 has been closed.
2023-05-03 09:35:25,918 - distributed.worker - INFO - Stopping worker at tcp://172.16.3.88:33948. Reason: worker-handle-scheduler-connection-broken
2023-05-03 09:35:25,922 - distributed.worker - ERROR - failed during get data with tcp://172.16.3.88:33948 -> tcp://172.16.3.93:41353
Traceback (most recent call last):
  File "/vortexfs1/home/anthony.meza/mambaforge/envs/atm_rivers/lib/python3.10/site-packages/distributed/comm/tcp.py", line 225, in read
    frames_nbytes = await stream.read_bytes(fmt_size)
tornado.iostream.StreamClosedError: Stream is closed

The above exception was the direct cause of the following exception:

Traceback (most recent call last):
  File "/vortexfs1/home/anthony.meza/mambaforge/envs/atm_rivers/lib/python3.10/site-packages/distributed/worker.py", line 1783, in get_data
    response = await comm.read(deserializers=serializers)
  File "/vortexfs1/home/anthony.meza/mambaforge/envs/atm_rivers/lib/python3.10/site-packages/distributed/comm/tcp.py", line 241, in read
    convert_stream_closed_error(self, e)
  File "/vortexfs1/home/anthony.meza/mambaforge/envs/atm_rivers/lib/python3.10/site-packages/distributed/comm/tcp.py", line 144, in convert_stream_closed_error
    raise CommClosedError(f"in {obj}: {exc}") from exc
distributed.comm.core.CommClosedError: in <TCP (closed)  local=tcp://172.16.3.88:33948 remote=tcp://172.16.3.93:36100>: Stream is closed
2023-05-03 09:35:25,924 - distributed.nanny - INFO - Closing Nanny gracefully at 'tcp://172.16.3.88:46392'. Reason: worker-handle-scheduler-connection-broken
2023-05-03 09:35:26,847 - distributed.worker - ERROR - failed during get data with tcp://172.16.3.88:33948 -> tcp://172.16.3.167:38996
Traceback (most recent call last):
  File "/vortexfs1/home/anthony.meza/mambaforge/envs/atm_rivers/lib/python3.10/site-packages/distributed/comm/tcp.py", line 317, in write
    raise StreamClosedError()
tornado.iostream.StreamClosedError: Stream is closed

The above exception was the direct cause of the following exception:

Traceback (most recent call last):
  File "/vortexfs1/home/anthony.meza/mambaforge/envs/atm_rivers/lib/python3.10/site-packages/distributed/worker.py", line 1782, in get_data
    compressed = await comm.write(msg, serializers=serializers)
  File "/vortexfs1/home/anthony.meza/mambaforge/envs/atm_rivers/lib/python3.10/site-packages/distributed/comm/tcp.py", line 328, in write
    convert_stream_closed_error(self, e)
  File "/vortexfs1/home/anthony.meza/mambaforge/envs/atm_rivers/lib/python3.10/site-packages/distributed/comm/tcp.py", line 144, in convert_stream_closed_error
    raise CommClosedError(f"in {obj}: {exc}") from exc
distributed.comm.core.CommClosedError: in <TCP (closed)  local=tcp://172.16.3.88:33948 remote=tcp://172.16.3.167:46498>: Stream is closed
2023-05-03 09:35:26,895 - distributed.worker - ERROR - failed during get data with tcp://172.16.3.88:33948 -> tcp://172.16.3.61:35519
Traceback (most recent call last):
  File "/vortexfs1/home/anthony.meza/mambaforge/envs/atm_rivers/lib/python3.10/site-packages/distributed/comm/tcp.py", line 317, in write
    raise StreamClosedError()
tornado.iostream.StreamClosedError: Stream is closed

The above exception was the direct cause of the following exception:

Traceback (most recent call last):
  File "/vortexfs1/home/anthony.meza/mambaforge/envs/atm_rivers/lib/python3.10/site-packages/distributed/worker.py", line 1782, in get_data
    compressed = await comm.write(msg, serializers=serializers)
  File "/vortexfs1/home/anthony.meza/mambaforge/envs/atm_rivers/lib/python3.10/site-packages/distributed/comm/tcp.py", line 328, in write
    convert_stream_closed_error(self, e)
  File "/vortexfs1/home/anthony.meza/mambaforge/envs/atm_rivers/lib/python3.10/site-packages/distributed/comm/tcp.py", line 144, in convert_stream_closed_error
    raise CommClosedError(f"in {obj}: {exc}") from exc
distributed.comm.core.CommClosedError: in <TCP (closed)  local=tcp://172.16.3.88:33948 remote=tcp://172.16.3.61:51279>: Stream is closed
2023-05-03 09:35:27,173 - distributed.worker - ERROR - failed during get data with tcp://172.16.3.88:33948 -> tcp://172.16.3.168:39334
Traceback (most recent call last):
  File "/vortexfs1/home/anthony.meza/mambaforge/envs/atm_rivers/lib/python3.10/site-packages/tornado/iostream.py", line 962, in _handle_write
    num_bytes = self.write_to_fd(self._write_buffer.peek(size))
  File "/vortexfs1/home/anthony.meza/mambaforge/envs/atm_rivers/lib/python3.10/site-packages/tornado/iostream.py", line 1124, in write_to_fd
    return self.socket.send(data)  # type: ignore
BrokenPipeError: [Errno 32] Broken pipe

The above exception was the direct cause of the following exception:

Traceback (most recent call last):
  File "/vortexfs1/home/anthony.meza/mambaforge/envs/atm_rivers/lib/python3.10/site-packages/distributed/worker.py", line 1783, in get_data
    response = await comm.read(deserializers=serializers)
  File "/vortexfs1/home/anthony.meza/mambaforge/envs/atm_rivers/lib/python3.10/site-packages/distributed/comm/tcp.py", line 241, in read
    convert_stream_closed_error(self, e)
  File "/vortexfs1/home/anthony.meza/mambaforge/envs/atm_rivers/lib/python3.10/site-packages/distributed/comm/tcp.py", line 142, in convert_stream_closed_error
    raise CommClosedError(f"in {obj}: {exc.__class__.__name__}: {exc}") from exc
distributed.comm.core.CommClosedError: in <TCP (closed)  local=tcp://172.16.3.88:33948 remote=tcp://172.16.3.168:34997>: BrokenPipeError: [Errno 32] Broken pipe
2023-05-03 09:35:27,457 - distributed.worker - ERROR - failed during get data with tcp://172.16.3.88:33948 -> tcp://172.16.3.169:39906
Traceback (most recent call last):
  File "/vortexfs1/home/anthony.meza/mambaforge/envs/atm_rivers/lib/python3.10/site-packages/distributed/comm/tcp.py", line 317, in write
    raise StreamClosedError()
tornado.iostream.StreamClosedError: Stream is closed

The above exception was the direct cause of the following exception:

Traceback (most recent call last):
  File "/vortexfs1/home/anthony.meza/mambaforge/envs/atm_rivers/lib/python3.10/site-packages/distributed/worker.py", line 1782, in get_data
    compressed = await comm.write(msg, serializers=serializers)
  File "/vortexfs1/home/anthony.meza/mambaforge/envs/atm_rivers/lib/python3.10/site-packages/distributed/comm/tcp.py", line 328, in write
    convert_stream_closed_error(self, e)
  File "/vortexfs1/home/anthony.meza/mambaforge/envs/atm_rivers/lib/python3.10/site-packages/distributed/comm/tcp.py", line 144, in convert_stream_closed_error
    raise CommClosedError(f"in {obj}: {exc}") from exc
distributed.comm.core.CommClosedError: in <TCP (closed)  local=tcp://172.16.3.88:33948 remote=tcp://172.16.3.169:35286>: Stream is closed
2023-05-03 09:35:28,938 - distributed.client - ERROR - 
ConnectionRefusedError: [Errno 111] Connection refused

The above exception was the direct cause of the following exception:

Traceback (most recent call last):
  File "/vortexfs1/home/anthony.meza/mambaforge/envs/atm_rivers/lib/python3.10/site-packages/distributed/comm/core.py", line 292, in connect
    comm = await wait_for(
  File "/vortexfs1/home/anthony.meza/mambaforge/envs/atm_rivers/lib/python3.10/site-packages/distributed/utils.py", line 1850, in wait_for
    return await asyncio.wait_for(fut, timeout)
  File "/vortexfs1/home/anthony.meza/mambaforge/envs/atm_rivers/lib/python3.10/asyncio/tasks.py", line 445, in wait_for
    return fut.result()
  File "/vortexfs1/home/anthony.meza/mambaforge/envs/atm_rivers/lib/python3.10/site-packages/distributed/comm/tcp.py", line 511, in connect
    convert_stream_closed_error(self, e)
  File "/vortexfs1/home/anthony.meza/mambaforge/envs/atm_rivers/lib/python3.10/site-packages/distributed/comm/tcp.py", line 142, in convert_stream_closed_error
    raise CommClosedError(f"in {obj}: {exc.__class__.__name__}: {exc}") from exc
distributed.comm.core.CommClosedError: in <distributed.comm.tcp.TCPConnector object at 0x2aab6783ca30>: ConnectionRefusedError: [Errno 111] Connection refused

During handling of the above exception, another exception occurred:

Traceback (most recent call last):
  File "/vortexfs1/home/anthony.meza/mambaforge/envs/atm_rivers/lib/python3.10/site-packages/distributed/utils.py", line 752, in wrapper
    return await func(*args, **kwargs)
  File "/vortexfs1/home/anthony.meza/mambaforge/envs/atm_rivers/lib/python3.10/site-packages/distributed/client.py", line 1321, in _reconnect
    await self._ensure_connected(timeout=timeout)
  File "/vortexfs1/home/anthony.meza/mambaforge/envs/atm_rivers/lib/python3.10/site-packages/distributed/client.py", line 1351, in _ensure_connected
    comm = await connect(
  File "/vortexfs1/home/anthony.meza/mambaforge/envs/atm_rivers/lib/python3.10/site-packages/distributed/comm/core.py", line 316, in connect
    await asyncio.sleep(backoff)
  File "/vortexfs1/home/anthony.meza/mambaforge/envs/atm_rivers/lib/python3.10/asyncio/tasks.py", line 605, in sleep
    return await future
asyncio.exceptions.CancelledError
2023-05-03 09:35:29,604 - distributed.nanny - INFO - Worker closed
2023-05-03 09:35:31,608 - distributed.nanny - ERROR - Worker process died unexpectedly
2023-05-03 09:35:42,686 - distributed.nanny - INFO - Closing Nanny at 'tcp://172.16.3.88:46392'. Reason: nanny-close-gracefully
2023-05-03 09:35:42,687 - distributed.dask_worker - INFO - End worker
