2023-04-17 10:01:22,894 - distributed.nanny - INFO -         Start Nanny at: 'tcp://172.16.3.94:37968'
2023-04-17 10:01:41,925 - distributed.worker - INFO -       Start worker at:    tcp://172.16.3.94:37384
2023-04-17 10:01:41,926 - distributed.worker - INFO -          Listening to:    tcp://172.16.3.94:37384
2023-04-17 10:01:41,926 - distributed.worker - INFO -           Worker name:             SLURMCluster-3
2023-04-17 10:01:41,926 - distributed.worker - INFO -          dashboard at:          172.16.3.94:35734
2023-04-17 10:01:41,926 - distributed.worker - INFO - Waiting to connect to:   tcp://172.16.3.167:41730
2023-04-17 10:01:41,926 - distributed.worker - INFO - -------------------------------------------------
2023-04-17 10:01:41,926 - distributed.worker - INFO -               Threads:                         36
2023-04-17 10:01:41,926 - distributed.worker - INFO -                Memory:                 178.81 GiB
2023-04-17 10:01:41,926 - distributed.worker - INFO -       Local Directory: /tmp/dask-worker-space/worker-5quks7vb
2023-04-17 10:01:41,926 - distributed.worker - INFO - -------------------------------------------------
2023-04-17 10:01:41,940 - distributed.worker - INFO -         Registered to:   tcp://172.16.3.167:41730
2023-04-17 10:01:41,941 - distributed.worker - INFO - -------------------------------------------------
2023-04-17 10:01:41,941 - distributed.core - INFO - Starting established connection to tcp://172.16.3.167:41730
2023-04-17 10:01:56,878 - distributed.core - INFO - Event loop was unresponsive in Worker for 3.50s.  This is often caused by long-running GIL-holding functions or moving large chunks of data. This can cause timeouts and instability.
/vortexfs1/home/anthony.meza/.conda/envs/notebook_env/lib/python3.10/site-packages/xarray/core/common.py:965: FutureWarning: 'base' in .resample() and in Grouper() is deprecated.
The new arguments that you should use are 'offset' or 'origin'.

>>> df.resample(freq="3s", base=2)

becomes:

>>> df.resample(freq="3s", offset="2s")

  grouper = pd.Grouper(
2023-04-17 10:03:11,790 - distributed.worker - ERROR - Failed to communicate with scheduler during heartbeat.
Traceback (most recent call last):
  File "/vortexfs1/home/anthony.meza/.conda/envs/notebook_env/lib/python3.10/site-packages/tornado/iostream.py", line 867, in _read_to_buffer
    bytes_read = self.read_from_fd(buf)
  File "/vortexfs1/home/anthony.meza/.conda/envs/notebook_env/lib/python3.10/site-packages/tornado/iostream.py", line 1140, in read_from_fd
    return self.socket.recv_into(buf, len(buf))
ConnectionResetError: [Errno 104] Connection reset by peer

The above exception was the direct cause of the following exception:

Traceback (most recent call last):
  File "/vortexfs1/home/anthony.meza/.conda/envs/notebook_env/lib/python3.10/site-packages/distributed/worker.py", line 1215, in heartbeat
    response = await retry_operation(
  File "/vortexfs1/home/anthony.meza/.conda/envs/notebook_env/lib/python3.10/site-packages/distributed/utils_comm.py", line 386, in retry_operation
    return await retry(
  File "/vortexfs1/home/anthony.meza/.conda/envs/notebook_env/lib/python3.10/site-packages/distributed/utils_comm.py", line 371, in retry
    return await coro()
  File "/vortexfs1/home/anthony.meza/.conda/envs/notebook_env/lib/python3.10/site-packages/distributed/core.py", line 1163, in send_recv_from_rpc
    return await send_recv(comm=comm, op=key, **kwargs)
  File "/vortexfs1/home/anthony.meza/.conda/envs/notebook_env/lib/python3.10/site-packages/distributed/core.py", line 928, in send_recv
    response = await comm.read(deserializers=deserializers)
  File "/vortexfs1/home/anthony.meza/.conda/envs/notebook_env/lib/python3.10/site-packages/distributed/comm/tcp.py", line 241, in read
    convert_stream_closed_error(self, e)
  File "/vortexfs1/home/anthony.meza/.conda/envs/notebook_env/lib/python3.10/site-packages/distributed/comm/tcp.py", line 142, in convert_stream_closed_error
    raise CommClosedError(f"in {obj}: {exc.__class__.__name__}: {exc}") from exc
distributed.comm.core.CommClosedError: in <TCP (closed) ConnectionPool.heartbeat_worker local=tcp://172.16.3.94:42724 remote=tcp://172.16.3.167:41730>: ConnectionResetError: [Errno 104] Connection reset by peer
2023-04-17 10:03:11,796 - distributed.core - INFO - Connection to tcp://172.16.3.167:41730 has been closed.
2023-04-17 10:03:11,797 - distributed.worker - INFO - Stopping worker at tcp://172.16.3.94:37384. Reason: worker-handle-scheduler-connection-broken
2023-04-17 10:03:11,801 - distributed.nanny - INFO - Closing Nanny gracefully at 'tcp://172.16.3.94:37968'. Reason: worker-handle-scheduler-connection-broken
2023-04-17 10:03:32,940 - distributed.nanny - INFO - Worker closed
2023-04-17 10:03:35,241 - distributed.nanny - INFO - Closing Nanny at 'tcp://172.16.3.94:37968'. Reason: nanny-close-gracefully
2023-04-17 10:03:35,241 - distributed.dask_worker - INFO - End worker
