2023-05-03 09:10:25,839 - distributed.nanny - INFO -         Start Nanny at: 'tcp://172.16.3.90:43326'
2023-05-03 09:10:28,441 - distributed.worker - INFO -       Start worker at:    tcp://172.16.3.90:45393
2023-05-03 09:10:28,441 - distributed.worker - INFO -          Listening to:    tcp://172.16.3.90:45393
2023-05-03 09:10:28,441 - distributed.worker - INFO -           Worker name:             SLURMCluster-7
2023-05-03 09:10:28,441 - distributed.worker - INFO -          dashboard at:          172.16.3.90:39561
2023-05-03 09:10:28,441 - distributed.worker - INFO - Waiting to connect to:   tcp://172.16.3.158:34390
2023-05-03 09:10:28,441 - distributed.worker - INFO - -------------------------------------------------
2023-05-03 09:10:28,441 - distributed.worker - INFO -               Threads:                         36
2023-05-03 09:10:28,441 - distributed.worker - INFO -                Memory:                  93.13 GiB
2023-05-03 09:10:28,441 - distributed.worker - INFO -       Local Directory: /tmp/dask-worker-space/worker-60rjx2jv
2023-05-03 09:10:28,441 - distributed.worker - INFO - -------------------------------------------------
2023-05-03 09:10:28,446 - distributed.worker - INFO -         Registered to:   tcp://172.16.3.158:34390
2023-05-03 09:10:28,446 - distributed.worker - INFO - -------------------------------------------------
2023-05-03 09:10:28,447 - distributed.core - INFO - Starting established connection to tcp://172.16.3.158:34390
2023-05-03 09:13:10,071 - distributed.utils_perf - INFO - full garbage collection released 4.17 GiB from 520 reference cycles (threshold: 9.54 MiB)
2023-05-03 09:13:14,113 - distributed.utils_perf - INFO - full garbage collection released 902.06 MiB from 319 reference cycles (threshold: 9.54 MiB)
2023-05-03 09:13:23,411 - distributed.utils_perf - INFO - full garbage collection released 1.09 GiB from 640 reference cycles (threshold: 9.54 MiB)
2023-05-03 09:13:28,602 - distributed.core - INFO - Removing comms to tcp://172.16.3.105:34566
2023-05-03 09:13:29,126 - distributed.worker - ERROR - Worker stream died during communication: tcp://172.16.3.105:34566
Traceback (most recent call last):
  File "/vortexfs1/home/anthony.meza/mambaforge/envs/atm_rivers/lib/python3.10/site-packages/distributed/comm/tcp.py", line 235, in read
    n = await stream.read_into(chunk)
tornado.iostream.StreamClosedError: Stream is closed

The above exception was the direct cause of the following exception:

Traceback (most recent call last):
  File "/vortexfs1/home/anthony.meza/mambaforge/envs/atm_rivers/lib/python3.10/site-packages/distributed/worker.py", line 2056, in gather_dep
    response = await get_data_from_worker(
  File "/vortexfs1/home/anthony.meza/mambaforge/envs/atm_rivers/lib/python3.10/site-packages/distributed/worker.py", line 2891, in get_data_from_worker
    response = await send_recv(
  File "/vortexfs1/home/anthony.meza/mambaforge/envs/atm_rivers/lib/python3.10/site-packages/distributed/core.py", line 1027, in send_recv
    response = await comm.read(deserializers=deserializers)
  File "/vortexfs1/home/anthony.meza/mambaforge/envs/atm_rivers/lib/python3.10/site-packages/distributed/comm/tcp.py", line 241, in read
    convert_stream_closed_error(self, e)
  File "/vortexfs1/home/anthony.meza/mambaforge/envs/atm_rivers/lib/python3.10/site-packages/distributed/comm/tcp.py", line 144, in convert_stream_closed_error
    raise CommClosedError(f"in {obj}: {exc}") from exc
distributed.comm.core.CommClosedError: in <TCP (closed) Ephemeral Worker->Worker for gather local=tcp://172.16.3.90:57865 remote=tcp://172.16.3.105:34566>: Stream is closed
2023-05-03 09:13:48,683 - distributed.worker.memory - WARNING - Worker is at 84% memory usage. Pausing worker.  Process memory: 78.36 GiB -- Worker memory limit: 93.13 GiB
2023-05-03 09:13:48,684 - distributed.core - INFO - Event loop was unresponsive in Worker for 14.77s.  This is often caused by long-running GIL-holding functions or moving large chunks of data. This can cause timeouts and instability.
2023-05-03 09:13:55,563 - distributed.nanny.memory - WARNING - Worker tcp://172.16.3.90:45393 (pid=187862) exceeded 95% memory budget. Restarting...
2023-05-03 09:13:57,913 - distributed.nanny - INFO - Worker process 187862 was killed by signal 15
2023-05-03 09:13:59,162 - distributed.nanny - WARNING - Restarting worker
2023-05-03 09:14:02,513 - distributed.worker - INFO -       Start worker at:    tcp://172.16.3.90:33314
2023-05-03 09:14:02,514 - distributed.worker - INFO -          Listening to:    tcp://172.16.3.90:33314
2023-05-03 09:14:02,514 - distributed.worker - INFO -           Worker name:             SLURMCluster-7
2023-05-03 09:14:02,514 - distributed.worker - INFO -          dashboard at:          172.16.3.90:33574
2023-05-03 09:14:02,514 - distributed.worker - INFO - Waiting to connect to:   tcp://172.16.3.158:34390
2023-05-03 09:14:02,514 - distributed.worker - INFO - -------------------------------------------------
2023-05-03 09:14:02,514 - distributed.worker - INFO -               Threads:                         36
2023-05-03 09:14:02,514 - distributed.worker - INFO -                Memory:                  93.13 GiB
2023-05-03 09:14:02,514 - distributed.worker - INFO -       Local Directory: /tmp/dask-worker-space/worker-q7udw_zz
2023-05-03 09:14:02,514 - distributed.worker - INFO - -------------------------------------------------
2023-05-03 09:14:32,515 - distributed.worker - INFO - Waiting to connect to:   tcp://172.16.3.158:34390
2023-05-03 09:14:59,163 - distributed.nanny - ERROR - Timed out connecting Nanny '<Nanny: tcp://172.16.3.90:45393, threads: 36>' to scheduler 'tcp://172.16.3.158:34390'
2023-05-03 09:14:59,163 - distributed.nanny - INFO - Closing Nanny at 'tcp://172.16.3.90:43326'. Reason: nanny-instantiate-timeout
2023-05-03 09:15:00,782 - distributed.worker - INFO - Stopping worker at tcp://172.16.3.90:33314. Reason: worker-close
2023-05-03 09:15:00,782 - distributed.worker - INFO - Closed worker has not yet started: Status.init
2023-05-03 09:15:00,784 - distributed.nanny - ERROR - Failed to start worker
ConnectionRefusedError: [Errno 111] Connection refused

The above exception was the direct cause of the following exception:

Traceback (most recent call last):
  File "/vortexfs1/home/anthony.meza/mambaforge/envs/atm_rivers/lib/python3.10/site-packages/distributed/comm/core.py", line 292, in connect
    comm = await wait_for(
  File "/vortexfs1/home/anthony.meza/mambaforge/envs/atm_rivers/lib/python3.10/site-packages/distributed/utils.py", line 1850, in wait_for
    return await asyncio.wait_for(fut, timeout)
  File "/vortexfs1/home/anthony.meza/mambaforge/envs/atm_rivers/lib/python3.10/asyncio/tasks.py", line 445, in wait_for
    return fut.result()
  File "/vortexfs1/home/anthony.meza/mambaforge/envs/atm_rivers/lib/python3.10/site-packages/distributed/comm/tcp.py", line 511, in connect
    convert_stream_closed_error(self, e)
  File "/vortexfs1/home/anthony.meza/mambaforge/envs/atm_rivers/lib/python3.10/site-packages/distributed/comm/tcp.py", line 142, in convert_stream_closed_error
    raise CommClosedError(f"in {obj}: {exc.__class__.__name__}: {exc}") from exc
distributed.comm.core.CommClosedError: in <distributed.comm.tcp.TCPConnector object at 0x2aaacaf56fb0>: ConnectionRefusedError: [Errno 111] Connection refused

During handling of the above exception, another exception occurred:

Traceback (most recent call last):
  File "/vortexfs1/home/anthony.meza/mambaforge/envs/atm_rivers/lib/python3.10/site-packages/distributed/worker.py", line 1472, in start_unsafe
    await self._register_with_scheduler()
  File "/vortexfs1/home/anthony.meza/mambaforge/envs/atm_rivers/lib/python3.10/site-packages/distributed/worker.py", line 1163, in _register_with_scheduler
    comm = await connect(self.scheduler.address, **self.connection_args)
  File "/vortexfs1/home/anthony.meza/mambaforge/envs/atm_rivers/lib/python3.10/site-packages/distributed/comm/core.py", line 316, in connect
    await asyncio.sleep(backoff)
  File "/vortexfs1/home/anthony.meza/mambaforge/envs/atm_rivers/lib/python3.10/asyncio/tasks.py", line 605, in sleep
    return await future
asyncio.exceptions.CancelledError

During handling of the above exception, another exception occurred:

Traceback (most recent call last):
  File "/vortexfs1/home/anthony.meza/mambaforge/envs/atm_rivers/lib/python3.10/asyncio/tasks.py", line 456, in wait_for
    return fut.result()
asyncio.exceptions.CancelledError

The above exception was the direct cause of the following exception:

Traceback (most recent call last):
  File "/vortexfs1/home/anthony.meza/mambaforge/envs/atm_rivers/lib/python3.10/site-packages/distributed/core.py", line 537, in start
    await wait_for(self.start_unsafe(), timeout=timeout)
  File "/vortexfs1/home/anthony.meza/mambaforge/envs/atm_rivers/lib/python3.10/site-packages/distributed/utils.py", line 1850, in wait_for
    return await asyncio.wait_for(fut, timeout)
  File "/vortexfs1/home/anthony.meza/mambaforge/envs/atm_rivers/lib/python3.10/asyncio/tasks.py", line 458, in wait_for
    raise exceptions.TimeoutError() from exc
asyncio.exceptions.TimeoutError

The above exception was the direct cause of the following exception:

Traceback (most recent call last):
  File "/vortexfs1/home/anthony.meza/mambaforge/envs/atm_rivers/lib/python3.10/site-packages/distributed/nanny.py", line 930, in run
    async with worker:
  File "/vortexfs1/home/anthony.meza/mambaforge/envs/atm_rivers/lib/python3.10/site-packages/distributed/core.py", line 550, in __aenter__
    await self
  File "/vortexfs1/home/anthony.meza/mambaforge/envs/atm_rivers/lib/python3.10/site-packages/distributed/core.py", line 540, in start
    raise asyncio.TimeoutError(
asyncio.exceptions.TimeoutError: Worker start timed out after 60s.
slurmstepd: error: *** JOB 3082091 ON pn040 CANCELLED AT 2023-05-03T11:10:37 DUE TO TIME LIMIT ***
