2023-05-03 09:39:52,177 - distributed.nanny - INFO -         Start Nanny at: 'tcp://172.16.3.89:41645'
2023-05-03 09:39:52,550 - distributed.diskutils - INFO - Found stale lock file and directory '/tmp/dask-worker-space/worker-c834lcfn', purging
2023-05-03 09:39:52,954 - distributed.worker - INFO -       Start worker at:    tcp://172.16.3.89:41868
2023-05-03 09:39:52,955 - distributed.worker - INFO -          Listening to:    tcp://172.16.3.89:41868
2023-05-03 09:39:52,955 - distributed.worker - INFO -           Worker name:             SLURMCluster-3
2023-05-03 09:39:52,955 - distributed.worker - INFO -          dashboard at:          172.16.3.89:45518
2023-05-03 09:39:52,955 - distributed.worker - INFO - Waiting to connect to:   tcp://172.16.3.158:44343
2023-05-03 09:39:52,955 - distributed.worker - INFO - -------------------------------------------------
2023-05-03 09:39:52,955 - distributed.worker - INFO -               Threads:                         36
2023-05-03 09:39:52,955 - distributed.worker - INFO -                Memory:                 178.81 GiB
2023-05-03 09:39:52,955 - distributed.worker - INFO -       Local Directory: /tmp/dask-worker-space/worker-dthmyky9
2023-05-03 09:39:52,955 - distributed.worker - INFO - -------------------------------------------------
2023-05-03 09:39:52,959 - distributed.worker - INFO -         Registered to:   tcp://172.16.3.158:44343
2023-05-03 09:39:52,960 - distributed.worker - INFO - -------------------------------------------------
2023-05-03 09:39:52,960 - distributed.core - INFO - Starting established connection to tcp://172.16.3.158:44343
2023-05-03 09:44:48,026 - distributed.core - INFO - Event loop was unresponsive in Worker for 3.80s.  This is often caused by long-running GIL-holding functions or moving large chunks of data. This can cause timeouts and instability.
2023-05-03 09:49:33,001 - distributed.core - INFO - Connection to tcp://172.16.3.158:44343 has been closed.
2023-05-03 09:49:33,001 - distributed.worker - INFO - Stopping worker at tcp://172.16.3.89:41868. Reason: worker-handle-scheduler-connection-broken
2023-05-03 09:49:33,002 - distributed.worker - ERROR - Failed to communicate with scheduler during heartbeat.
Traceback (most recent call last):
  File "/vortexfs1/home/anthony.meza/mambaforge/envs/atm_rivers/lib/python3.10/site-packages/tornado/iostream.py", line 861, in _read_to_buffer
    bytes_read = self.read_from_fd(buf)
  File "/vortexfs1/home/anthony.meza/mambaforge/envs/atm_rivers/lib/python3.10/site-packages/tornado/iostream.py", line 1116, in read_from_fd
    return self.socket.recv_into(buf, len(buf))
ConnectionResetError: [Errno 104] Connection reset by peer

The above exception was the direct cause of the following exception:

Traceback (most recent call last):
  File "/vortexfs1/home/anthony.meza/mambaforge/envs/atm_rivers/lib/python3.10/site-packages/distributed/worker.py", line 1234, in heartbeat
    response = await retry_operation(
  File "/vortexfs1/home/anthony.meza/mambaforge/envs/atm_rivers/lib/python3.10/site-packages/distributed/utils_comm.py", line 434, in retry_operation
    return await retry(
  File "/vortexfs1/home/anthony.meza/mambaforge/envs/atm_rivers/lib/python3.10/site-packages/distributed/utils_comm.py", line 413, in retry
    return await coro()
  File "/vortexfs1/home/anthony.meza/mambaforge/envs/atm_rivers/lib/python3.10/site-packages/distributed/core.py", line 1268, in send_recv_from_rpc
    return await send_recv(comm=comm, op=key, **kwargs)
  File "/vortexfs1/home/anthony.meza/mambaforge/envs/atm_rivers/lib/python3.10/site-packages/distributed/core.py", line 1027, in send_recv
    response = await comm.read(deserializers=deserializers)
  File "/vortexfs1/home/anthony.meza/mambaforge/envs/atm_rivers/lib/python3.10/site-packages/distributed/comm/tcp.py", line 241, in read
    convert_stream_closed_error(self, e)
  File "/vortexfs1/home/anthony.meza/mambaforge/envs/atm_rivers/lib/python3.10/site-packages/distributed/comm/tcp.py", line 142, in convert_stream_closed_error
    raise CommClosedError(f"in {obj}: {exc.__class__.__name__}: {exc}") from exc
distributed.comm.core.CommClosedError: in <TCP (closed) ConnectionPool.heartbeat_worker local=tcp://172.16.3.89:45353 remote=tcp://172.16.3.158:44343>: ConnectionResetError: [Errno 104] Connection reset by peer
2023-05-03 09:49:33,077 - distributed.worker - ERROR - failed during get data with tcp://172.16.3.89:41868 -> tcp://172.16.3.61:37998
Traceback (most recent call last):
  File "/vortexfs1/home/anthony.meza/mambaforge/envs/atm_rivers/lib/python3.10/site-packages/distributed/comm/tcp.py", line 225, in read
    frames_nbytes = await stream.read_bytes(fmt_size)
tornado.iostream.StreamClosedError: Stream is closed

The above exception was the direct cause of the following exception:

Traceback (most recent call last):
  File "/vortexfs1/home/anthony.meza/mambaforge/envs/atm_rivers/lib/python3.10/site-packages/distributed/worker.py", line 1783, in get_data
    response = await comm.read(deserializers=serializers)
  File "/vortexfs1/home/anthony.meza/mambaforge/envs/atm_rivers/lib/python3.10/site-packages/distributed/comm/tcp.py", line 241, in read
    convert_stream_closed_error(self, e)
  File "/vortexfs1/home/anthony.meza/mambaforge/envs/atm_rivers/lib/python3.10/site-packages/distributed/comm/tcp.py", line 144, in convert_stream_closed_error
    raise CommClosedError(f"in {obj}: {exc}") from exc
distributed.comm.core.CommClosedError: in <TCP (closed)  local=tcp://172.16.3.89:41868 remote=tcp://172.16.3.61:55092>: Stream is closed
2023-05-03 09:49:33,079 - distributed.nanny - INFO - Closing Nanny gracefully at 'tcp://172.16.3.89:41645'. Reason: worker-handle-scheduler-connection-broken
2023-05-03 09:49:33,164 - distributed.worker - ERROR - failed during get data with tcp://172.16.3.89:41868 -> tcp://172.16.3.63:38486
Traceback (most recent call last):
  File "/vortexfs1/home/anthony.meza/mambaforge/envs/atm_rivers/lib/python3.10/site-packages/distributed/comm/tcp.py", line 225, in read
    frames_nbytes = await stream.read_bytes(fmt_size)
tornado.iostream.StreamClosedError: Stream is closed

The above exception was the direct cause of the following exception:

Traceback (most recent call last):
  File "/vortexfs1/home/anthony.meza/mambaforge/envs/atm_rivers/lib/python3.10/site-packages/distributed/worker.py", line 1783, in get_data
    response = await comm.read(deserializers=serializers)
  File "/vortexfs1/home/anthony.meza/mambaforge/envs/atm_rivers/lib/python3.10/site-packages/distributed/comm/tcp.py", line 241, in read
    convert_stream_closed_error(self, e)
  File "/vortexfs1/home/anthony.meza/mambaforge/envs/atm_rivers/lib/python3.10/site-packages/distributed/comm/tcp.py", line 144, in convert_stream_closed_error
    raise CommClosedError(f"in {obj}: {exc}") from exc
distributed.comm.core.CommClosedError: in <TCP (closed)  local=tcp://172.16.3.89:41868 remote=tcp://172.16.3.63:49146>: Stream is closed
2023-05-03 09:49:33,188 - distributed.worker - ERROR - failed during get data with tcp://172.16.3.89:41868 -> tcp://172.16.3.167:34932
Traceback (most recent call last):
  File "/vortexfs1/home/anthony.meza/mambaforge/envs/atm_rivers/lib/python3.10/site-packages/tornado/iostream.py", line 861, in _read_to_buffer
    bytes_read = self.read_from_fd(buf)
  File "/vortexfs1/home/anthony.meza/mambaforge/envs/atm_rivers/lib/python3.10/site-packages/tornado/iostream.py", line 1116, in read_from_fd
    return self.socket.recv_into(buf, len(buf))
ConnectionResetError: [Errno 104] Connection reset by peer

The above exception was the direct cause of the following exception:

Traceback (most recent call last):
  File "/vortexfs1/home/anthony.meza/mambaforge/envs/atm_rivers/lib/python3.10/site-packages/distributed/worker.py", line 1783, in get_data
    response = await comm.read(deserializers=serializers)
  File "/vortexfs1/home/anthony.meza/mambaforge/envs/atm_rivers/lib/python3.10/site-packages/distributed/comm/tcp.py", line 241, in read
    convert_stream_closed_error(self, e)
  File "/vortexfs1/home/anthony.meza/mambaforge/envs/atm_rivers/lib/python3.10/site-packages/distributed/comm/tcp.py", line 142, in convert_stream_closed_error
    raise CommClosedError(f"in {obj}: {exc.__class__.__name__}: {exc}") from exc
distributed.comm.core.CommClosedError: in <TCP (closed)  local=tcp://172.16.3.89:41868 remote=tcp://172.16.3.167:60510>: ConnectionResetError: [Errno 104] Connection reset by peer
2023-05-03 09:49:33,333 - distributed.worker - ERROR - failed during get data with tcp://172.16.3.89:41868 -> tcp://172.16.3.62:42614
Traceback (most recent call last):
  File "/vortexfs1/home/anthony.meza/mambaforge/envs/atm_rivers/lib/python3.10/site-packages/tornado/iostream.py", line 861, in _read_to_buffer
    bytes_read = self.read_from_fd(buf)
  File "/vortexfs1/home/anthony.meza/mambaforge/envs/atm_rivers/lib/python3.10/site-packages/tornado/iostream.py", line 1116, in read_from_fd
    return self.socket.recv_into(buf, len(buf))
ConnectionResetError: [Errno 104] Connection reset by peer

The above exception was the direct cause of the following exception:

Traceback (most recent call last):
  File "/vortexfs1/home/anthony.meza/mambaforge/envs/atm_rivers/lib/python3.10/site-packages/distributed/worker.py", line 1783, in get_data
    response = await comm.read(deserializers=serializers)
  File "/vortexfs1/home/anthony.meza/mambaforge/envs/atm_rivers/lib/python3.10/site-packages/distributed/comm/tcp.py", line 241, in read
    convert_stream_closed_error(self, e)
  File "/vortexfs1/home/anthony.meza/mambaforge/envs/atm_rivers/lib/python3.10/site-packages/distributed/comm/tcp.py", line 142, in convert_stream_closed_error
    raise CommClosedError(f"in {obj}: {exc.__class__.__name__}: {exc}") from exc
distributed.comm.core.CommClosedError: in <TCP (closed)  local=tcp://172.16.3.89:41868 remote=tcp://172.16.3.62:58533>: ConnectionResetError: [Errno 104] Connection reset by peer
2023-05-03 09:49:36,799 - distributed.worker - ERROR - failed during get data with tcp://172.16.3.89:41868 -> tcp://172.16.3.168:40360
Traceback (most recent call last):
  File "/vortexfs1/home/anthony.meza/mambaforge/envs/atm_rivers/lib/python3.10/site-packages/distributed/comm/tcp.py", line 225, in read
    frames_nbytes = await stream.read_bytes(fmt_size)
tornado.iostream.StreamClosedError: Stream is closed

The above exception was the direct cause of the following exception:

Traceback (most recent call last):
  File "/vortexfs1/home/anthony.meza/mambaforge/envs/atm_rivers/lib/python3.10/site-packages/distributed/worker.py", line 1783, in get_data
    response = await comm.read(deserializers=serializers)
  File "/vortexfs1/home/anthony.meza/mambaforge/envs/atm_rivers/lib/python3.10/site-packages/distributed/comm/tcp.py", line 241, in read
    convert_stream_closed_error(self, e)
  File "/vortexfs1/home/anthony.meza/mambaforge/envs/atm_rivers/lib/python3.10/site-packages/distributed/comm/tcp.py", line 144, in convert_stream_closed_error
    raise CommClosedError(f"in {obj}: {exc}") from exc
distributed.comm.core.CommClosedError: in <TCP (closed)  local=tcp://172.16.3.89:41868 remote=tcp://172.16.3.168:43492>: Stream is closed
2023-05-03 09:49:50,689 - distributed.nanny - INFO - Worker closed
2023-05-03 09:49:52,694 - distributed.nanny - ERROR - Worker process died unexpectedly
2023-05-03 09:49:54,553 - distributed.nanny - INFO - Closing Nanny at 'tcp://172.16.3.89:41645'. Reason: nanny-close-gracefully
2023-05-03 09:49:54,553 - distributed.dask_worker - INFO - End worker
