2023-05-02 17:07:55,029 - distributed.nanny - INFO -         Start Nanny at: 'tcp://172.16.3.188:45888'
2023-05-02 17:07:55,881 - distributed.worker - INFO -       Start worker at:   tcp://172.16.3.188:42968
2023-05-02 17:07:55,883 - distributed.worker - INFO -          Listening to:   tcp://172.16.3.188:42968
2023-05-02 17:07:55,883 - distributed.worker - INFO -           Worker name:             SLURMCluster-3
2023-05-02 17:07:55,883 - distributed.worker - INFO -          dashboard at:         172.16.3.188:46667
2023-05-02 17:07:55,883 - distributed.worker - INFO - Waiting to connect to:   tcp://172.16.3.106:42366
2023-05-02 17:07:55,883 - distributed.worker - INFO - -------------------------------------------------
2023-05-02 17:07:55,883 - distributed.worker - INFO -               Threads:                         36
2023-05-02 17:07:55,883 - distributed.worker - INFO -                Memory:                  93.13 GiB
2023-05-02 17:07:55,883 - distributed.worker - INFO -       Local Directory: /tmp/dask-worker-space/worker-uc66rryx
2023-05-02 17:07:55,883 - distributed.worker - INFO - -------------------------------------------------
2023-05-02 17:07:56,179 - distributed.worker - INFO -         Registered to:   tcp://172.16.3.106:42366
2023-05-02 17:07:56,179 - distributed.worker - INFO - -------------------------------------------------
2023-05-02 17:07:56,179 - distributed.core - INFO - Starting established connection to tcp://172.16.3.106:42366
2023-05-02 17:10:06,291 - distributed.core - INFO - Event loop was unresponsive in Worker for 4.55s.  This is often caused by long-running GIL-holding functions or moving large chunks of data. This can cause timeouts and instability.
2023-05-02 17:10:34,047 - distributed.worker.memory - WARNING - Unmanaged memory use is high. This may indicate a memory leak or the memory may not be released to the OS; see https://distributed.dask.org/en/latest/worker-memory.html#memory-not-released-back-to-the-os for more information. -- Unmanaged memory: 60.97 GiB -- Worker memory limit: 93.13 GiB
2023-05-02 17:10:39,890 - distributed.nanny.memory - WARNING - Worker tcp://172.16.3.188:42968 (pid=437782) exceeded 95% memory budget. Restarting...
2023-05-02 17:10:46,376 - distributed.nanny - INFO - Worker process 437782 was killed by signal 15
2023-05-02 17:10:46,499 - distributed.nanny - WARNING - Restarting worker
2023-05-02 17:10:50,596 - distributed.worker - INFO -       Start worker at:   tcp://172.16.3.188:36147
2023-05-02 17:10:50,598 - distributed.worker - INFO -          Listening to:   tcp://172.16.3.188:36147
2023-05-02 17:10:50,598 - distributed.worker - INFO -           Worker name:             SLURMCluster-3
2023-05-02 17:10:50,598 - distributed.worker - INFO -          dashboard at:         172.16.3.188:35687
2023-05-02 17:10:50,598 - distributed.worker - INFO - Waiting to connect to:   tcp://172.16.3.106:42366
2023-05-02 17:10:50,598 - distributed.worker - INFO - -------------------------------------------------
2023-05-02 17:10:50,598 - distributed.worker - INFO -               Threads:                         36
2023-05-02 17:10:50,598 - distributed.worker - INFO -                Memory:                  93.13 GiB
2023-05-02 17:10:50,598 - distributed.worker - INFO -       Local Directory: /tmp/dask-worker-space/worker-azgbmlhi
2023-05-02 17:10:50,599 - distributed.worker - INFO - -------------------------------------------------
2023-05-02 17:10:50,611 - distributed.worker - INFO -         Registered to:   tcp://172.16.3.106:42366
2023-05-02 17:10:50,611 - distributed.worker - INFO - -------------------------------------------------
2023-05-02 17:10:50,612 - distributed.core - INFO - Starting established connection to tcp://172.16.3.106:42366
2023-05-02 17:10:54,850 - distributed.core - INFO - Removing comms to tcp://172.16.3.167:38166
2023-05-02 17:11:05,634 - distributed.core - INFO - Event loop was unresponsive in Worker for 7.92s.  This is often caused by long-running GIL-holding functions or moving large chunks of data. This can cause timeouts and instability.
2023-05-02 17:11:05,642 - distributed.worker - ERROR - Failed to communicate with scheduler during heartbeat.
Traceback (most recent call last):
  File "/vortexfs1/home/anthony.meza/mambaforge/envs/atm_rivers/lib/python3.10/site-packages/distributed/comm/tcp.py", line 225, in read
    frames_nbytes = await stream.read_bytes(fmt_size)
tornado.iostream.StreamClosedError: Stream is closed

The above exception was the direct cause of the following exception:

Traceback (most recent call last):
  File "/vortexfs1/home/anthony.meza/mambaforge/envs/atm_rivers/lib/python3.10/site-packages/distributed/worker.py", line 1234, in heartbeat
    response = await retry_operation(
  File "/vortexfs1/home/anthony.meza/mambaforge/envs/atm_rivers/lib/python3.10/site-packages/distributed/utils_comm.py", line 434, in retry_operation
    return await retry(
  File "/vortexfs1/home/anthony.meza/mambaforge/envs/atm_rivers/lib/python3.10/site-packages/distributed/utils_comm.py", line 413, in retry
    return await coro()
  File "/vortexfs1/home/anthony.meza/mambaforge/envs/atm_rivers/lib/python3.10/site-packages/distributed/core.py", line 1268, in send_recv_from_rpc
    return await send_recv(comm=comm, op=key, **kwargs)
  File "/vortexfs1/home/anthony.meza/mambaforge/envs/atm_rivers/lib/python3.10/site-packages/distributed/core.py", line 1027, in send_recv
    response = await comm.read(deserializers=deserializers)
  File "/vortexfs1/home/anthony.meza/mambaforge/envs/atm_rivers/lib/python3.10/site-packages/distributed/comm/tcp.py", line 241, in read
    convert_stream_closed_error(self, e)
  File "/vortexfs1/home/anthony.meza/mambaforge/envs/atm_rivers/lib/python3.10/site-packages/distributed/comm/tcp.py", line 144, in convert_stream_closed_error
    raise CommClosedError(f"in {obj}: {exc}") from exc
distributed.comm.core.CommClosedError: in <TCP (closed) ConnectionPool.heartbeat_worker local=tcp://172.16.3.188:57643 remote=tcp://172.16.3.106:42366>: Stream is closed
2023-05-02 17:11:05,665 - distributed.worker - ERROR - failed during get data with tcp://172.16.3.188:36147 -> tcp://172.16.3.92:46102
Traceback (most recent call last):
  File "/vortexfs1/home/anthony.meza/mambaforge/envs/atm_rivers/lib/python3.10/site-packages/distributed/comm/tcp.py", line 225, in read
    frames_nbytes = await stream.read_bytes(fmt_size)
tornado.iostream.StreamClosedError: Stream is closed

The above exception was the direct cause of the following exception:

Traceback (most recent call last):
  File "/vortexfs1/home/anthony.meza/mambaforge/envs/atm_rivers/lib/python3.10/site-packages/distributed/worker.py", line 1783, in get_data
    response = await comm.read(deserializers=serializers)
  File "/vortexfs1/home/anthony.meza/mambaforge/envs/atm_rivers/lib/python3.10/site-packages/distributed/comm/tcp.py", line 241, in read
    convert_stream_closed_error(self, e)
  File "/vortexfs1/home/anthony.meza/mambaforge/envs/atm_rivers/lib/python3.10/site-packages/distributed/comm/tcp.py", line 144, in convert_stream_closed_error
    raise CommClosedError(f"in {obj}: {exc}") from exc
distributed.comm.core.CommClosedError: in <TCP (closed)  local=tcp://172.16.3.188:36147 remote=tcp://172.16.3.92:56719>: Stream is closed
2023-05-02 17:11:05,666 - distributed.core - INFO - Lost connection to 'tcp://172.16.3.92:56719'
Traceback (most recent call last):
  File "/vortexfs1/home/anthony.meza/mambaforge/envs/atm_rivers/lib/python3.10/site-packages/distributed/comm/tcp.py", line 225, in read
    frames_nbytes = await stream.read_bytes(fmt_size)
tornado.iostream.StreamClosedError: Stream is closed

The above exception was the direct cause of the following exception:

Traceback (most recent call last):
  File "/vortexfs1/home/anthony.meza/mambaforge/envs/atm_rivers/lib/python3.10/site-packages/distributed/core.py", line 831, in _handle_comm
    result = await result
  File "/vortexfs1/home/anthony.meza/mambaforge/envs/atm_rivers/lib/python3.10/site-packages/distributed/core.py", line 990, in wrapper
    return await func(self, *args, **kwargs)
  File "/vortexfs1/home/anthony.meza/mambaforge/envs/atm_rivers/lib/python3.10/site-packages/distributed/worker.py", line 1783, in get_data
    response = await comm.read(deserializers=serializers)
  File "/vortexfs1/home/anthony.meza/mambaforge/envs/atm_rivers/lib/python3.10/site-packages/distributed/comm/tcp.py", line 241, in read
    convert_stream_closed_error(self, e)
  File "/vortexfs1/home/anthony.meza/mambaforge/envs/atm_rivers/lib/python3.10/site-packages/distributed/comm/tcp.py", line 144, in convert_stream_closed_error
    raise CommClosedError(f"in {obj}: {exc}") from exc
distributed.comm.core.CommClosedError: in <TCP (closed)  local=tcp://172.16.3.188:36147 remote=tcp://172.16.3.92:56719>: Stream is closed
2023-05-02 17:11:05,666 - distributed.worker - ERROR - failed during get data with tcp://172.16.3.188:36147 -> tcp://172.16.3.105:42096
Traceback (most recent call last):
  File "/vortexfs1/home/anthony.meza/mambaforge/envs/atm_rivers/lib/python3.10/site-packages/distributed/comm/tcp.py", line 225, in read
    frames_nbytes = await stream.read_bytes(fmt_size)
tornado.iostream.StreamClosedError: Stream is closed

The above exception was the direct cause of the following exception:

Traceback (most recent call last):
  File "/vortexfs1/home/anthony.meza/mambaforge/envs/atm_rivers/lib/python3.10/site-packages/distributed/worker.py", line 1783, in get_data
    response = await comm.read(deserializers=serializers)
  File "/vortexfs1/home/anthony.meza/mambaforge/envs/atm_rivers/lib/python3.10/site-packages/distributed/comm/tcp.py", line 241, in read
    convert_stream_closed_error(self, e)
  File "/vortexfs1/home/anthony.meza/mambaforge/envs/atm_rivers/lib/python3.10/site-packages/distributed/comm/tcp.py", line 144, in convert_stream_closed_error
    raise CommClosedError(f"in {obj}: {exc}") from exc
distributed.comm.core.CommClosedError: in <TCP (closed)  local=tcp://172.16.3.188:36147 remote=tcp://172.16.3.105:38005>: Stream is closed
2023-05-02 17:11:05,666 - distributed.core - INFO - Lost connection to 'tcp://172.16.3.105:38005'
Traceback (most recent call last):
  File "/vortexfs1/home/anthony.meza/mambaforge/envs/atm_rivers/lib/python3.10/site-packages/distributed/comm/tcp.py", line 225, in read
    frames_nbytes = await stream.read_bytes(fmt_size)
tornado.iostream.StreamClosedError: Stream is closed

The above exception was the direct cause of the following exception:

Traceback (most recent call last):
  File "/vortexfs1/home/anthony.meza/mambaforge/envs/atm_rivers/lib/python3.10/site-packages/distributed/core.py", line 831, in _handle_comm
    result = await result
  File "/vortexfs1/home/anthony.meza/mambaforge/envs/atm_rivers/lib/python3.10/site-packages/distributed/core.py", line 990, in wrapper
    return await func(self, *args, **kwargs)
  File "/vortexfs1/home/anthony.meza/mambaforge/envs/atm_rivers/lib/python3.10/site-packages/distributed/worker.py", line 1783, in get_data
    response = await comm.read(deserializers=serializers)
  File "/vortexfs1/home/anthony.meza/mambaforge/envs/atm_rivers/lib/python3.10/site-packages/distributed/comm/tcp.py", line 241, in read
    convert_stream_closed_error(self, e)
  File "/vortexfs1/home/anthony.meza/mambaforge/envs/atm_rivers/lib/python3.10/site-packages/distributed/comm/tcp.py", line 144, in convert_stream_closed_error
    raise CommClosedError(f"in {obj}: {exc}") from exc
distributed.comm.core.CommClosedError: in <TCP (closed)  local=tcp://172.16.3.188:36147 remote=tcp://172.16.3.105:38005>: Stream is closed
2023-05-02 17:11:05,667 - distributed.core - INFO - Connection to tcp://172.16.3.106:42366 has been closed.
2023-05-02 17:11:05,667 - distributed.worker - INFO - Stopping worker at tcp://172.16.3.188:36147. Reason: worker-handle-scheduler-connection-broken
2023-05-02 17:11:05,667 - distributed.batched - INFO - Batched Comm Closed <TCP (closed) Worker->Scheduler local=tcp://172.16.3.188:57641 remote=tcp://172.16.3.106:42366>
Traceback (most recent call last):
  File "/vortexfs1/home/anthony.meza/mambaforge/envs/atm_rivers/lib/python3.10/site-packages/distributed/batched.py", line 115, in _background_send
    nbytes = yield coro
  File "/vortexfs1/home/anthony.meza/mambaforge/envs/atm_rivers/lib/python3.10/site-packages/tornado/gen.py", line 767, in run
    value = future.result()
  File "/vortexfs1/home/anthony.meza/mambaforge/envs/atm_rivers/lib/python3.10/site-packages/distributed/comm/tcp.py", line 269, in write
    raise CommClosedError()
distributed.comm.core.CommClosedError
2023-05-02 17:11:05,751 - distributed.nanny - INFO - Closing Nanny gracefully at 'tcp://172.16.3.188:45888'. Reason: worker-handle-scheduler-connection-broken
2023-05-02 17:11:35,757 - distributed.nanny - INFO - Worker closed
2023-05-02 17:11:37,759 - distributed.nanny - ERROR - Worker process died unexpectedly
2023-05-02 17:11:42,956 - distributed.nanny - INFO - Closing Nanny at 'tcp://172.16.3.188:45888'. Reason: nanny-close-gracefully
2023-05-02 17:11:42,962 - distributed.dask_worker - INFO - End worker
